Workbook

Sheet 车次台账
A1: 车次台账（导出 2026-09-21 13:26，共 101 车，不含作废） 表头颜色：蓝=基本信息 绿=利润 黄=利润过程参数 紫=票款 灰=其他；净利润 = 毛服务费 + 量补金额 − 垫资成本 − 调货人提成 − 其他成本
A2: 车次ID | B2: 结算日期 | C2: 车号/船号 | D2: 车/船 | E2: 路径 | F2: 链条 | G2: 调货人 | H2: 供货厂/车队 | I2: 票源方 | J2: 状态 | K2: 结算吨位(吨) | L2: 结算金额(元) | M2: 净利润(元) | N2: 单吨利润(元/吨) | O2: 留存利润(元)·不计入净利润 | P2: 服务费单价(元/吨) | Q2: 毛服务费(元) | R2: 量补单价(元/吨) | S2: 量补金额(元) | T2: 对外结算点位(%) | U2: 给客户付(元) | V2: 垫资费单价(元/吨) | W2: 垫资费(元) | X2: 前端开票金额(元) | Y2: 票源成本点位(%) | Z2: 前端实付(元) | AA2: 垫资成本(元)·配票=个人垫资 | AB2: 提成单价(元/吨) | AC2: 调货人提成(元) | AD2: 其他成本(元)·含切割费 | AE2: 本车改过的费率 | AF2: 开票路径 | AG2: 票额(估)(元) | AH2: 进项 | AI2: 销项→欧冶 | AJ2: 欧冶回款 | AK2: 付票源 | AL2: 到客户账户 | AM2: 提成已付(元) | AN2: 接单日期 | AO2: 结算月份 | AP2: 扣杂(吨) | AQ2: 结算单号 | AR2: 钢厂 | AS2: 户头 | AT2: 司机 | AU2: 备注
A3: 1 | B3: 46253 | C3: 苏DBB772 | D3: 车 | E3: 配票/反向 | F3: 配票 | G3: 林凯 | H3: 林凯车队 | I3: 俊兴 | J3: 已开票 | K3: 73.58 | L3: 168498.2 | M3: =Q3+S3-AA3-AC3-AD3 | N3: =IF(K3=0,0,M3/K3) | O3: 0 | Q3: 0 | R3: 20 | S3: 1471.6 | T3: 14 | U3: 144908.45 | V3: 23 | W3: 1692.34 | X3: 166805.86 | Y3: 13.5 | Z3: 144287.07 | AA3: 621.3831 | AB3: 5 | AC3: 367.9 | AD3: 0 | AF3: 我们配票（经俊兴） | AG3: 166805.86 | AH3: — | AI3: 按状态视为已完成(历史) | AJ3: 待登记 | AK3: — | AL3: 未开始(前一环节未完成) | AM3: 0 | AN3: 46253 | AO3: 2026-08 | AP3: 0.9 | AQ3: 台账历史数据-已出结算单（具体单号未录入） | AR3: 华西特钢 | AS3: 华西-欧冶户头 | AU3: 由台账 Excel 历史数据自动导入（8.19付款明细-欧冶物宝1.xlsx 第5行），日期为过磅日期近似值 [原货主:林凯]
A4: 2 | B4: 46254 | C4: 苏DFM060 | D4: 车 | E4: 配票/反向 | F4: 配票 | G4: 林凯 | H4: 林凯车队 | I4: 俊兴 | J4: 已开票 | K4: 34.8 | L4: 84564 | M4: =Q4+S4-AA4-AC4-AD4 | N4: =IF(K4=0,0,M4/K4) | O4: 0 | Q4: 0 | R4: 20 | S4: 696 | T4: 14 | U4: 72725.04 | V4: 23 | W4: 800.4 | X4: 83763.6 | Y4: 13.5 | Z4: 72455.514 | AA4: 269.526 | AB4: 5 | AC4: 174 | AD4: 0 | AF4: 我们配票（经俊兴） | AG4: 83763.6 | AH4: — | AI4: 按状态视为已完成(历史) | AJ4: 待登记 | AK4: — | AL4: 未开始(前一环节未完成) | AM4: 0 | AN4: 46254 | AO4: 2026-08 | AP4: 0.5 | AQ4: 台账历史数据-已出结算单（具体单号未录入） | AR4: 华西特钢 | AS4: 华西-欧冶户头 | AU4: 由台账 Excel 历史数据自动导入（8.19付款明细-欧冶物宝1.xlsx 第6行），日期为过磅日期近似值 [原货主:林凯]
A5: 3 | B5: 46255 | C5: 苏DBB772 | D5: 车 | E5: 配票/反向 | F5: 配票 | G5: 林凯 | H5: 林凯车队 | I5: 俊兴 | J5: 已开票 | K5: 81.16 | L5: 201276.8 | M5: =Q5+S5-AA5-AC5-AD5 | N5: =IF(K5=0,0,M5/K5) | O5: 0 | Q5: 0 | R5: 20 | S5: 1623.2 | T5: 14 | U5: 173098.05 | V5: 23 | W5: 1866.68 | X5: 199410.12 | Y5: 13.5 | Z5: 172489.75 | AA5: 608.2942 | AB5: 5 | AC5: 405.8 | AD5: 0 | AF5: 我们配票（经俊兴） | AG5: 199410.12 | AH5: — | AI5: 按状态视为已完成(历史) | AJ5: 待登记 | AK5: — | AL5: 未开始(前一环节未完成) | AM5: 0 | AN5: 46255 | AO5: 2026-08 | AP5: 0.8 | AQ5: 台账历史数据-已出结算单（具体单号未录入） | AR5: 华西特钢 | AS5: 华西-欧冶户头 | AU5: 由台账 Excel 历史数据自动导入（8.19付款明细-欧冶物宝1.xlsx 第7行），日期为过磅日期近似值 [原货主:林凯]
A6: 4 | B6: 46255 | C6: 皖M2A505 | D6: 车 | E6: 配票/反向 | F6: 配票 | H6: 俊兴 | I6: 俊兴 | J6: 已开票 | K6: 36.36 | L6: 83264.4 | M6: =Q6+S6-AA6-AC6-AD6 | N6: =IF(K6=0,0,M6/K6) | O6: 0 | Q6: 0 | R6: 20 | S6: 727.2 | T6: 14 | U6: 71607.384 | V6: 23 | W6: 836.28 | X6: 82428.12 | Y6: 13.5 | Z6: 71300.324 | AA6: 307.0602 | AB6: 0 | AC6: 0 | AD6: 0 | AF6: 我们配票（经俊兴） | AG6: 82428.12 | AH6: — | AI6: 按状态视为已完成(历史) | AJ6: 待登记 | AK6: — | AL6: 未开始(前一环节未完成) | AM6: 0 | AN6: 46255 | AO6: 2026-08 | AP6: 0.3 | AQ6: 台账历史数据-已出结算单（具体单号未录入） | AR6: 华西特钢 | AS6: 华西-欧冶户头 | AU6: 由台账 Excel 历史数据自动导入（8.19付款明细-欧冶物宝1.xlsx 第8行），日期为过磅日期近似值
A7: 5 | B7: 46255 | C7: 苏EQB977 | D7: 车 | E7: 配票/反向 | F7: 配票 | H7: 俊兴 | I7: 俊兴 | J7: 已开票 | K7: 32.94 | L7: 75432.6 | M7: =Q7+S7-AA7-AC7-AD7 | N7: =IF(K7=0,0,M7/K7) | O7: 0 | Q7: 0 | R7: 20 | S7: 658.8 | T7: 14 | U7: 64872.036 | V7: 23 | W7: 757.62 | X7: 74674.98 | Y7: 13.5 | Z7: 64593.858 | AA7: 278.1783 | AB7: 0 | AC7: 0 | AD7: 0 | AF7: 我们配票（经俊兴） | AG7: 74674.98 | AH7: — | AI7: 按状态视为已完成(历史) | AJ7: 待登记 | AK7: — | AL7: 未开始(前一环节未完成) | AM7: 0 | AN7: 46255 | AO7: 2026-08 | AP7: 0.3 | AQ7: 台账历史数据-已出结算单（具体单号未录入） | AR7: 华西特钢 | AS7: 华西-欧冶户头 | AU7: 由台账 Excel 历史数据自动导入（8.19付款明细-欧冶物宝1.xlsx 第9行），日期为过磅日期近似值
A8: 6 | B8: 46255 | C8: 苏BUK952 | D8: 车 | E8: 配票/反向 | F8: 配票 | G8: 林凯 | H8: 林凯车队 | I8: 俊兴 | J8: 已开票 | K8: 24.41 | L8: 59023.38 | M8: =Q8+S8-AA8-AC8-AD8 | N8: =IF(K8=0,0,M8/K8) | O8: 0 | Q8: 0 | R8: 20 | S8: 488.2 | T8: 14 | U8: 50760.107 | V8: 23 | W8: 561.43 | X8: 58461.95 | Y8: 13.5 | Z8: 50569.587 | AA8: 190.52005 | AB8: 5 | AC8: 122.05 | AD8: 0 | AF8: 我们配票（经俊兴） | AG8: 58461.95 | AH8: — | AI8: 按状态视为已完成(历史) | AJ8: 待登记 | AK8: — | AL8: 未开始(前一环节未完成) | AM8: 0 | AN8: 46255 | AO8: 2026-08 | AP8: 0.25 | AQ8: 台账历史数据-已出结算单（具体单号未录入） | AR8: 华西特钢 | AS8: 华西-欧冶户头 | AU8: 由台账 Excel 历史数据自动导入（8.19付款明细-欧冶物宝1.xlsx 第10行），日期为过磅日期近似值 [原货主:林凯]
A9: 7 | B9: 46256 | C9: 苏DBB772 | D9: 车 | E9: 配票/反向 | F9: 配票 | G9: 林凯 | H9: 林凯车队 | I9: 俊兴 | J9: 已开票 | K9: 69.5 | L9: 159155 | M9: =Q9+S9-AA9-AC9-AD9 | N9: =IF(K9=0,0,M9/K9) | O9: 0 | Q9: 0 | R9: 20 | S9: 1390 | T9: 14 | U9: 136873.3 | V9: 23 | W9: 1598.5 | X9: 157556.5 | Y9: 13.5 | Z9: 136286.37 | AA9: 586.9275 | AB9: 5 | AC9: 347.5 | AD9: 0 | AF9: 我们配票（经俊兴） | AG9: 157556.5 | AH9: — | AI9: 按状态视为已完成(历史) | AJ9: 待登记 | AK9: — | AL9: 未开始(前一环节未完成) | AM9: 0 | AN9: 46256 | AO9: 2026-08 | AP9: 1.4 | AQ9: 台账历史数据-已出结算单（具体单号未录入） | AR9: 华西特钢 | AS9: 华西-欧冶户头 | AU9: 由台账 Excel 历史数据自动导入（8.19付款明细-欧冶物宝1.xlsx 第12行），日期为过磅日期近似值 [原货主:林凯]
A10: 8 | B10: 46256 | C10: 苏E9W908 | D10: 车 | E10: 配票/反向 | F10: 配票 | G10: 邓晶焱 | H10: 邓晶焱车队 | I10: 俊兴 | J10: 已开票 | K10: 39.16 | L10: 91242.8 | M10: =Q10+S10-AA10-AC10-AD10 | N10: =IF(K10=0,0,M10/K10) | O10: 0 | Q10: 0 | R10: 20 | S10: 783.2 | T10: 14 | U10: 78468.808 | V10: 23 | W10: 900.68 | X10: 90342.12 | Y10: 13.5 | Z10: 78145.934 | AA10: 322.8742 | AB10: 0 | AC10: 0 | AD10: 0 | AF10: 我们配票（经俊兴） | AG10: 90342.12 | AH10: — | AI10: 按状态视为已完成(历史) | AJ10: 待登记 | AK10: — | AL10: 未开始(前一环节未完成) | AM10: 0 | AN10: 46256 | AO10: 2026-08 | AP10: 1 | AQ10: 台账历史数据-已出结算单（具体单号未录入） | AR10: 华西特钢 | AS10: 华西-欧冶户头 | AU10: 由台账 Excel 历史数据自动导入（8.19付款明细-欧冶物宝1.xlsx 第13行），日期为过磅日期近似值
A11: 9 | B11: 46256 | C11: 苏MAK862 | D11: 车 | E11: 配票/反向 | F11: 配票 | H11: 俊兴 | I11: 俊兴 | J11: 已开票 | K11: 34.24 | L11: 78409.6 | M11: =Q11+S11-AA11-AC11-AD11 | N11: =IF(K11=0,0,M11/K11) | O11: 0 | Q11: 0 | R11: 20 | S11: 684.8 | T11: 14 | U11: 67432.256 | V11: 23 | W11: 787.52 | X11: 77622.08 | Y11: 13.5 | Z11: 67143.099 | AA11: 289.1568 | AB11: 0 | AC11: 0 | AD11: 0 | AF11: 我们配票（经俊兴） | AG11: 77622.08 | AH11: — | AI11: 按状态视为已完成(历史) | AJ11: 待登记 | AK11: — | AL11: 未开始(前一环节未完成) | AM11: 0 | AN11: 46256 | AO11: 2026-08 | AP11: 0.6 | AQ11: 台账历史数据-已出结算单（具体单号未录入） | AR11: 华西特钢 | AS11: 华西-欧冶户头 | AU11: 由台账 Excel 历史数据自动导入（8.19付款明细-欧冶物宝1.xlsx 第14行），日期为过磅日期近似值
A12: 10 | B12: 46259 | C12: 苏DBE075 | D12: 车 | E12: 配票/反向 | F12: 配票 | G12: 林凯 | H12: 林凯车队 | I12: 俊兴 | J12: 已开票 | K12: 81 | L12: 184032 | M12: =Q12+S12-AA12-AC12-AD12 | N12: =IF(K12=0,0,M12/K12) | O12: 0 | Q12: 0 | R12: 20 | S12: 1620 | T12: 14 | U12: 158267.52 | V12: 23 | W12: 1863 | X12: 182169 | Y12: 13.5 | Z12: 157576.18 | AA12: 691.335 | AB12: 5 | AC12: 405 | AD12: 0 | AF12: 我们配票（经俊兴） | AG12: 182169 | AH12: — | AI12: 按状态视为已完成(历史) | AJ12: 待登记 | AK12: — | AL12: 未开始(前一环节未完成) | AM12: 0 | AN12: 46259 | AO12: 2026-08 | AP12: 1.2 | AQ12: 台账历史数据-已出结算单（具体单号未录入） | AR12: 华西特钢 | AS12: 华西-欧冶户头 | AU12: 由台账 Excel 历史数据自动导入（8.19付款明细-欧冶物宝1.xlsx 第15行），日期为过磅日期近似值 [原货主:林凯]
A13: 11 | B13: 46261 | C13: 苏淮货16776 | D13: 船 | E13: 配票/反向 | F13: 配票 | H13: 俊兴 | I13: 俊兴 | J13: 已开票 | K13: 560.39 | L13: 1344115.9 | M13: =Q13+S13-AA13-AC13-AD13 | N13: =IF(K13=0,0,M13/K13) | O13: 0 | Q13: 0 | R13: 25 | S13: 14009.75 | T13: 14 | U13: 1155939.7 | V13: 23 | W13: 12888.97 | X13: 1331226.9 | Y13: 13.5 | Z13: 1151511.3 | AA13: 4428.3796 | AB13: 0 | AC13: 0 | AD13: 0 | AF13: 我们配票（经俊兴） | AG13: 1331226.9 | AH13: — | AI13: 按状态视为已完成(历史) | AJ13: 待登记 | AK13: — | AL13: 未开始(前一环节未完成) | AM13: 0 | AN13: 46261 | AO13: 2026-08 | AP13: 0 | AQ13: 台账历史数据-已出结算单（具体单号未录入） | AR13: 华西特钢 | AS13: 华西-欧冶户头 | AU13: 由台账 Excel 历史数据自动导入（8.19付款明细-欧冶物宝1.xlsx 第17行），日期为过磅日期近似值
A14: 12 | B14: 46261 | C14: 苏NEX375 | D14: 车 | E14: 配票/反向 | F14: 配票 | G14: 林凯 | H14: 林凯车队 | I14: 俊兴 | J14: 已开票 | K14: 40.27 | L14: 93426.4 | M14: =Q14+S14-AA14-AC14-AD14 | N14: =IF(K14=0,0,M14/K14) | O14: 0 | Q14: 0 | R14: 25 | S14: 1006.75 | T14: 14 | U14: 80346.704 | V14: 23 | W14: 926.21 | X14: 92500.19 | Y14: 13.5 | Z14: 80012.664 | AA14: 334.03965 | AB14: 5 | AC14: 201.35 | AD14: 0 | AF14: 我们配票（经俊兴） | AG14: 92500.19 | AH14: — | AI14: 按状态视为已完成(历史) | AJ14: 待登记 | AK14: — | AL14: 未开始(前一环节未完成) | AM14: 0 | AN14: 46261 | AO14: 2026-08 | AP14: 0.45 | AQ14: 台账历史数据-已出结算单（具体单号未录入） | AR14: 华西特钢 | AS14: 华西-欧冶户头 | AU14: 由台账 Excel 历史数据自动导入（8.19付款明细-欧冶物宝1.xlsx 第18行），日期为过磅日期近似值 [原货主:林凯]
A15: 13 | B15: 46261 | C15: 苏DFM060 | D15: 车 | E15: 配票/反向 | F15: 配票 | G15: 林凯 | H15: 林凯车队 | I15: 俊兴 | J15: 已开票 | K15: 34.3 | L15: 84206.5 | M15: =Q15+S15-AA15-AC15-AD15 | N15: =IF(K15=0,0,M15/K15) | O15: 0 | Q15: 0 | R15: 25 | S15: 857.5 | T15: 14 | U15: 72417.59 | V15: 23 | W15: 788.9 | X15: 83417.6 | Y15: 13.5 | Z15: 72156.224 | AA15: 261.366 | AB15: 5 | AC15: 171.5 | AD15: 0 | AF15: 我们配票（经俊兴） | AG15: 83417.6 | AH15: — | AI15: 按状态视为已完成(历史) | AJ15: 待登记 | AK15: — | AL15: 未开始(前一环节未完成) | AM15: 0 | AN15: 46261 | AO15: 2026-08 | AP15: 0.2 | AQ15: 台账历史数据-已出结算单（具体单号未录入） | AR15: 华西特钢 | AS15: 华西-欧冶户头 | AU15: 由台账 Excel 历史数据自动导入（8.19付款明细-欧冶物宝1.xlsx 第19行），日期为过磅日期近似值 [原货主:林凯]
A16: 14 | B16: 46261 | C16: 苏DBB772 | D16: 车 | E16: 配票/反向 | F16: 配票 | G16: 林凯 | H16: 君盛 | I16: 俊兴 | J16: 已开票 | K16: 66.22 | L16: 148332.8 | M16: =Q16+S16-AA16-AC16-AD16 | N16: =IF(K16=0,0,M16/K16) | O16: 0 | Q16: 0 | R16: 25 | S16: 1655.5 | T16: 14 | U16: 127566.21 | V16: 23 | W16: 1523.06 | X16: 146809.74 | Y16: 13.5 | Z16: 126990.43 | AA16: 575.7829 | AB16: 5 | AC16: 331.1 | AD16: 0 | AF16: 供货厂自带票（带票带货） | AG16: 146809.74 | AH16: — | AI16: 按状态视为已完成(历史) | AJ16: 待登记 | AK16: — | AL16: — | AM16: 0 | AN16: 46261 | AO16: 2026-08 | AP16: 1 | AQ16: 台账历史数据-已出结算单（具体单号未录入） | AR16: 华西特钢 | AS16: 华西-欧冶户头 | AU16: 由台账 Excel 历史数据自动导入（8.19付款明细-欧冶物宝1.xlsx 第21行），日期为过磅日期近似值 [原货主:林凯]
A17: 15 | B17: 46261 | C17: 苏BDK567 | D17: 车 | E17: 配票/反向 | F17: 配票 | G17: 林凯 | H17: 林凯车队 | I17: 俊兴 | J17: 已开票 | K17: 32.05 | L17: 78682.75 | M17: =Q17+S17-AA17-AC17-AD17 | N17: =IF(K17=0,0,M17/K17) | O17: 0 | Q17: 0 | R17: 25 | S17: 801.25 | T17: 14 | U17: 67667.165 | V17: 23 | W17: 737.15 | X17: 77945.6 | Y17: 13.5 | Z17: 67422.944 | AA17: 244.221 | AB17: 5 | AC17: 160.25 | AD17: 0 | AF17: 我们配票（经俊兴） | AG17: 77945.6 | AH17: — | AI17: 按状态视为已完成(历史) | AJ17: 待登记 | AK17: — | AL17: 未开始(前一环节未完成) | AM17: 0 | AN17: 46261 | AO17: 2026-08 | AP17: 0.25 | AQ17: 台账历史数据-已出结算单（具体单号未录入） | AR17: 华西特钢 | AS17: 华西-欧冶户头 | AU17: 由台账 Excel 历史数据自动导入（8.19付款明细-欧冶物宝1.xlsx 第22行），日期为过磅日期近似值 [原货主:林凯]
A18: 16 | B18: 46261 | C18: 苏BZP839 | D18: 车 | E18: 配票/反向 | F18: 配票 | G18: 林凯 | H18: 林凯车队 | I18: 俊兴 | J18: 已开票 | K18: 28.47 | L18: 68569.64 | M18: =Q18+S18-AA18-AC18-AD18 | N18: =IF(K18=0,0,M18/K18) | O18: 0 | Q18: 0 | R18: 25 | S18: 711.75 | T18: 14 | U18: 58969.89 | V18: 23 | W18: 654.81 | X18: 67914.83 | Y18: 13.5 | Z18: 58746.328 | AA18: 223.06245 | AB18: 5 | AC18: 142.35 | AD18: 100 | AF18: 我们配票（经俊兴） | AG18: 67914.83 | AH18: — | AI18: 按状态视为已完成(历史) | AJ18: 待登记 | AK18: — | AL18: 未开始(前一环节未完成) | AM18: 0 | AN18: 46261 | AO18: 2026-08 | AP18: 0.45 | AQ18: 台账历史数据-已出结算单（具体单号未录入） | AR18: 华西特钢 | AS18: 华西-欧冶户头 | AU18: 由台账 Excel 历史数据自动导入（8.19付款明细-欧冶物宝1.xlsx 第24行），日期为过磅日期近似值 [原货主:林凯]
A19: 17 | B19: 46261 | C19: 苏NEV615 | D19: 车 | E19: 配票/反向 | F19: 配票 | H19: 俊兴 | I19: 俊兴 | J19: 已开票 | K19: 38.78 | L19: 89969.6 | M19: =Q19+S19-AA19-AC19-AD19 | N19: =IF(K19=0,0,M19/K19) | O19: 0 | Q19: 0 | R19: 25 | S19: 969.5 | T19: 14 | U19: 77373.856 | V19: 23 | W19: 891.94 | X19: 89077.66 | Y19: 13.5 | Z19: 77052.176 | AA19: 321.6801 | AB19: 0 | AC19: 0 | AD19: 0 | AF19: 我们配票（经俊兴） | AG19: 89077.66 | AH19: — | AI19: 按状态视为已完成(历史) | AJ19: 待登记 | AK19: — | AL19: 未开始(前一环节未完成) | AM19: 0 | AN19: 46261 | AO19: 2026-08 | AP19: 0.5 | AQ19: 台账历史数据-已出结算单（具体单号未录入） | AR19: 华西特钢 | AS19: 华西-欧冶户头 | AU19: 由台账 Excel 历史数据自动导入（8.19付款明细-欧冶物宝1.xlsx 第26行），日期为过磅日期近似值
A20: 18 | B20: 46261 | C20: 苏ERS080 | D20: 车 | E20: 配票/反向 | F20: 配票 | G20: 林凯 | H20: 林凯车队 | I20: 俊兴 | J20: 已开票 | K20: 48.38 | L20: 116112 | M20: =Q20+S20-AA20-AC20-AD20 | N20: =IF(K20=0,0,M20/K20) | O20: 0 | Q20: 0 | R20: 25 | S20: 1209.5 | T20: 14 | U20: 99856.32 | V20: 23 | W20: 1112.74 | X20: 114999.26 | Y20: 13.5 | Z20: 99474.36 | AA20: 381.9601 | AB20: 5 | AC20: 241.9 | AD20: 0 | AF20: 我们配票（经俊兴） | AG20: 114999.26 | AH20: — | AI20: 按状态视为已完成(历史) | AJ20: 待登记 | AK20: — | AL20: 未开始(前一环节未完成) | AM20: 0 | AN20: 46261 | AO20: 2026-08 | AP20: 0.3 | AQ20: 台账历史数据-已出结算单（具体单号未录入） | AR20: 华西特钢 | AS20: 华西-欧冶户头 | AU20: 由台账 Excel 历史数据自动导入（8.19付款明细-欧冶物宝1.xlsx 第27行），日期为过磅日期近似值 [原货主:林凯]
A21: 19 | B21: 46261 | C21: 鲁济宁货4095 | D21: 船 | E21: 配票/反向 | F21: 配票 | H21: 俊兴 | I21: 俊兴 | J21: 已开票 | K21: 518.48 | L21: 1271259 | M21: =Q21+S21-AA21-AC21-AD21 | N21: =IF(K21=0,0,M21/K21) | O21: 0 | Q21: 0 | R21: 25 | S21: 12962 | T21: 14 | U21: 1093282.7 | V21: 23 | W21: 11925.04 | X21: 1259333.9 | Y21: 13.5 | Z21: 1089323.8 | AA21: 3958.8648 | AB21: 0 | AC21: 0 | AD21: 0 | AF21: 我们配票（经俊兴） | AG21: 1259333.9 | AH21: — | AI21: 按状态视为已完成(历史) | AJ21: 待登记 | AK21: — | AL21: 未开始(前一环节未完成) | AM21: 0 | AN21: 46261 | AO21: 2026-08 | AP21: 0 | AQ21: 台账历史数据-已出结算单（具体单号未录入） | AR21: 华西特钢 | AS21: 华西-欧冶户头 | AU21: 由台账 Excel 历史数据自动导入（8.19付款明细-欧冶物宝1.xlsx 第29行），日期为过磅日期近似值
A22: 20 | B22: 46262 | C22: 苏DBE075 | D22: 车 | E22: 配票/反向 | F22: 配票 | G22: 林凯 | H22: 林凯车队 | I22: 俊兴 | J22: 已开票 | K22: 38.2 | L22: 88624 | M22: =Q22+S22-AA22-AC22-AD22 | N22: =IF(K22=0,0,M22/K22) | O22: 0 | Q22: 0 | R22: 25 | S22: 955 | T22: 14 | U22: 76216.64 | V22: 23 | W22: 878.6 | X22: 87745.4 | Y22: 13.5 | Z22: 75899.771 | AA22: 316.869 | AB22: 5 | AC22: 191 | AD22: 0 | AF22: 我们配票（经俊兴） | AG22: 87745.4 | AH22: — | AI22: 按状态视为已完成(历史) | AJ22: 待登记 | AK22: — | AL22: 未开始(前一环节未完成) | AM22: 0 | AN22: 46262 | AO22: 2026-08 | AP22: 0.2 | AQ22: 台账历史数据-已出结算单（具体单号未录入） | AR22: 华西特钢 | AS22: 华西-欧冶户头 | AU22: 由台账 Excel 历史数据自动导入（8.19付款明细-欧冶物宝1.xlsx 第30行），日期为过磅日期近似值 [原货主:林凯]
A23: 21 | B23: 46262 | C23: 苏DBX137 | D23: 车 | E23: 配票/反向 | F23: 配票 | G23: 林凯 | H23: 林凯车队 | I23: 俊兴 | J23: 已开票 | K23: 18.52 | L23: 44448 | M23: =Q23+S23-AA23-AC23-AD23 | N23: =IF(K23=0,0,M23/K23) | O23: 0 | Q23: 0 | R23: 25 | S23: 463 | T23: 14 | U23: 38225.28 | V23: 23 | W23: 425.96 | X23: 44022.04 | Y23: 13.5 | Z23: 38079.065 | AA23: 146.2154 | AB23: 5 | AC23: 92.6 | AD23: 0 | AF23: 我们配票（经俊兴） | AG23: 44022.04 | AH23: — | AI23: 按状态视为已完成(历史) | AJ23: 待登记 | AK23: — | AL23: 未开始(前一环节未完成) | AM23: 0 | AN23: 46262 | AO23: 2026-08 | AP23: 0.3 | AQ23: 台账历史数据-已出结算单（具体单号未录入） | AR23: 华西特钢 | AS23: 华西-欧冶户头 | AU23: 由台账 Excel 历史数据自动导入（8.19付款明细-欧冶物宝1.xlsx 第31行），日期为过磅日期近似值 [原货主:林凯]
A24: 22 | B24: 46262 | C24: 苏DFB287 | D24: 车 | E24: 配票/反向 | F24: 配票 | G24: 林凯 | H24: 林凯车队 | I24: 俊兴 | J24: 已开票 | K24: 81.9 | L24: 191646 | M24: =Q24+S24-AA24-AC24-AD24 | N24: =IF(K24=0,0,M24/K24) | O24: 0 | Q24: 0 | R24: 25 | S24: 2047.5 | T24: 14 | U24: 164815.56 | V24: 23 | W24: 1883.7 | X24: 189762.3 | Y24: 13.5 | Z24: 164144.39 | AA24: 671.1705 | AB24: 5 | AC24: 409.5 | AD24: 0 | AF24: 我们配票（经俊兴） | AG24: 189762.3 | AH24: — | AI24: 按状态视为已完成(历史) | AJ24: 待登记 | AK24: — | AL24: 未开始(前一环节未完成) | AM24: 0 | AN24: 46262 | AO24: 2026-08 | AP24: 0.6 | AQ24: 台账历史数据-已出结算单（具体单号未录入） | AR24: 华西特钢 | AS24: 华西-欧冶户头 | AU24: 由台账 Excel 历史数据自动导入（8.19付款明细-欧冶物宝1.xlsx 第32行），日期为过磅日期近似值 [原货主:林凯]
A25: 23 | B25: 46262 | C25: 苏DFM060 | D25: 车 | E25: 配票/反向 | F25: 配票 | G25: 林凯 | H25: 林凯车队 | I25: 俊兴 | J25: 已开票 | K25: 55.18 | L25: 130224.8 | M25: =Q25+S25-AA25-AC25-AD25 | N25: =IF(K25=0,0,M25/K25) | O25: 0 | Q25: 0 | R25: 25 | S25: 1379.5 | T25: 14 | U25: 111993.33 | V25: 23 | W25: 1269.14 | X25: 128955.66 | Y25: 13.5 | Z25: 111546.65 | AA25: 446.6821 | AB25: 5 | AC25: 275.9 | AD25: 0 | AF25: 我们配票（经俊兴） | AG25: 128955.66 | AH25: — | AI25: 按状态视为已完成(历史) | AJ25: 待登记 | AK25: — | AL25: 未开始(前一环节未完成) | AM25: 0 | AN25: 46262 | AO25: 2026-08 | AP25: 0.5 | AQ25: 台账历史数据-已出结算单（具体单号未录入） | AR25: 华西特钢 | AS25: 华西-欧冶户头 | AU25: 由台账 Excel 历史数据自动导入（8.19付款明细-欧冶物宝1.xlsx 第34行），日期为过磅日期近似值 [原货主:林凯]
A26: 24 | B26: 46262 | C26: 苏DBB772 | D26: 车 | E26: 配票/反向 | F26: 配票 | G26: 林凯 | H26: 林凯车队 | I26: 俊兴 | J26: 已开票 | K26: 63.16 | L26: 153352.48 | M26: =Q26+S26-AA26-AC26-AD26 | N26: =IF(K26=0,0,M26/K26) | O26: 0 | Q26: 0 | R26: 25 | S26: 1579 | T26: 14 | U26: 131883.13 | V26: 23 | W26: 1452.68 | X26: 151899.8 | Y26: 13.5 | Z26: 131393.33 | AA26: 489.8058 | AB26: 5 | AC26: 315.8 | AD26: 0 | AF26: 我们配票（经俊兴） | AG26: 151899.8 | AH26: — | AI26: 按状态视为已完成(历史) | AJ26: 待登记 | AK26: — | AL26: 未开始(前一环节未完成) | AM26: 0 | AN26: 46262 | AO26: 2026-08 | AP26: 0.5 | AQ26: 台账历史数据-已出结算单（具体单号未录入） | AR26: 华西特钢 | AS26: 华西-欧冶户头 | AU26: 由台账 Excel 历史数据自动导入（8.19付款明细-欧冶物宝1.xlsx 第35行），日期为过磅日期近似值 [原货主:林凯]
A27: 25 | B27: 46262 | C27: 苏BDK567 | D27: 车 | E27: 配票/反向 | F27: 配票 | G27: 林凯 | H27: 林凯车队 | I27: 俊兴 | J27: 已开票 | K27: 34.22 | L27: 83496.8 | M27: =Q27+S27-AA27-AC27-AD27 | N27: =IF(K27=0,0,M27/K27) | O27: 0 | Q27: 0 | R27: 25 | S27: 855.5 | T27: 14 | U27: 71807.248 | V27: 23 | W27: 787.06 | X27: 82709.74 | Y27: 13.5 | Z27: 71543.925 | AA27: 263.3229 | AB27: 5 | AC27: 171.1 | AD27: 0 | AF27: 我们配票（经俊兴） | AG27: 82709.74 | AH27: — | AI27: 按状态视为已完成(历史) | AJ27: 待登记 | AK27: — | AL27: 未开始(前一环节未完成) | AM27: 0 | AN27: 46262 | AO27: 2026-08 | AP27: 0.3 | AQ27: 台账历史数据-已出结算单（具体单号未录入） | AR27: 华西特钢 | AS27: 华西-欧冶户头 | AU27: 由台账 Excel 历史数据自动导入（8.19付款明细-欧冶物宝1.xlsx 第37行），日期为过磅日期近似值 [原货主:林凯]
A28: 26 | B28: 46262 | C28: 苏BUK952 | D28: 车 | E28: 配票/反向 | F28: 配票 | G28: 林凯 | H28: 林凯车队 | I28: 俊兴 | J28: 已开票 | K28: 27.22 | L28: 66416.8 | M28: =Q28+S28-AA28-AC28-AD28 | N28: =IF(K28=0,0,M28/K28) | O28: 0 | Q28: 0 | R28: 25 | S28: 680.5 | T28: 14 | U28: 57118.448 | V28: 23 | W28: 626.06 | X28: 65790.74 | Y28: 13.5 | Z28: 56908.99 | AA28: 209.4579 | AB28: 5 | AC28: 136.1 | AD28: 0 | AF28: 我们配票（经俊兴） | AG28: 65790.74 | AH28: — | AI28: 按状态视为已完成(历史) | AJ28: 待登记 | AK28: — | AL28: 未开始(前一环节未完成) | AM28: 0 | AN28: 46262 | AO28: 2026-08 | AP28: 0.2 | AQ28: 台账历史数据-已出结算单（具体单号未录入） | AR28: 华西特钢 | AS28: 华西-欧冶户头 | AU28: 由台账 Excel 历史数据自动导入（8.19付款明细-欧冶物宝1.xlsx 第38行），日期为过磅日期近似值 [原货主:林凯]
A29: 27 | B29: 46262 | C29: 皖KQ1052 | D29: 车 | E29: 配票/反向 | F29: 配票 | H29: 俊兴 | I29: 俊兴 | J29: 已开票 | K29: 34.49 | L29: 80430.68 | M29: =Q29+S29-AA29-AC29-AD29 | N29: =IF(K29=0,0,M29/K29) | O29: 0 | Q29: 0 | R29: 25 | S29: 862.25 | T29: 14 | U29: 69170.385 | V29: 23 | W29: 793.27 | X29: 79637.41 | Y29: 13.5 | Z29: 68886.36 | AA29: 284.02515 | AB29: 0 | AC29: 0 | AD29: 0 | AF29: 我们配票（经俊兴） | AG29: 79637.41 | AH29: — | AI29: 按状态视为已完成(历史) | AJ29: 待登记 | AK29: — | AL29: 未开始(前一环节未完成) | AM29: 0 | AN29: 46262 | AO29: 2026-08 | AP29: 0.35 | AQ29: 台账历史数据-已出结算单（具体单号未录入） | AR29: 华西特钢 | AS29: 华西-欧冶户头 | AU29: 由台账 Excel 历史数据自动导入（8.19付款明细-欧冶物宝1.xlsx 第39行），日期为过磅日期近似值
A30: 28 | B30: 46262 | C30: 苏DBE075 | D30: 车 | E30: 配票/反向 | F30: 配票 | G30: 林凯 | H30: 林凯车队 | I30: 俊兴 | J30: 已开票 | K30: 67.8 | L30: 151872 | M30: =Q30+S30-AA30-AC30-AD30 | N30: =IF(K30=0,0,M30/K30) | O30: 0 | Q30: 0 | R30: 25 | S30: 1695 | T30: 14 | U30: 130609.92 | V30: 23 | W30: 1559.4 | X30: 150312.6 | Y30: 13.5 | Z30: 130020.4 | AA30: 589.521 | AB30: 5 | AC30: 339 | AD30: 0 | AF30: 我们配票（经俊兴） | AG30: 150312.6 | AH30: — | AI30: 按状态视为已完成(历史) | AJ30: 待登记 | AK30: — | AL30: 未开始(前一环节未完成) | AM30: 0 | AN30: 46262 | AO30: 2026-08 | AP30: 1.9 | AQ30: 台账历史数据-已出结算单（具体单号未录入） | AR30: 华西特钢 | AS30: 华西-欧冶户头 | AU30: 由台账 Excel 历史数据自动导入（8.19付款明细-欧冶物宝1.xlsx 第41行），日期为过磅日期近似值 [原货主:林凯]
A31: 29 | B31: 46262 | C31: 冀A224E6 | D31: 车 | E31: 配票/反向 | F31: 配票 | G31: 林凯 | H31: 林凯车队 | I31: 俊兴 | J31: 已开票 | K31: 29 | L31: 71369 | M31: =Q31+S31-AA31-AC31-AD31 | N31: =IF(K31=0,0,M31/K31) | O31: 0 | Q31: 0 | R31: 25 | S31: 725 | T31: 14 | U31: 61377.34 | V31: 23 | W31: 667 | X31: 70702 | Y31: 13.5 | Z31: 61157.23 | AA31: 220.11 | AB31: 5 | AC31: 145 | AD31: 0 | AF31: 我们配票（经俊兴） | AG31: 70702 | AH31: — | AI31: 按状态视为已完成(历史) | AJ31: 待登记 | AK31: — | AL31: 未开始(前一环节未完成) | AM31: 0 | AN31: 46262 | AO31: 2026-08 | AP31: 0.4 | AQ31: 台账历史数据-已出结算单（具体单号未录入） | AR31: 华西特钢 | AS31: 华西-欧冶户头 | AU31: 由台账 Excel 历史数据自动导入（8.19付款明细-欧冶物宝1.xlsx 第42行），日期为过磅日期近似值 [原货主:林凯]
A32: 30 | B32: 46262 | C32: 苏BWX568 | D32: 车 | E32: 配票/反向 | F32: 配票 | G32: 林凯 | H32: 林凯车队 | I32: 俊兴 | J32: 已开票 | K32: 32.52 | L32: 78048 | M32: =Q32+S32-AA32-AC32-AD32 | N32: =IF(K32=0,0,M32/K32) | O32: 0 | Q32: 0 | R32: 25 | S32: 813 | T32: 14 | U32: 67121.28 | V32: 23 | W32: 747.96 | X32: 77300.04 | Y32: 13.5 | Z32: 66864.535 | AA32: 256.7454 | AB32: 5 | AC32: 162.6 | AD32: 0 | AF32: 我们配票（经俊兴） | AG32: 77300.04 | AH32: — | AI32: 按状态视为已完成(历史) | AJ32: 待登记 | AK32: — | AL32: 未开始(前一环节未完成) | AM32: 0 | AN32: 46262 | AO32: 2026-08 | AP32: 0.7 | AQ32: 台账历史数据-已出结算单（具体单号未录入） | AR32: 华西特钢 | AS32: 华西-欧冶户头 | AU32: 由台账 Excel 历史数据自动导入（8.19付款明细-欧冶物宝1.xlsx 第44行），日期为过磅日期近似值 [原货主:林凯]
A33: 31 | B33: 46263 | C33: 苏DBB772 | D33: 车 | E33: 配票/反向 | F33: 配票 | G33: 林凯 | H33: 林凯车队 | I33: 俊兴 | J33: 已开票 | K33: 81.36 | L33: 204213.6 | M33: =Q33+S33-AA33-AC33-AD33 | N33: =IF(K33=0,0,M33/K33) | O33: 0 | Q33: 0 | R33: 25 | S33: 2034 | T33: 14 | U33: 175623.7 | V33: 23 | W33: 1871.28 | X33: 202342.32 | Y33: 13.5 | Z33: 175026.11 | AA33: 597.5892 | AB33: 5 | AC33: 406.8 | AD33: 0 | AF33: 我们配票（经俊兴） | AG33: 202342.32 | AH33: — | AI33: 按状态视为已完成(历史) | AJ33: 待登记 | AK33: — | AL33: 未开始(前一环节未完成) | AM33: 0 | AN33: 46263 | AO33: 2026-08 | AP33: 0.7 | AQ33: 台账历史数据-已出结算单（具体单号未录入） | AR33: 华西特钢 | AS33: 华西-欧冶户头 | AU33: 由台账 Excel 历史数据自动导入（8.19付款明细-欧冶物宝1.xlsx 第45行），日期为过磅日期近似值 [原货主:林凯]
A34: 32 | B34: 46263 | C34: 苏ERS080 | D34: 车 | E34: 配票/反向 | F34: 配票 | G34: 林凯 | H34: 林凯车队 | I34: 俊兴 | J34: 已开票 | K34: 48.75 | L34: 117000 | M34: =Q34+S34-AA34-AC34-AD34 | N34: =IF(K34=0,0,M34/K34) | O34: 0 | Q34: 0 | R34: 25 | S34: 1218.75 | T34: 14 | U34: 100620 | V34: 23 | W34: 1121.25 | X34: 115878.75 | Y34: 13.5 | Z34: 100235.12 | AA34: 384.88125 | AB34: 5 | AC34: 243.75 | AD34: 0 | AF34: 我们配票（经俊兴） | AG34: 115878.75 | AH34: — | AI34: 按状态视为已完成(历史) | AJ34: 待登记 | AK34: — | AL34: 未开始(前一环节未完成) | AM34: 0 | AN34: 46263 | AO34: 2026-08 | AP34: 0.45 | AQ34: 台账历史数据-已出结算单（具体单号未录入） | AR34: 华西特钢 | AS34: 华西-欧冶户头 | AU34: 由台账 Excel 历史数据自动导入（8.19付款明细-欧冶物宝1.xlsx 第46行），日期为过磅日期近似值 [原货主:林凯]
A35: 33 | B35: 46263 | C35: 苏DBE075 | D35: 车 | E35: 配票/反向 | F35: 配票 | G35: 林凯 | H35: 林凯车队 | I35: 俊兴 | J35: 已开票 | K35: 79.68 | L35: 199996.8 | M35: =Q35+S35-AA35-AC35-AD35 | N35: =IF(K35=0,0,M35/K35) | O35: 0 | Q35: 0 | R35: 25 | S35: 1992 | T35: 14 | U35: 171997.25 | V35: 23 | W35: 1832.64 | X35: 198164.16 | Y35: 13.5 | Z35: 171412 | AA35: 585.2496 | AB35: 5 | AC35: 398.4 | AD35: 0 | AF35: 我们配票（经俊兴） | AG35: 198164.16 | AH35: — | AI35: 按状态视为已完成(历史) | AJ35: 待登记 | AK35: — | AL35: 未开始(前一环节未完成) | AM35: 0 | AN35: 46263 | AO35: 2026-08 | AP35: 0.7 | AQ35: 台账历史数据-已出结算单（具体单号未录入） | AR35: 华西特钢 | AS35: 华西-欧冶户头 | AU35: 由台账 Excel 历史数据自动导入（8.19付款明细-欧冶物宝1.xlsx 第47行），日期为过磅日期近似值 [原货主:林凯]
A36: 34 | B36: 46263 | C36: 冀A224E6 | D36: 车 | E36: 配票/反向 | F36: 配票 | H36: 俊兴 | I36: 俊兴 | J36: 已开票 | K36: 20 | L36: 48800 | M36: =Q36+S36-AA36-AC36-AD36 | N36: =IF(K36=0,0,M36/K36) | O36: 0 | Q36: 0 | R36: 25 | S36: 500 | T36: 14 | U36: 41968 | V36: 23 | W36: 460 | X36: 48340 | Y36: 13.5 | Z36: 41814.1 | AA36: 153.9 | AB36: 0 | AC36: 0 | AD36: 0 | AF36: 我们配票（经俊兴） | AG36: 48340 | AH36: — | AI36: 按状态视为已完成(历史) | AJ36: 待登记 | AK36: — | AL36: 未开始(前一环节未完成) | AM36: 0 | AN36: 46263 | AO36: 2026-08 | AP36: 0.4 | AQ36: 台账历史数据-已出结算单（具体单号未录入） | AR36: 华西特钢 | AS36: 华西-欧冶户头 | AU36: 由台账 Excel 历史数据自动导入（8.19付款明细-欧冶物宝1.xlsx 第48行），日期为过磅日期近似值
A37: 35 | B37: 46263 | C37: 苏AE8896 | D37: 车 | E37: 配票/反向 | F37: 配票 | H37: 俊兴 | I37: 俊兴 | J37: 已开票 | K37: 39.96 | L37: 93186.72 | M37: =Q37+S37-AA37-AC37-AD37 | N37: =IF(K37=0,0,M37/K37) | O37: 0 | Q37: 0 | R37: 25 | S37: 999 | T37: 14 | U37: 80140.579 | V37: 23 | W37: 919.08 | X37: 92267.64 | Y37: 13.5 | Z37: 79811.509 | AA37: 329.0706 | AB37: 0 | AC37: 0 | AD37: 0 | AF37: 我们配票（经俊兴） | AG37: 92267.64 | AH37: — | AI37: 按状态视为已完成(历史) | AJ37: 待登记 | AK37: — | AL37: 未开始(前一环节未完成) | AM37: 0 | AN37: 46263 | AO37: 2026-08 | AP37: 0.4 | AQ37: 台账历史数据-已出结算单（具体单号未录入） | AR37: 华西特钢 | AS37: 华西-欧冶户头 | AU37: 由台账 Excel 历史数据自动导入（8.19付款明细-欧冶物宝1.xlsx 第49行），日期为过磅日期近似值
A38: 36 | B38: 46263 | C38: 苏DBB772 | D38: 车 | E38: 配票/反向 | F38: 配票 | G38: 林凯 | H38: 林凯车队 | I38: 俊兴 | J38: 已开票 | K38: 66.06 | L38: 147974.4 | M38: =Q38+S38-AA38-AC38-AD38 | N38: =IF(K38=0,0,M38/K38) | O38: 0 | Q38: 0 | R38: 25 | S38: 1651.5 | T38: 14 | U38: 127257.98 | V38: 23 | W38: 1519.38 | X38: 146455.02 | Y38: 13.5 | Z38: 126683.59 | AA38: 574.3917 | AB38: 5 | AC38: 330.3 | AD38: 0 | AF38: 我们配票（经俊兴） | AG38: 146455.02 | AH38: — | AI38: 按状态视为已完成(历史) | AJ38: 待登记 | AK38: — | AL38: 未开始(前一环节未完成) | AM38: 0 | AN38: 46263 | AO38: 2026-08 | AP38: 0.6 | AQ38: 台账历史数据-已出结算单（具体单号未录入） | AR38: 华西特钢 | AS38: 华西-欧冶户头 | AU38: 由台账 Excel 历史数据自动导入（8.19付款明细-欧冶物宝1.xlsx 第51行），日期为过磅日期近似值 [原货主:林凯]
A39: 37 | B39: 46264 | C39: 苏DBE075 | D39: 车 | E39: 配票/反向 | F39: 配票 | G39: 林凯 | H39: 林凯车队 | I39: 俊兴 | J39: 已开票 | K39: 81.92 | L39: 205619.2 | M39: =Q39+S39-AA39-AC39-AD39 | N39: =IF(K39=0,0,M39/K39) | O39: 0 | Q39: 0 | R39: 25 | S39: 2048 | T39: 14 | U39: 176832.51 | V39: 23 | W39: 1884.16 | X39: 203735.04 | Y39: 13.5 | Z39: 176230.81 | AA39: 601.7024 | AB39: 5 | AC39: 409.6 | AD39: 0 | AF39: 我们配票（经俊兴） | AG39: 203735.04 | AH39: — | AI39: 按状态视为已完成(历史) | AJ39: 待登记 | AK39: — | AL39: 未开始(前一环节未完成) | AM39: 0 | AN39: 46264 | AO39: 2026-08 | AP39: 0.8 | AQ39: 台账历史数据-已出结算单（具体单号未录入） | AR39: 华西特钢 | AS39: 华西-欧冶户头 | AU39: 由台账 Excel 历史数据自动导入（8.19付款明细-欧冶物宝1.xlsx 第52行），日期为过磅日期近似值 [原货主:林凯]
A40: 38 | B40: 46264 | C40: 苏DBE961 | D40: 车 | E40: 配票/反向 | F40: 配票 | H40: 俊兴 | I40: 俊兴 | J40: 已开票 | K40: 78.64 | L40: 181501.12 | M40: =Q40+S40-AA40-AC40-AD40 | N40: =IF(K40=0,0,M40/K40) | O40: 0 | Q40: 0 | R40: 25 | S40: 1966 | T40: 14 | U40: 156090.96 | V40: 23 | W40: 1808.72 | X40: 179692.4 | Y40: 13.5 | Z40: 155433.93 | AA40: 657.0372 | AB40: 0 | AC40: 0 | AD40: 0 | AF40: 我们配票（经俊兴） | AG40: 179692.4 | AH40: — | AI40: 按状态视为已完成(历史) | AJ40: 待登记 | AK40: — | AL40: 未开始(前一环节未完成) | AM40: 0 | AN40: 46264 | AO40: 2026-08 | AP40: 0.6 | AQ40: 台账历史数据-已出结算单（具体单号未录入） | AR40: 华西特钢 | AS40: 华西-欧冶户头 | AU40: 由台账 Excel 历史数据自动导入（8.19付款明细-欧冶物宝1.xlsx 第53行），日期为过磅日期近似值
...

Sheet 统计汇总
A1: 统计汇总（导出 2026-09-21 13:26；全部为引用「车次台账」的公式，不含作废）
A3: 一、总体与利润构成
A4: 车次数 | B4: =COUNT('车次台账'!$A$3:$A$103)
A5: 结算吨位(吨) | B5: =SUM('车次台账'!$K$3:$K$103)
A6: 结算金额(元) | B6: =SUM('车次台账'!$L$3:$L$103)
A7: 毛服务费(元) | B7: =SUM('车次台账'!$Q$3:$Q$103)
A8: + 量补金额(元) | B8: =SUM('车次台账'!$S$3:$S$103)
A9: − 垫资成本(元) | B9: =SUM('车次台账'!$AA$3:$AA$103)
A10: − 调货人提成(元) | B10: =SUM('车次台账'!$AC$3:$AC$103)
A11: − 其他成本(元) | B11: =SUM('车次台账'!$AD$3:$AD$103)
A12: 净利润(元)（上面各项加减） | B12: =SUM('车次台账'!$M$3:$M$103)
A13: 单吨利润(元/吨) | B13: =IF(B5=0,0,B12/B5)
A14: 留存利润(元)·专项留存，不计入净利润 | B14: =SUM('车次台账'!$O$3:$O$103)
A16: 二、按路径（带票带货 / 配票·反向）
A17: 名称 | B17: 车次数 | C17: 吨位(吨) | D17: 结算金额(元) | E17: 净利润(元) | F17: 单吨利润(元/吨) | G17: 调货人提成(元) | H17: 留存利润(元)
A18: 配票/反向 | B18: =COUNTIFS('车次台账'!$E$3:$E$103,"配票/反向") | C18: =SUMIFS('车次台账'!$K$3:$K$103,'车次台账'!$E$3:$E$103,"配票/反向") | D18: =SUMIFS('车次台账'!$L$3:$L$103,'车次台账'!$E$3:$E$103,"配票/反向") | E18: =SUMIFS('车次台账'!$M$3:$M$103,'车次台账'!$E$3:$E$103,"配票/反向") | F18: =IF(C18=0,0,E18/C18) | G18: =SUMIFS('车次台账'!$AC$3:$AC$103,'车次台账'!$E$3:$E$103,"配票/反向") | H18: =SUMIFS('车次台账'!$O$3:$O$103,'车次台账'!$E$3:$E$103,"配票/反向")
A19: 带票带货 | B19: =COUNTIFS('车次台账'!$E$3:$E$103,"带票带货") | C19: =SUMIFS('车次台账'!$K$3:$K$103,'车次台账'!$E$3:$E$103,"带票带货") | D19: =SUMIFS('车次台账'!$L$3:$L$103,'车次台账'!$E$3:$E$103,"带票带货") | E19: =SUMIFS('车次台账'!$M$3:$M$103,'车次台账'!$E$3:$E$103,"带票带货") | F19: =IF(C19=0,0,E19/C19) | G19: =SUMIFS('车次台账'!$AC$3:$AC$103,'车次台账'!$E$3:$E$103,"带票带货") | H19: =SUMIFS('车次台账'!$O$3:$O$103,'车次台账'!$E$3:$E$103,"带票带货")
A20: 小计 | B20: =SUM(B18:B19) | C20: =SUM(C18:C19) | D20: =SUM(D18:D19) | E20: =SUM(E18:E19) | F20: =IF(C20=0,0,E20/C20) | G20: =SUM(G18:G19) | H20: =SUM(H18:H19)
A22: 三、按车/船
A23: 名称 | B23: 车次数 | C23: 吨位(吨) | D23: 结算金额(元) | E23: 净利润(元) | F23: 单吨利润(元/吨) | G23: 调货人提成(元) | H23: 留存利润(元)
A24: 车 | B24: =COUNTIFS('车次台账'!$D$3:$D$103,"车") | C24: =SUMIFS('车次台账'!$K$3:$K$103,'车次台账'!$D$3:$D$103,"车") | D24: =SUMIFS('车次台账'!$L$3:$L$103,'车次台账'!$D$3:$D$103,"车") | E24: =SUMIFS('车次台账'!$M$3:$M$103,'车次台账'!$D$3:$D$103,"车") | F24: =IF(C24=0,0,E24/C24) | G24: =SUMIFS('车次台账'!$AC$3:$AC$103,'车次台账'!$D$3:$D$103,"车") | H24: =SUMIFS('车次台账'!$O$3:$O$103,'车次台账'!$D$3:$D$103,"车")
A25: 船 | B25: =COUNTIFS('车次台账'!$D$3:$D$103,"船") | C25: =SUMIFS('车次台账'!$K$3:$K$103,'车次台账'!$D$3:$D$103,"船") | D25: =SUMIFS('车次台账'!$L$3:$L$103,'车次台账'!$D$3:$D$103,"船") | E25: =SUMIFS('车次台账'!$M$3:$M$103,'车次台账'!$D$3:$D$103,"船") | F25: =IF(C25=0,0,E25/C25) | G25: =SUMIFS('车次台账'!$AC$3:$AC$103,'车次台账'!$D$3:$D$103,"船") | H25: =SUMIFS('车次台账'!$O$3:$O$103,'车次台账'!$D$3:$D$103,"船")
A26: 小计 | B26: =SUM(B24:B25) | C26: =SUM(C24:C25) | D26: =SUM(D24:D25) | E26: =SUM(E24:E25) | F26: =IF(C26=0,0,E26/C26) | G26: =SUM(G24:G25) | H26: =SUM(H24:H25)
A28: 四、按链条规则
A29: 名称 | B29: 车次数 | C29: 吨位(吨) | D29: 结算金额(元) | E29: 净利润(元) | F29: 单吨利润(元/吨) | G29: 调货人提成(元) | H29: 留存利润(元)
A30: 反向 | B30: =COUNTIFS('车次台账'!$F$3:$F$103,"反向") | C30: =SUMIFS('车次台账'!$K$3:$K$103,'车次台账'!$F$3:$F$103,"反向") | D30: =SUMIFS('车次台账'!$L$3:$L$103,'车次台账'!$F$3:$F$103,"反向") | E30: =SUMIFS('车次台账'!$M$3:$M$103,'车次台账'!$F$3:$F$103,"反向") | F30: =IF(C30=0,0,E30/C30) | G30: =SUMIFS('车次台账'!$AC$3:$AC$103,'车次台账'!$F$3:$F$103,"反向") | H30: =SUMIFS('车次台账'!$O$3:$O$103,'车次台账'!$F$3:$F$103,"反向")
A31: 户头通道 | B31: =COUNTIFS('车次台账'!$F$3:$F$103,"户头通道") | C31: =SUMIFS('车次台账'!$K$3:$K$103,'车次台账'!$F$3:$F$103,"户头通道") | D31: =SUMIFS('车次台账'!$L$3:$L$103,'车次台账'!$F$3:$F$103,"户头通道") | E31: =SUMIFS('车次台账'!$M$3:$M$103,'车次台账'!$F$3:$F$103,"户头通道") | F31: =IF(C31=0,0,E31/C31) | G31: =SUMIFS('车次台账'!$AC$3:$AC$103,'车次台账'!$F$3:$F$103,"户头通道") | H31: =SUMIFS('车次台账'!$O$3:$O$103,'车次台账'!$F$3:$F$103,"户头通道")
A32: 直签带票 | B32: =COUNTIFS('车次台账'!$F$3:$F$103,"直签带票") | C32: =SUMIFS('车次台账'!$K$3:$K$103,'车次台账'!$F$3:$F$103,"直签带票") | D32: =SUMIFS('车次台账'!$L$3:$L$103,'车次台账'!$F$3:$F$103,"直签带票") | E32: =SUMIFS('车次台账'!$M$3:$M$103,'车次台账'!$F$3:$F$103,"直签带票") | F32: =IF(C32=0,0,E32/C32) | G32: =SUMIFS('车次台账'!$AC$3:$AC$103,'车次台账'!$F$3:$F$103,"直签带票") | H32: =SUMIFS('车次台账'!$O$3:$O$103,'车次台账'!$F$3:$F$103,"直签带票")
A33: 配票 | B33: =COUNTIFS('车次台账'!$F$3:$F$103,"配票") | C33: =SUMIFS('车次台账'!$K$3:$K$103,'车次台账'!$F$3:$F$103,"配票") | D33: =SUMIFS('车次台账'!$L$3:$L$103,'车次台账'!$F$3:$F$103,"配票") | E33: =SUMIFS('车次台账'!$M$3:$M$103,'车次台账'!$F$3:$F$103,"配票") | F33: =IF(C33=0,0,E33/C33) | G33: =SUMIFS('车次台账'!$AC$3:$AC$103,'车次台账'!$F$3:$F$103,"配票") | H33: =SUMIFS('车次台账'!$O$3:$O$103,'车次台账'!$F$3:$F$103,"配票")
A34: 小计 | B34: =SUM(B30:B33) | C34: =SUM(C30:C33) | D34: =SUM(D30:D33) | E34: =SUM(E30:E33) | F34: =IF(C34=0,0,E34/C34) | G34: =SUM(G30:G33) | H34: =SUM(H30:H33)
A36: 五、按调货人 | C36: 没填调货人的车次不在此表
A37: 名称 | B37: 车次数 | C37: 吨位(吨) | D37: 结算金额(元) | E37: 净利润(元) | F37: 单吨利润(元/吨) | G37: 调货人提成(元) | H37: 留存利润(元)
A38: 李涛 | B38: =COUNTIFS('车次台账'!$G$3:$G$103,"李涛") | C38: =SUMIFS('车次台账'!$K$3:$K$103,'车次台账'!$G$3:$G$103,"李涛") | D38: =SUMIFS('车次台账'!$L$3:$L$103,'车次台账'!$G$3:$G$103,"李涛") | E38: =SUMIFS('车次台账'!$M$3:$M$103,'车次台账'!$G$3:$G$103,"李涛") | F38: =IF(C38=0,0,E38/C38) | G38: =SUMIFS('车次台账'!$AC$3:$AC$103,'车次台账'!$G$3:$G$103,"李涛") | H38: =SUMIFS('车次台账'!$O$3:$O$103,'车次台账'!$G$3:$G$103,"李涛")
A39: 林凯 | B39: =COUNTIFS('车次台账'!$G$3:$G$103,"林凯") | C39: =SUMIFS('车次台账'!$K$3:$K$103,'车次台账'!$G$3:$G$103,"林凯") | D39: =SUMIFS('车次台账'!$L$3:$L$103,'车次台账'!$G$3:$G$103,"林凯") | E39: =SUMIFS('车次台账'!$M$3:$M$103,'车次台账'!$G$3:$G$103,"林凯") | F39: =IF(C39=0,0,E39/C39) | G39: =SUMIFS('车次台账'!$AC$3:$AC$103,'车次台账'!$G$3:$G$103,"林凯") | H39: =SUMIFS('车次台账'!$O$3:$O$103,'车次台账'!$G$3:$G$103,"林凯")
A40: 邓晶焱 | B40: =COUNTIFS('车次台账'!$G$3:$G$103,"邓晶焱") | C40: =SUMIFS('车次台账'!$K$3:$K$103,'车次台账'!$G$3:$G$103,"邓晶焱") | D40: =SUMIFS('车次台账'!$L$3:$L$103,'车次台账'!$G$3:$G$103,"邓晶焱") | E40: =SUMIFS('车次台账'!$M$3:$M$103,'车次台账'!$G$3:$G$103,"邓晶焱") | F40: =IF(C40=0,0,E40/C40) | G40: =SUMIFS('车次台账'!$AC$3:$AC$103,'车次台账'!$G$3:$G$103,"邓晶焱") | H40: =SUMIFS('车次台账'!$O$3:$O$103,'车次台账'!$G$3:$G$103,"邓晶焱")
A41: 闫东朋 | B41: =COUNTIFS('车次台账'!$G$3:$G$103,"闫东朋") | C41: =SUMIFS('车次台账'!$K$3:$K$103,'车次台账'!$G$3:$G$103,"闫东朋") | D41: =SUMIFS('车次台账'!$L$3:$L$103,'车次台账'!$G$3:$G$103,"闫东朋") | E41: =SUMIFS('车次台账'!$M$3:$M$103,'车次台账'!$G$3:$G$103,"闫东朋") | F41: =IF(C41=0,0,E41/C41) | G41: =SUMIFS('车次台账'!$AC$3:$AC$103,'车次台账'!$G$3:$G$103,"闫东朋") | H41: =SUMIFS('车次台账'!$O$3:$O$103,'车次台账'!$G$3:$G$103,"闫东朋")
A42: 陈杰 | B42: =COUNTIFS('车次台账'!$G$3:$G$103,"陈杰") | C42: =SUMIFS('车次台账'!$K$3:$K$103,'车次台账'!$G$3:$G$103,"陈杰") | D42: =SUMIFS('车次台账'!$L$3:$L$103,'车次台账'!$G$3:$G$103,"陈杰") | E42: =SUMIFS('车次台账'!$M$3:$M$103,'车次台账'!$G$3:$G$103,"陈杰") | F42: =IF(C42=0,0,E42/C42) | G42: =SUMIFS('车次台账'!$AC$3:$AC$103,'车次台账'!$G$3:$G$103,"陈杰") | H42: =SUMIFS('车次台账'!$O$3:$O$103,'车次台账'!$G$3:$G$103,"陈杰")
A43: 小计 | B43: =SUM(B38:B42) | C43: =SUM(C38:C42) | D43: =SUM(D38:D42) | E43: =SUM(E38:E42) | F43: =IF(C43=0,0,E43/C43) | G43: =SUM(G38:G42) | H43: =SUM(H38:H42)
A45: 六、按供货厂/车队
A46: 名称 | B46: 车次数 | C46: 吨位(吨) | D46: 结算金额(元) | E46: 净利润(元) | F46: 单吨利润(元/吨) | G46: 调货人提成(元) | H46: 留存利润(元)
...

Sheet 磅重明细
A1: 车次ID | B1: 结算日期 | C1: 车号/船号 | D1: 车/船 | E1: 路径 | F1: 链条 | G1: 调货人 | H1: 供货厂/车队 | I1: 货型大类 | J1: 货型 | K1: 扣杂(吨) | L1: 结算吨数(吨) | M1: 单价(元/吨) | N1: 切割费(元) | O1: 金额(元)
A2: 1 | B2: 46253 | C2: 苏DBB772 | D2: 车 | E2: 配票/反向 | F2: 配票 | G2: 林凯 | H2: 林凯车队 | I2: 废钢压块类 | J2: 废钢压块2 | K2: 0.9 | L2: 73.58 | M2: 2290 | N2: 0 | O2: 168498.2
A3: 2 | B3: 46254 | C3: 苏DFM060 | D3: 车 | E3: 配票/反向 | F3: 配票 | G3: 林凯 | H3: 林凯车队 | I3: 废钢 | J3: 中废1 | K3: 0.5 | L3: 34.8 | M3: 2430 | N3: 0 | O3: 84564
A4: 3 | B4: 46255 | C4: 苏DBB772 | D4: 车 | E4: 配票/反向 | F4: 配票 | G4: 林凯 | H4: 林凯车队 | I4: 铁水罐压块类 | J4: 铁加压块 | K4: 0.8 | L4: 81.16 | M4: 2480 | N4: 0 | O4: 201276.8
A5: 4 | B5: 46255 | C5: 皖M2A505 | D5: 车 | E5: 配票/反向 | F5: 配票 | H5: 俊兴 | I5: 废钢压块类 | J5: 废钢压块2 | K5: 0.3 | L5: 36.36 | M5: 2290 | N5: 0 | O5: 83264.4
A6: 5 | B6: 46255 | C6: 苏EQB977 | D6: 车 | E6: 配票/反向 | F6: 配票 | H6: 俊兴 | I6: 废钢压块类 | J6: 废钢压块2 | K6: 0.3 | L6: 32.94 | M6: 2290 | N6: 0 | O6: 75432.6
A7: 6 | B7: 46255 | C7: 苏BUK952 | D7: 车 | E7: 配票/反向 | F7: 配票 | G7: 林凯 | H7: 林凯车队 | I7: 废钢 | J7: 中废1 | K7: 0.175 | L7: 17.087 | M7: 2430 | N7: 0 | O7: 41521.41
A8: 6 | B8: 46255 | C8: 苏BUK952 | D8: 车 | E8: 配票/反向 | F8: 配票 | G8: 林凯 | H8: 林凯车队 | I8: 废钢 | J8: 中废2 | K8: 0.075 | L8: 7.323 | M8: 2390 | N8: 0 | O8: 17501.97
A9: 7 | B9: 46256 | C9: 苏DBB772 | D9: 车 | E9: 配票/反向 | F9: 配票 | G9: 林凯 | H9: 林凯车队 | I9: 废钢压块类 | J9: 废钢压块2 | K9: 1.4 | L9: 69.5 | M9: 2290 | N9: 0 | O9: 159155
A10: 8 | B10: 46256 | C10: 苏E9W908 | D10: 车 | E10: 配票/反向 | F10: 配票 | G10: 邓晶焱 | H10: 邓晶焱车队 | I10: 废钢压块类 | J10: 废钢压块1 | K10: 1 | L10: 39.16 | M10: 2330 | N10: 0 | O10: 91242.8
A11: 9 | B11: 46256 | C11: 苏MAK862 | D11: 车 | E11: 配票/反向 | F11: 配票 | H11: 俊兴 | I11: 废钢压块类 | J11: 废钢压块2 | K11: 0.6 | L11: 34.24 | M11: 2290 | N11: 0 | O11: 78409.6
A12: 10 | B12: 46259 | C12: 苏DBE075 | D12: 车 | E12: 配票/反向 | F12: 配票 | G12: 林凯 | H12: 林凯车队 | I12: 废钢压块类 | J12: 废钢压块2 | K12: 0.84 | L12: 56.7 | M12: 2260 | N12: 0 | O12: 128142
A13: 10 | B13: 46259 | C13: 苏DBE075 | D13: 车 | E13: 配票/反向 | F13: 配票 | G13: 林凯 | H13: 林凯车队 | I13: 废钢压块类 | J13: 废钢压块3 | K13: 0.36 | L13: 24.3 | M13: 2300 | N13: 0 | O13: 55890
A14: 11 | B14: 46261 | C14: 苏淮货16776 | D14: 船 | E14: 配票/反向 | F14: 配票 | H14: 俊兴 | I14: 历史导入-待归类 | J14: 未注明 | K14: 0 | L14: 560.39 | N14: 0 | O14: 1344115.9
A15: 12 | B15: 46261 | C15: 苏NEX375 | D15: 车 | E15: 配票/反向 | F15: 配票 | G15: 林凯 | H15: 林凯车队 | I15: 废钢压块类 | J15: 废钢压块2 | K15: 0.45 | L15: 40.27 | M15: 2320 | N15: 0 | O15: 93426.4
A16: 13 | B16: 46261 | C16: 苏DFM060 | D16: 车 | E16: 配票/反向 | F16: 配票 | G16: 林凯 | H16: 林凯车队 | I16: 废钢 | J16: 中废1 | K16: 0.1 | L16: 17.15 | M16: 2440 | N16: 0 | O16: 41846
A17: 13 | B17: 46261 | C17: 苏DFM060 | D17: 车 | E17: 配票/反向 | F17: 配票 | G17: 林凯 | H17: 林凯车队 | I17: 废钢 | J17: 剪切中废1 | K17: 0.1 | L17: 17.15 | M17: 2470 | N17: 0 | O17: 42360.5
A18: 14 | B18: 46261 | C18: 苏DBB772 | D18: 车 | E18: 配票/反向 | F18: 配票 | G18: 林凯 | H18: 君盛 | I18: 废钢压块类 | J18: 普通压块 | K18: 1 | L18: 66.22 | M18: 2240 | N18: 0 | O18: 148332.8
A19: 15 | B19: 46261 | C19: 苏BDK567 | D19: 车 | E19: 配票/反向 | F19: 配票 | G19: 林凯 | H19: 林凯车队 | I19: 废钢 | J19: 中废1 | K19: 0.125 | L19: 16.025 | M19: 2440 | N19: 0 | O19: 39101
A20: 15 | B20: 46261 | C20: 苏BDK567 | D20: 车 | E20: 配票/反向 | F20: 配票 | G20: 林凯 | H20: 林凯车队 | I20: 废钢 | J20: 剪切中废1 | K20: 0.125 | L20: 16.025 | M20: 2470 | N20: 0 | O20: 39581.75
A21: 16 | B21: 46261 | C21: 苏BZP839 | D21: 车 | E21: 配票/反向 | F21: 配票 | G21: 林凯 | H21: 林凯车队 | I21: 废钢 | J21: 中废2 | K21: 0.315 | L21: 19.929 | M21: 2400 | N21: 70 | O21: 47759.6
A22: 16 | B22: 46261 | C22: 苏BZP839 | D22: 车 | E22: 配票/反向 | F22: 配票 | G22: 林凯 | H22: 林凯车队 | I22: 废钢 | J22: 中废1 | K22: 0.135 | L22: 8.541 | M22: 2440 | N22: 30 | O22: 20810.04
A23: 17 | B23: 46261 | C23: 苏NEV615 | D23: 车 | E23: 配票/反向 | F23: 配票 | H23: 俊兴 | I23: 废钢压块类 | J23: 废钢压块2 | K23: 0.5 | L23: 38.78 | M23: 2320 | N23: 0 | O23: 89969.6
A24: 18 | B24: 46261 | C24: 苏ERS080 | D24: 车 | E24: 配票/反向 | F24: 配票 | G24: 林凯 | H24: 林凯车队 | I24: 废钢 | J24: 中废1 | K24: 0.15 | L24: 24.19 | M24: 2440 | N24: 0 | O24: 59023.6
A25: 18 | B25: 46261 | C25: 苏ERS080 | D25: 车 | E25: 配票/反向 | F25: 配票 | G25: 林凯 | H25: 林凯车队 | I25: 废钢压块类 | J25: 废钢压块1 | K25: 0.15 | L25: 24.19 | M25: 2360 | N25: 0 | O25: 57088.4
A26: 19 | B26: 46261 | C26: 鲁济宁货4095 | D26: 船 | E26: 配票/反向 | F26: 配票 | H26: 俊兴 | I26: 历史导入-待归类 | J26: 未注明 | K26: 0 | L26: 518.48 | N26: 0 | O26: 1271259
A27: 20 | B27: 46262 | C27: 苏DBE075 | D27: 车 | E27: 配票/反向 | F27: 配票 | G27: 林凯 | H27: 林凯车队 | I27: 废钢压块类 | J27: 废钢压块2 | K27: 0.2 | L27: 38.2 | M27: 2320 | N27: 0 | O27: 88624
A28: 21 | B28: 46262 | C28: 苏DBX137 | D28: 车 | E28: 配票/反向 | F28: 配票 | G28: 林凯 | H28: 林凯车队 | I28: 废钢 | J28: 中废2 | K28: 0.3 | L28: 18.52 | M28: 2400 | N28: 0 | O28: 44448
A29: 22 | B29: 46262 | C29: 苏DFB287 | D29: 车 | E29: 配票/反向 | F29: 配票 | G29: 林凯 | H29: 林凯车队 | I29: 废钢压块类 | J29: 废钢压块2 | K29: 0.3 | L29: 40.95 | M29: 2320 | N29: 0 | O29: 95004
A30: 22 | B30: 46262 | C30: 苏DFB287 | D30: 车 | E30: 配票/反向 | F30: 配票 | G30: 林凯 | H30: 林凯车队 | I30: 废钢压块类 | J30: 废钢压块1 | K30: 0.3 | L30: 40.95 | M30: 2360 | N30: 0 | O30: 96642
A31: 23 | B31: 46262 | C31: 苏DFM060 | D31: 车 | E31: 配票/反向 | F31: 配票 | G31: 林凯 | H31: 林凯车队 | I31: 废钢压块类 | J31: 废钢压块1 | K31: 0.5 | L31: 55.18 | M31: 2360 | N31: 0 | O31: 130224.8
A32: 24 | B32: 46262 | C32: 苏DBB772 | D32: 车 | E32: 配票/反向 | F32: 配票 | G32: 林凯 | H32: 林凯车队 | I32: 废钢 | J32: 中废1 | K32: 0.35 | L32: 44.212 | M32: 2440 | N32: 0 | O32: 107877.28
A33: 24 | B33: 46262 | C33: 苏DBB772 | D33: 车 | E33: 配票/反向 | F33: 配票 | G33: 林凯 | H33: 林凯车队 | I33: 废钢 | J33: 中废2 | K33: 0.15 | L33: 18.948 | M33: 2400 | N33: 0 | O33: 45475.2
A34: 25 | B34: 46262 | C34: 苏BDK567 | D34: 车 | E34: 配票/反向 | F34: 配票 | G34: 林凯 | H34: 林凯车队 | I34: 废钢 | J34: 中废1 | K34: 0.3 | L34: 34.22 | M34: 2440 | N34: 0 | O34: 83496.8
A35: 26 | B35: 46262 | C35: 苏BUK952 | D35: 车 | E35: 配票/反向 | F35: 配票 | G35: 林凯 | H35: 林凯车队 | I35: 废钢 | J35: 中废1 | K35: 0.2 | L35: 27.22 | M35: 2440 | N35: 0 | O35: 66416.8
A36: 27 | B36: 46262 | C36: 皖KQ1052 | D36: 车 | E36: 配票/反向 | F36: 配票 | H36: 俊兴 | I36: 废钢压块类 | J36: 废钢压块2 | K36: 0.245 | L36: 24.143 | M36: 2320 | N36: 0 | O36: 56011.76
A37: 27 | B37: 46262 | C37: 皖KQ1052 | D37: 车 | E37: 配票/反向 | F37: 配票 | H37: 俊兴 | I37: 废钢压块类 | J37: 废钢压块1 | K37: 0.105 | L37: 10.347 | M37: 2360 | N37: 0 | O37: 24418.92
A38: 28 | B38: 46262 | C38: 苏DBE075 | D38: 车 | E38: 配票/反向 | F38: 配票 | G38: 林凯 | H38: 林凯车队 | I38: 废钢压块类 | J38: 普通压块 | K38: 1.9 | L38: 67.8 | M38: 2240 | N38: 0 | O38: 151872
A39: 29 | B39: 46262 | C39: 冀A224E6 | D39: 车 | E39: 配票/反向 | F39: 配票 | G39: 林凯 | H39: 林凯车队 | I39: 废钢 | J39: 剪切中废1 | K39: 0.28 | L39: 20.3 | M39: 2470 | N39: 0 | O39: 50141
A40: 29 | B40: 46262 | C40: 冀A224E6 | D40: 车 | E40: 配票/反向 | F40: 配票 | G40: 林凯 | H40: 林凯车队 | I40: 废钢 | J40: 中废1 | K40: 0.12 | L40: 8.7 | M40: 2440 | N40: 0 | O40: 21228
...

Sheet 票款追踪
A1: 车次ID | B1: 结算日期 | C1: 车号/船号 | D1: 路径 | E1: 开票路径 | F1: 供货厂/车队 | G1: 线 | H1: 环节 | I1: 从 | J1: 到 | K1: 应登记(票额)(元) | L1: 已登记(元) | M1: 待登记(元) | N1: 状态 | O1: 账龄(天) | P1: 批次ID
A2: 1 | B2: 46253 | C2: 苏DBB772 | D2: 配票/反向 | E2: 我们配票（经俊兴） | F2: 林凯车队 | G2: 开票 | H2: 销项→欧冶 | I2: 俊兴 | J2: 欧冶物宝 | K2: 166805.86 | L2: 0 | M2: =IF(OR(N2="已登记",LEFT(N2,2)="按状"),0,K2-L2) | N2: 按状态视为已完成(历史)
A3: 1 | B3: 46253 | C3: 苏DBB772 | D3: 配票/反向 | E3: 我们配票（经俊兴） | F3: 林凯车队 | G3: 回款 | H3: 欧冶回款 | I3: 欧冶物宝 | J3: 俊兴 | K3: 166805.86 | L3: 0 | M3: =IF(OR(N3="已登记",LEFT(N3,2)="按状"),0,K3-L3) | N3: 待登记 | O3: 0
A4: 1 | B4: 46253 | C4: 苏DBB772 | D4: 配票/反向 | E4: 我们配票（经俊兴） | F4: 林凯车队 | G4: 回款 | H4: 到客户账户 | I4: 俊兴 | J4: 林凯车队·客户账户 | K4: 166805.86 | L4: 0 | M4: =IF(OR(N4="已登记",LEFT(N4,2)="按状"),0,K4-L4) | N4: 未开始(前一环节未完成)
A5: 2 | B5: 46254 | C5: 苏DFM060 | D5: 配票/反向 | E5: 我们配票（经俊兴） | F5: 林凯车队 | G5: 开票 | H5: 销项→欧冶 | I5: 俊兴 | J5: 欧冶物宝 | K5: 83763.6 | L5: 0 | M5: =IF(OR(N5="已登记",LEFT(N5,2)="按状"),0,K5-L5) | N5: 按状态视为已完成(历史)
A6: 2 | B6: 46254 | C6: 苏DFM060 | D6: 配票/反向 | E6: 我们配票（经俊兴） | F6: 林凯车队 | G6: 回款 | H6: 欧冶回款 | I6: 欧冶物宝 | J6: 俊兴 | K6: 83763.6 | L6: 0 | M6: =IF(OR(N6="已登记",LEFT(N6,2)="按状"),0,K6-L6) | N6: 待登记 | O6: 32
A7: 2 | B7: 46254 | C7: 苏DFM060 | D7: 配票/反向 | E7: 我们配票（经俊兴） | F7: 林凯车队 | G7: 回款 | H7: 到客户账户 | I7: 俊兴 | J7: 林凯车队·客户账户 | K7: 83763.6 | L7: 0 | M7: =IF(OR(N7="已登记",LEFT(N7,2)="按状"),0,K7-L7) | N7: 未开始(前一环节未完成)
A8: 3 | B8: 46255 | C8: 苏DBB772 | D8: 配票/反向 | E8: 我们配票（经俊兴） | F8: 林凯车队 | G8: 开票 | H8: 销项→欧冶 | I8: 俊兴 | J8: 欧冶物宝 | K8: 199410.12 | L8: 0 | M8: =IF(OR(N8="已登记",LEFT(N8,2)="按状"),0,K8-L8) | N8: 按状态视为已完成(历史)
A9: 3 | B9: 46255 | C9: 苏DBB772 | D9: 配票/反向 | E9: 我们配票（经俊兴） | F9: 林凯车队 | G9: 回款 | H9: 欧冶回款 | I9: 欧冶物宝 | J9: 俊兴 | K9: 199410.12 | L9: 0 | M9: =IF(OR(N9="已登记",LEFT(N9,2)="按状"),0,K9-L9) | N9: 待登记 | O9: 31
A10: 3 | B10: 46255 | C10: 苏DBB772 | D10: 配票/反向 | E10: 我们配票（经俊兴） | F10: 林凯车队 | G10: 回款 | H10: 到客户账户 | I10: 俊兴 | J10: 林凯车队·客户账户 | K10: 199410.12 | L10: 0 | M10: =IF(OR(N10="已登记",LEFT(N10,2)="按状"),0,K10-L10) | N10: 未开始(前一环节未完成)
A11: 4 | B11: 46255 | C11: 皖M2A505 | D11: 配票/反向 | E11: 我们配票（经俊兴） | F11: 俊兴 | G11: 开票 | H11: 销项→欧冶 | I11: 俊兴 | J11: 欧冶物宝 | K11: 82428.12 | L11: 0 | M11: =IF(OR(N11="已登记",LEFT(N11,2)="按状"),0,K11-L11) | N11: 按状态视为已完成(历史)
A12: 4 | B12: 46255 | C12: 皖M2A505 | D12: 配票/反向 | E12: 我们配票（经俊兴） | F12: 俊兴 | G12: 回款 | H12: 欧冶回款 | I12: 欧冶物宝 | J12: 俊兴 | K12: 82428.12 | L12: 0 | M12: =IF(OR(N12="已登记",LEFT(N12,2)="按状"),0,K12-L12) | N12: 待登记 | O12: 31
A13: 4 | B13: 46255 | C13: 皖M2A505 | D13: 配票/反向 | E13: 我们配票（经俊兴） | F13: 俊兴 | G13: 回款 | H13: 到客户账户 | I13: 俊兴 | J13: 俊兴·客户账户 | K13: 82428.12 | L13: 0 | M13: =IF(OR(N13="已登记",LEFT(N13,2)="按状"),0,K13-L13) | N13: 未开始(前一环节未完成)
A14: 5 | B14: 46255 | C14: 苏EQB977 | D14: 配票/反向 | E14: 我们配票（经俊兴） | F14: 俊兴 | G14: 开票 | H14: 销项→欧冶 | I14: 俊兴 | J14: 欧冶物宝 | K14: 74674.98 | L14: 0 | M14: =IF(OR(N14="已登记",LEFT(N14,2)="按状"),0,K14-L14) | N14: 按状态视为已完成(历史)
A15: 5 | B15: 46255 | C15: 苏EQB977 | D15: 配票/反向 | E15: 我们配票（经俊兴） | F15: 俊兴 | G15: 回款 | H15: 欧冶回款 | I15: 欧冶物宝 | J15: 俊兴 | K15: 74674.98 | L15: 0 | M15: =IF(OR(N15="已登记",LEFT(N15,2)="按状"),0,K15-L15) | N15: 待登记 | O15: 31
A16: 5 | B16: 46255 | C16: 苏EQB977 | D16: 配票/反向 | E16: 我们配票（经俊兴） | F16: 俊兴 | G16: 回款 | H16: 到客户账户 | I16: 俊兴 | J16: 俊兴·客户账户 | K16: 74674.98 | L16: 0 | M16: =IF(OR(N16="已登记",LEFT(N16,2)="按状"),0,K16-L16) | N16: 未开始(前一环节未完成)
A17: 6 | B17: 46255 | C17: 苏BUK952 | D17: 配票/反向 | E17: 我们配票（经俊兴） | F17: 林凯车队 | G17: 开票 | H17: 销项→欧冶 | I17: 俊兴 | J17: 欧冶物宝 | K17: 58461.95 | L17: 0 | M17: =IF(OR(N17="已登记",LEFT(N17,2)="按状"),0,K17-L17) | N17: 按状态视为已完成(历史)
A18: 6 | B18: 46255 | C18: 苏BUK952 | D18: 配票/反向 | E18: 我们配票（经俊兴） | F18: 林凯车队 | G18: 回款 | H18: 欧冶回款 | I18: 欧冶物宝 | J18: 俊兴 | K18: 58461.95 | L18: 0 | M18: =IF(OR(N18="已登记",LEFT(N18,2)="按状"),0,K18-L18) | N18: 待登记 | O18: 31
A19: 6 | B19: 46255 | C19: 苏BUK952 | D19: 配票/反向 | E19: 我们配票（经俊兴） | F19: 林凯车队 | G19: 回款 | H19: 到客户账户 | I19: 俊兴 | J19: 林凯车队·客户账户 | K19: 58461.95 | L19: 0 | M19: =IF(OR(N19="已登记",LEFT(N19,2)="按状"),0,K19-L19) | N19: 未开始(前一环节未完成)
A20: 7 | B20: 46256 | C20: 苏DBB772 | D20: 配票/反向 | E20: 我们配票（经俊兴） | F20: 林凯车队 | G20: 开票 | H20: 销项→欧冶 | I20: 俊兴 | J20: 欧冶物宝 | K20: 157556.5 | L20: 0 | M20: =IF(OR(N20="已登记",LEFT(N20,2)="按状"),0,K20-L20) | N20: 按状态视为已完成(历史)
A21: 7 | B21: 46256 | C21: 苏DBB772 | D21: 配票/反向 | E21: 我们配票（经俊兴） | F21: 林凯车队 | G21: 回款 | H21: 欧冶回款 | I21: 欧冶物宝 | J21: 俊兴 | K21: 157556.5 | L21: 0 | M21: =IF(OR(N21="已登记",LEFT(N21,2)="按状"),0,K21-L21) | N21: 待登记 | O21: 30
A22: 7 | B22: 46256 | C22: 苏DBB772 | D22: 配票/反向 | E22: 我们配票（经俊兴） | F22: 林凯车队 | G22: 回款 | H22: 到客户账户 | I22: 俊兴 | J22: 林凯车队·客户账户 | K22: 157556.5 | L22: 0 | M22: =IF(OR(N22="已登记",LEFT(N22,2)="按状"),0,K22-L22) | N22: 未开始(前一环节未完成)
A23: 8 | B23: 46256 | C23: 苏E9W908 | D23: 配票/反向 | E23: 我们配票（经俊兴） | F23: 邓晶焱车队 | G23: 开票 | H23: 销项→欧冶 | I23: 俊兴 | J23: 欧冶物宝 | K23: 90342.12 | L23: 0 | M23: =IF(OR(N23="已登记",LEFT(N23,2)="按状"),0,K23-L23) | N23: 按状态视为已完成(历史)
A24: 8 | B24: 46256 | C24: 苏E9W908 | D24: 配票/反向 | E24: 我们配票（经俊兴） | F24: 邓晶焱车队 | G24: 回款 | H24: 欧冶回款 | I24: 欧冶物宝 | J24: 俊兴 | K24: 90342.12 | L24: 0 | M24: =IF(OR(N24="已登记",LEFT(N24,2)="按状"),0,K24-L24) | N24: 待登记 | O24: 30
A25: 8 | B25: 46256 | C25: 苏E9W908 | D25: 配票/反向 | E25: 我们配票（经俊兴） | F25: 邓晶焱车队 | G25: 回款 | H25: 到客户账户 | I25: 俊兴 | J25: 邓晶焱车队·客户账户 | K25: 90342.12 | L25: 0 | M25: =IF(OR(N25="已登记",LEFT(N25,2)="按状"),0,K25-L25) | N25: 未开始(前一环节未完成)
A26: 9 | B26: 46256 | C26: 苏MAK862 | D26: 配票/反向 | E26: 我们配票（经俊兴） | F26: 俊兴 | G26: 开票 | H26: 销项→欧冶 | I26: 俊兴 | J26: 欧冶物宝 | K26: 77622.08 | L26: 0 | M26: =IF(OR(N26="已登记",LEFT(N26,2)="按状"),0,K26-L26) | N26: 按状态视为已完成(历史)
A27: 9 | B27: 46256 | C27: 苏MAK862 | D27: 配票/反向 | E27: 我们配票（经俊兴） | F27: 俊兴 | G27: 回款 | H27: 欧冶回款 | I27: 欧冶物宝 | J27: 俊兴 | K27: 77622.08 | L27: 0 | M27: =IF(OR(N27="已登记",LEFT(N27,2)="按状"),0,K27-L27) | N27: 待登记 | O27: 30
A28: 9 | B28: 46256 | C28: 苏MAK862 | D28: 配票/反向 | E28: 我们配票（经俊兴） | F28: 俊兴 | G28: 回款 | H28: 到客户账户 | I28: 俊兴 | J28: 俊兴·客户账户 | K28: 77622.08 | L28: 0 | M28: =IF(OR(N28="已登记",LEFT(N28,2)="按状"),0,K28-L28) | N28: 未开始(前一环节未完成)
A29: 10 | B29: 46259 | C29: 苏DBE075 | D29: 配票/反向 | E29: 我们配票（经俊兴） | F29: 林凯车队 | G29: 开票 | H29: 销项→欧冶 | I29: 俊兴 | J29: 欧冶物宝 | K29: 182169 | L29: 0 | M29: =IF(OR(N29="已登记",LEFT(N29,2)="按状"),0,K29-L29) | N29: 按状态视为已完成(历史)
A30: 10 | B30: 46259 | C30: 苏DBE075 | D30: 配票/反向 | E30: 我们配票（经俊兴） | F30: 林凯车队 | G30: 回款 | H30: 欧冶回款 | I30: 欧冶物宝 | J30: 俊兴 | K30: 182169 | L30: 0 | M30: =IF(OR(N30="已登记",LEFT(N30,2)="按状"),0,K30-L30) | N30: 待登记 | O30: 27
A31: 10 | B31: 46259 | C31: 苏DBE075 | D31: 配票/反向 | E31: 我们配票（经俊兴） | F31: 林凯车队 | G31: 回款 | H31: 到客户账户 | I31: 俊兴 | J31: 林凯车队·客户账户 | K31: 182169 | L31: 0 | M31: =IF(OR(N31="已登记",LEFT(N31,2)="按状"),0,K31-L31) | N31: 未开始(前一环节未完成)
A32: 11 | B32: 46261 | C32: 苏淮货16776 | D32: 配票/反向 | E32: 我们配票（经俊兴） | F32: 俊兴 | G32: 开票 | H32: 销项→欧冶 | I32: 俊兴 | J32: 欧冶物宝 | K32: 1331226.9 | L32: 0 | M32: =IF(OR(N32="已登记",LEFT(N32,2)="按状"),0,K32-L32) | N32: 按状态视为已完成(历史)
A33: 11 | B33: 46261 | C33: 苏淮货16776 | D33: 配票/反向 | E33: 我们配票（经俊兴） | F33: 俊兴 | G33: 回款 | H33: 欧冶回款 | I33: 欧冶物宝 | J33: 俊兴 | K33: 1331226.9 | L33: 0 | M33: =IF(OR(N33="已登记",LEFT(N33,2)="按状"),0,K33-L33) | N33: 待登记 | O33: 25
A34: 11 | B34: 46261 | C34: 苏淮货16776 | D34: 配票/反向 | E34: 我们配票（经俊兴） | F34: 俊兴 | G34: 回款 | H34: 到客户账户 | I34: 俊兴 | J34: 俊兴·客户账户 | K34: 1331226.9 | L34: 0 | M34: =IF(OR(N34="已登记",LEFT(N34,2)="按状"),0,K34-L34) | N34: 未开始(前一环节未完成)
A35: 12 | B35: 46261 | C35: 苏NEX375 | D35: 配票/反向 | E35: 我们配票（经俊兴） | F35: 林凯车队 | G35: 开票 | H35: 销项→欧冶 | I35: 俊兴 | J35: 欧冶物宝 | K35: 92500.19 | L35: 0 | M35: =IF(OR(N35="已登记",LEFT(N35,2)="按状"),0,K35-L35) | N35: 按状态视为已完成(历史)
A36: 12 | B36: 46261 | C36: 苏NEX375 | D36: 配票/反向 | E36: 我们配票（经俊兴） | F36: 林凯车队 | G36: 回款 | H36: 欧冶回款 | I36: 欧冶物宝 | J36: 俊兴 | K36: 92500.19 | L36: 0 | M36: =IF(OR(N36="已登记",LEFT(N36,2)="按状"),0,K36-L36) | N36: 待登记 | O36: 25
A37: 12 | B37: 46261 | C37: 苏NEX375 | D37: 配票/反向 | E37: 我们配票（经俊兴） | F37: 林凯车队 | G37: 回款 | H37: 到客户账户 | I37: 俊兴 | J37: 林凯车队·客户账户 | K37: 92500.19 | L37: 0 | M37: =IF(OR(N37="已登记",LEFT(N37,2)="按状"),0,K37-L37) | N37: 未开始(前一环节未完成)
A38: 13 | B38: 46261 | C38: 苏DFM060 | D38: 配票/反向 | E38: 我们配票（经俊兴） | F38: 林凯车队 | G38: 开票 | H38: 销项→欧冶 | I38: 俊兴 | J38: 欧冶物宝 | K38: 83417.6 | L38: 0 | M38: =IF(OR(N38="已登记",LEFT(N38,2)="按状"),0,K38-L38) | N38: 按状态视为已完成(历史)
A39: 13 | B39: 46261 | C39: 苏DFM060 | D39: 配票/反向 | E39: 我们配票（经俊兴） | F39: 林凯车队 | G39: 回款 | H39: 欧冶回款 | I39: 欧冶物宝 | J39: 俊兴 | K39: 83417.6 | L39: 0 | M39: =IF(OR(N39="已登记",LEFT(N39,2)="按状"),0,K39-L39) | N39: 待登记 | O39: 25
A40: 13 | B40: 46261 | C40: 苏DFM060 | D40: 配票/反向 | E40: 我们配票（经俊兴） | F40: 林凯车队 | G40: 回款 | H40: 到客户账户 | I40: 俊兴 | J40: 林凯车队·客户账户 | K40: 83417.6 | L40: 0 | M40: =IF(OR(N40="已登记",LEFT(N40,2)="按状"),0,K40-L40) | N40: 未开始(前一环节未完成)
...

Sheet 批次记录
A1: 批次ID | B1: 日期 | C1: 类型 | D1: 环节 | E1: 从 | F1: 到 | G1: 单号/流水号 | H1: 收款账户 | I1: 车次数 | J1: 批次金额(元) | K1: 备注 | M1: 明细：批次ID | N1: 车次ID | O1: 车号 | P1: 分摊金额(元)
A2: 还没有登记过批次（在系统「回款追踪」页勾选车次登记）

Sheet 票源额度
A1: 票源方 | B1: 类型 | C1: 额度周期 | D1: 周期起 | E1: 额度上限(元) | F1: 预警线(元) | G1: 已用(元) | H1: 占用比例 | I1: 剩余额度(元) | J1: 状态
A2: 反向-闫东朋 | B2: 反向自然人 | C2: 年度 | D2: 2026-01-01 | E2: 3500000 | F2: 1800000 | G2: 1035736.6 | H2: =IF(N(E2)=0,0,G2/E2) | I2: =IF(N(E2)=0,0,E2-G2) | J2: =IF(N(E2)=0,"未设额度",IF(G2>=E2,"已超额度",IF(AND(N(F2)>0,G2>=F2),"超预警线",IF(H2>=0.9,"接近额度","正常"))))
A3: 俊兴 | B3: 前端公司 | C3: 月度 | D3: 2026-09-01 | E3: 5000000 | G3: 2743286.9 | H3: =IF(N(E3)=0,0,G3/E3) | I3: =IF(N(E3)=0,0,E3-G3) | J3: =IF(N(E3)=0,"未设额度",IF(G3>=E3,"已超额度",IF(AND(N(F3)>0,G3>=F3),"超预警线",IF(H3>=0.9,"接近额度","正常"))))
A4: 益周 | B4: 前端公司 | C4: 月度 | D4: 2026-09-01 | E4: 5000000 | G4: 2498501.4 | H4: =IF(N(E4)=0,0,G4/E4) | I4: =IF(N(E4)=0,0,E4-G4) | J4: =IF(N(E4)=0,"未设额度",IF(G4>=E4,"已超额度",IF(AND(N(F4)>0,G4>=F4),"超预警线",IF(H4>=0.9,"接近额度","正常"))))
A5: 煌烽 | B5: 前端公司 | C5: 月度 | D5: 2026-09-01 | E5: 5000000 | G5: 4842789.2 | H5: =IF(N(E5)=0,0,G5/E5) | I5: =IF(N(E5)=0,0,E5-G5) | J5: =IF(N(E5)=0,"未设额度",IF(G5>=E5,"已超额度",IF(AND(N(F5)>0,G5>=F5),"超预警线",IF(H5>=0.9,"接近额度","正常"))))
A6: 反向-尹鹏飞 | B6: 反向自然人 | C6: 年度 | D6: 2026-01-01 | E6: 3500000 | F6: 1800000 | G6: 1563945.8 | H6: =IF(N(E6)=0,0,G6/E6) | I6: =IF(N(E6)=0,0,E6-G6) | J6: =IF(N(E6)=0,"未设额度",IF(G6>=E6,"已超额度",IF(AND(N(F6)>0,G6>=F6),"超预警线",IF(H6>=0.9,"接近额度","正常"))))
A8: 已用 = 本周期内该票源车次的票额(结算金额 − 吨位×垫资费单价)，与系统首页「票源额度水位」同口径。
