Workbook

Sheet 差异汇总
A1: 财务「发货记录表」与系统车次比对
A2: 数据：财务表 12 个分表共 101 行；系统为你电脑上 2026-09-22 的数据库（101 车，不含作废）。利润口径：系统为主营净利润（不含票差留存）。
A4: 财务利润合计（101行全部） | B4: =SUM(逐车比对!H2:H102) -> 161231.5 | C4: 比财务表自己的合计单元格(林凯!L23=160,390.91)多 840.59：它的公式漏了闫东鹏 9/21 那一行
A5: 系统利润合计（101车） | B5: =SUM(逐车比对!Q2:Q102) -> 186934.98 | C5: 系统首页「累计利润」；逐车比对里 #33、#34 两车合在一行
A6: 总差额（系统−财务） | B6: =B5-B4 -> 25703.484
A8: 差额拆解
A9: 原因 | B9: 金额(系统−财务) | C9: 涉及车数 | D9: 说明 | E9: 谁对？需要确认什么
A10: 量补单价 | B10: =SUM(逐车比对!S2:S102) -> 12531.4 | C10: =COUNTIF(逐车比对!S2:S102,">0.5")+COUNTIF(逐车比对!S2:S102,"<-0.5") -> 38 | D10: 8/26 之后结算的车，系统量补按 25 元/吨（本期 8/26~9/25 累计已过档），财务在「林凯」表 8/26~9/01 的车、「邓晶焱」8/27、8/29 两车仍按 20 元/吨；但财务李涛 8/30、高栾凤 8/28、王荣胜 8/29 又按 25 算，财务自己前后不一致 | E10: 确认 8/26~9/05 这段林凯/邓晶焱的车量补到底是 20 还是 25。如果和林凯另有约定（例如这段量补只给到 20），告诉我，系统可以按调货人+时段设
A11: 调货提成 | B11: =SUM(逐车比对!T2:T102) -> 4460.55 | C11: =COUNTIF(逐车比对!T2:T102,">0.5")+COUNTIF(逐车比对!T2:T102,"<-0.5") -> 8 | D11: 财务把 7 车记在林凯名下并扣 5 元/吨提成（8/21 皖M2A505、苏EQB977，8/22 苏MAK862，8/26 苏淮货16776 船，8/30 苏DBE961、苏DFB287、冀A224E6），系统这几车没填调货人（供货厂写的俊兴），没扣提成；另有合并行里的冀A224E6 20 吨 | E11: 确认这几车是不是林凯调的。是的话在系统里补上调货人=林凯，利润会减少这部分
A12: 票点系数 | B12: =SUM(逐车比对!U2:U102) -> 9157.46 | C12: =COUNTIF(逐车比对!U2:U102,">0.5")+COUNTIF(逐车比对!U2:U102,"<-0.5") -> 5 | D12: 煌烽票源的 5 车（苏兴达货8566、皖四航6058 两条船，邓晶焱 9/15、9/16，高栾凤 9/15），财务利润公式用 ×0.865（俊兴 13.5%），而同一张表的“带票公司付”和「林凯」表的煌烽车都用 ×0.868（煌烽 13.2%） | E12: 大概率是财务公式没改：煌烽的车应该用 0.868，系统是对的。请财务确认
A13: 给客户点位 | B13: =SUM(逐车比对!V2:V102) -> 2542.52 | C13: =COUNTIF(逐车比对!V2:V102,">0.5")+COUNTIF(逐车比对!V2:V102,"<-0.5") -> 1 | D13: 王荣胜 8/29 鲁济宁货4095 船：财务实际付款 = 结算额×0.862（按 13.8%），系统按统一 14%（×0.86） | E13: 财务“实际付款金额”是真付出去的钱：如果这条船当时就是按 13.8% 付的，系统这车要把“给客户付”改成 13.8%（车次详情里本车费率可改），利润会少 2,542.52
A14: 切割费 | B14: =SUM(逐车比对!W2:W102) -> -800 | C14: =COUNTIF(逐车比对!W2:W102,">0.5")+COUNTIF(逐车比对!W2:W102,"<-0.5") -> 4 | D14: 5 车有切割费（苏BZP839 100、苏GE2356 100、苏NHY179 100、苏DBE075(鑫景通) 500，合计 800；李涛皖LE9644 的 16310 两边利润一致未计入）。两边的结算金额里都已经扣掉了切割费；系统又从利润里再减一次，财务没有 | E14: 要定一个规则：钢厂从结算额里扣掉的切割费，是客户承担（按扣完的结算额给客户付，系统不应再扣）还是我们承担（系统现在的做法）。你定了我改规则
A15: 路径不同 | B15: =SUM(逐车比对!X2:X102) -> -1298.91 | C15: =COUNTIF(逐车比对!X2:X102,">0.5")+COUNTIF(逐车比对!X2:X102,"<-0.5") -> 4 | D15: 4 车两边走的路径不一样：苏DBB772 8/27、9/14 财务记君盛带票，系统是配票；苏DBB772 9/18 83.74 吨财务记林凯配票(煌烽)，系统是君盛直签带票；鲁DC6106 9/14 财务记高栾凤配票(煌烽)，系统是户头通道且固化快照里服务费异常(18.56 元/吨) | E15: 逐车确认这 4 车实际怎么走的，改系统里的链条规则/票源；鲁DC6106 建议解除固化重算
A16: 取整 | B16: =SUM(逐车比对!Y2:Y102) -> -48.96 | C16: =COUNTIF(逐车比对!Y2:Y102,">0.5")+COUNTIF(逐车比对!Y2:Y102,"<-0.5") -> 43 | D16: 财务“实际付款金额”用 INT() 向下取整，每车差几毛钱；另含 #86 吨位差 0.18 吨的影响(约 5 元) | E16: 不用处理
A17: 系统没有的车（闫东鹏 9/21 27.98吨） | B17: =-逐车比对!H96 -> -840.5876 | C17: 1 | D17: 财务有 9/21 闫东鹏反向一车（70,229.80 元，利润 840.59），系统还没录 | E17: 补录到系统
A18: 合计 | B18: =SUM(B10:B17) -> 25703.472 | C18: =IF(ABS(B18-B6)<0.1,"✓ 对得上（分项四舍五入差几分钱）","✗ 有未解释差额") -> ✓ 对得上（分项四舍五入差几分钱） | D18: 应等于上面的总差额
A21: 不影响利润、但需要统一的记录差异
A22: 类型 | B22: 内容 | C22: 建议
A23: 车次合并 | B23: 财务 8/29 林凯 99.68 吨一行 = 系统 苏DBE075 79.68 吨 + 冀A224E6 20 吨两车 | C23: 以系统两车为准，财务可拆开
A24: 吨位 | B24: 林凯-力拓 9/17：财务 29.97 吨，系统 29.79 吨（金额都是 68,576.58） | C24: 看结算单确认
A25: 应收金额 | B25: 林凯-鑫景通 9/15：财务应收写死 200,063.80，按 71.5×2370 应为 169,455.00（系统） | C25: 财务改
A26: 供货厂 | B26: 苏DBE075 9/10、苏DBB772 9/11：财务记力拓，系统记君盛；林凯-力拓 9/17 同上；苏DBB772 9/14 系统供货厂写的林凯 | C26: 看结算单确认后改系统
A27: 调货人/货主 | B27: 财务按人分表：高栾凤(3车)、王荣胜(1船)、尹鹏飞(4船)、邓晶焱 9/15、9/16 等；系统里这些车多数没填调货人、供货厂写的“俊兴/邓晶焱” | C27: 确认后补调货人，调货人统计才准
A28: 票源 | B28: 林凯 8/31~9/06、李涛 9/04 两车：财务写俊兴，系统益周（利润口径一样，但系统对益周另算票差留存约 2.2 万）；陈杰 9/04 财务煌烽、系统益周；尹鹏飞 9/03 船 财务益周、系统俊兴；邓晶焱 9/12 财务煌烽、系统俊兴 | C28: 以开票实际为准统一；票源决定额度占用和票差留存
A29: 日期 | B29: 9 车日期差 1~2 天，主要是船（财务像是结算单日期，系统是结算日期/过磅日期） | C29: 一般不影响；月底跨期的要注意
A30: 链条名称 | B30: 闫东朋 9/14 苏J19371：系统标“户头通道”，实际是反向（利润一样） | C30: 系统改成“反向”

Sheet 逐车比对
A1: 财务表 | B1: 行 | C1: 财务日期 | D1: 财务吨位 | E1: 财务应收金额 | F1: 财务路径 | G1: 财务票源 | H1: 财务利润 | I1: 系统车次 | J1: 车号 | K1: 系统结算日期 | L1: 系统吨位 | M1: 系统结算金额 | N1: 调货人：供货厂 | O1: 系统票源 | P1: 系统链条 | Q1: 系统利润 | R1: 差额(系统-财务) | S1: 差:量补单价 | T1: 差:调货提成 | U1: 差:票点系数 | V1: 差:给客户点位 | W1: 差:切割费 | X1: 差:路径不同 | Y1: 差:取整 | Z1: 分项合计核对 | AA1: 差异说明
A2: 林凯 | B2: 2 | C2: 2026-08-19 | D2: 73.58 | E2: 168498.2 | F2: 配票 | G2: 俊兴 | H2: 482.7689 | I2: #1 | J2: 苏DBB772 | K2: 2026-08-19 | L2: 73.58 | M2: 168498.2 | N2: 林凯 | O2: 俊兴 | P2: 配票 | Q2: 482.3169 | R2: =IF(Q2="","",Q2-H2) -> -0.452 | S2: 0 | T2: 0 | U2: 0 | V2: 0 | W2: 0 | X2: 0 | Y2: -0.45 | Z2: =IF(Q2="","",SUM(S2:Y2)-R2) -> 0.002
A3: 林凯 | B3: 3 | C3: 2026-08-20 | D3: 34.8 | E3: 84564 | F3: 配票 | G3: 俊兴 | H3: 252.514 | I3: #2 | J3: 苏DFM060 | K3: 2026-08-20 | L3: 34.8 | M3: 84564 | N3: 林凯 | O3: 俊兴 | P3: 配票 | Q3: 252.474 | R3: =IF(Q3="","",Q3-H3) -> -0.04 | S3: 0 | T3: 0 | U3: 0 | V3: 0 | W3: 0 | X3: 0 | Y3: -0.04 | Z3: =IF(Q3="","",SUM(S3:Y3)-R3) -> -6.5165304e-12
A4: 林凯 | B4: 4 | C4: 2026-08-21 | D4: 81.16 | E4: 201276.8 | F4: 配票 | G4: 俊兴 | H4: 608.1538 | I4: #3 | J4: 苏DBB772 | K4: 2026-08-21 | L4: 81.16 | M4: 201276.8 | N4: 林凯 | O4: 俊兴 | P4: 配票 | Q4: 609.1058 | R4: =IF(Q4="","",Q4-H4) -> 0.952 | S4: 0 | T4: 0 | U4: 0 | V4: 0 | W4: 0 | X4: 0 | Y4: 0.95 | Z4: =IF(Q4="","",SUM(S4:Y4)-R4) -> -0.002
A5: 林凯 | B5: 5 | C5: 2026-08-21 | D5: 36.36 | E5: 83264.4 | F5: 配票 | G5: 俊兴 | H5: 238.7238 | I5: #4 | J5: 皖M2A505 | K5: 2026-08-21 | L5: 36.36 | M5: 83264.4 | N5: 俊兴 | O5: 俊兴 | P5: 配票 | Q5: 420.1398 | R5: =IF(Q5="","",Q5-H5) -> 181.416 | S5: 0 | T5: 181.8 | U5: 0 | V5: 0 | W5: 0 | X5: 0 | Y5: -0.38 | Z5: =IF(Q5="","",SUM(S5:Y5)-R5) -> 0.004 | AA5: 提成：财务扣5元/吨（算林凯的），系统没填调货人、没扣
A6: 林凯 | B6: 6 | C6: 2026-08-21 | D6: 32.94 | E6: 75432.6 | F6: 配票 | G6: 俊兴 | H6: 215.9577 | I6: #5 | J6: 苏EQB977 | K6: 2026-08-21 | L6: 32.94 | M6: 75432.6 | N6: 俊兴 | O6: 俊兴 | P6: 配票 | Q6: 380.6217 | R6: =IF(Q6="","",Q6-H6) -> 164.664 | S6: 0 | T6: 164.7 | U6: 0 | V6: 0 | W6: 0 | X6: 0 | Y6: -0.04 | Z6: =IF(Q6="","",SUM(S6:Y6)-R6) -> -0.004 | AA6: 提成：财务扣5元/吨（算林凯的），系统没填调货人、没扣
A7: 林凯 | B7: 7 | C7: 2026-08-21 | D7: 24.41 | E7: 59023.38 | F7: 配票 | G7: 俊兴 | H7: 175.73675 | I7: #6 | J7: 苏BUK952 | K7: 2026-08-21 | L7: 24.41 | M7: 59023.38 | N7: 林凯 | O7: 俊兴 | P7: 配票 | Q7: 175.62995 | R7: =IF(Q7="","",Q7-H7) -> -0.1068 | S7: 0 | T7: 0 | U7: 0 | V7: 0 | W7: 0 | X7: 0 | Y7: -0.11 | Z7: =IF(Q7="","",SUM(S7:Y7)-R7) -> -0.0032
A8: 林凯 | B8: 8 | C8: 2026-08-22 | D8: 69.5 | E8: 159155 | F8: 配票 | G8: 俊兴 | H8: 455.8725 | I8: #7 | J8: 苏DBB772 | K8: 2026-08-22 | L8: 69.5 | M8: 159155 | N8: 林凯 | O8: 俊兴 | P8: 配票 | Q8: 455.5725 | R8: =IF(Q8="","",Q8-H8) -> -0.3 | S8: 0 | T8: 0 | U8: 0 | V8: 0 | W8: 0 | X8: 0 | Y8: -0.3 | Z8: =IF(Q8="","",SUM(S8:Y8)-R8) -> -1.1300461e-11
A9: 林凯 | B9: 9 | C9: 2026-08-22 | D9: 34.24 | E9: 78409.6 | F9: 配票 | G9: 俊兴 | H9: 224.6992 | I9: #9 | J9: 苏MAK862 | K9: 2026-08-22 | L9: 34.24 | M9: 78409.6 | N9: 俊兴 | O9: 俊兴 | P9: 配票 | Q9: 395.6432 | R9: =IF(Q9="","",Q9-H9) -> 170.944 | S9: 0 | T9: 171.2 | U9: 0 | V9: 0 | W9: 0 | X9: 0 | Y9: -0.26 | Z9: =IF(Q9="","",SUM(S9:Y9)-R9) -> -0.004 | AA9: 提成：财务扣5元/吨（算林凯的），系统没填调货人、没扣
A10: 林凯 | B10: 10 | C10: 2026-08-25 | D10: 81 | E10: 184032 | F10: 配票 | G10: 俊兴 | H10: 524.185 | I10: #10 | J10: 苏DBE075 | K10: 2026-08-25 | L10: 81 | M10: 184032 | N10: 林凯 | O10: 俊兴 | P10: 配票 | Q10: 523.665 | R10: =IF(Q10="","",Q10-H10) -> -0.52 | S10: 0 | T10: 0 | U10: 0 | V10: 0 | W10: 0 | X10: 0 | Y10: -0.52 | Z10: =IF(Q10="","",SUM(S10:Y10)-R10) -> -1.0136336e-11
A11: 林凯 | B11: 11 | C11: 2026-08-26 | D11: 560.39 | E11: 1344115.9 | F11: 配票 | G11: 俊兴 | H11: 3978.1358 | I11: #11 | J11: 苏淮货16776 | K11: 2026-08-27 | L11: 560.39 | M11: 1344115.9 | N11: 俊兴 | O11: 俊兴 | P11: 配票 | Q11: 9581.3704 | R11: =IF(Q11="","",Q11-H11) -> 5603.2346 | S11: 2801.95 | T11: 2801.95 | U11: 0 | V11: 0 | W11: 0 | X11: 0 | Y11: -0.67 | Z11: =IF(Q11="","",SUM(S11:Y11)-R11) -> -0.0046000002 | AA11: 量补：财务按20元/吨，系统按25元/吨；提成：财务扣5元/吨（算林凯的），系统没填调货人、没扣；日期：财务08-26，系统结算日期08-27
A12: 林凯 | B12: 12 | C12: 2026-08-27 | D12: 40.27 | E12: 93426.4 | F12: 配票 | G12: 俊兴 | H12: 270.71435 | I12: #12 | J12: 苏NEX375 | K12: 2026-08-27 | L12: 40.27 | M12: 93426.4 | N12: 林凯 | O12: 俊兴 | P12: 配票 | Q12: 471.36035 | R12: =IF(Q12="","",Q12-H12) -> 200.646 | S12: 201.35 | T12: 0 | U12: 0 | V12: 0 | W12: 0 | X12: 0 | Y12: -0.7 | Z12: =IF(Q12="","",SUM(S12:Y12)-R12) -> 0.004 | AA12: 量补：财务按20元/吨，系统按25元/吨
A13: 林凯 | B13: 13 | C13: 2026-08-27 | D13: 34.3 | E13: 84206.5 | F13: 配票 | G13: 俊兴 | H13: 253.724 | I13: #13 | J13: 苏DFM060 | K13: 2026-08-27 | L13: 34.3 | M13: 84206.5 | N13: 林凯 | O13: 俊兴 | P13: 配票 | Q13: 424.634 | R13: =IF(Q13="","",Q13-H13) -> 170.91 | S13: 171.5 | T13: 0 | U13: 0 | V13: 0 | W13: 0 | X13: 0 | Y13: -0.59 | Z13: =IF(Q13="","",SUM(S13:Y13)-R13) -> -3.524292e-12 | AA13: 量补：财务按20元/吨，系统按25元/吨
A14: 林凯 | B14: 14 | C14: 2026-08-27 | D14: 32.05 | E14: 78682.75 | F14: 配票 | G14: 俊兴 | H14: 236.694 | I14: #15 | J14: 苏BDK567 | K14: 2026-08-27 | L14: 32.05 | M14: 78682.75 | N14: 林凯 | O14: 俊兴 | P14: 配票 | Q14: 396.779 | R14: =IF(Q14="","",Q14-H14) -> 160.085 | S14: 160.25 | T14: 0 | U14: 0 | V14: 0 | W14: 0 | X14: 0 | Y14: -0.16 | Z14: =IF(Q14="","",SUM(S14:Y14)-R14) -> 0.005 | AA14: 量补：财务按20元/吨，系统按25元/吨
A15: 林凯 | B15: 15 | C15: 2026-08-27 | D15: 28.47 | E15: 68569.64 | F15: 配票 | G15: 俊兴 | H15: 204.37795 | I15: #16 | J15: 苏BZP839 | K15: 2026-08-27 | L15: 28.47 | M15: 68569.64 | N15: 林凯 | O15: 俊兴 | P15: 配票 | Q15: 246.33755 | R15: =IF(Q15="","",Q15-H15) -> 41.9596 | S15: 142.35 | T15: 0 | U15: 0 | V15: 0 | W15: -100 | X15: 0 | Y15: -0.39 | Z15: =IF(Q15="","",SUM(S15:Y15)-R15) -> 0.0004 | AA15: 量补：财务按20元/吨，系统按25元/吨；切割费100元：两边结算额里都已扣掉；系统又从利润里再扣一次，财务没扣
A16: 林凯 | B16: 16 | C16: 2026-08-27 | D16: 48.38 | E16: 116112 | F16: 配票 | G16: 俊兴 | H16: 344.0599 | I16: #18 | J16: 苏ERS080 | K16: 2026-08-27 | L16: 48.38 | M16: 116112 | N16: 林凯 | O16: 俊兴 | P16: 配票 | Q16: 585.6399 | R16: =IF(Q16="","",Q16-H16) -> 241.58 | S16: 241.9 | T16: 0 | U16: 0 | V16: 0 | W16: 0 | X16: 0 | Y16: -0.32 | Z16: =IF(Q16="","",SUM(S16:Y16)-R16) -> -7.4180662e-12 | AA16: 量补：财务按20元/吨，系统按25元/吨
A17: 林凯 | B17: 17 | C17: 2026-08-28 | D17: 81.9 | E17: 191646 | F17: 配票 | G17: 俊兴 | H17: 557.8895 | I17: #22 | J17: 苏DFB287 | K17: 2026-08-28 | L17: 81.9 | M17: 191646 | N17: 林凯 | O17: 俊兴 | P17: 配票 | Q17: 966.8295 | R17: =IF(Q17="","",Q17-H17) -> 408.94 | S17: 409.5 | T17: 0 | U17: 0 | V17: 0 | W17: 0 | X17: 0 | Y17: -0.56 | Z17: =IF(Q17="","",SUM(S17:Y17)-R17) -> -2.7853275e-12 | AA17: 量补：财务按20元/吨，系统按25元/吨
A18: 林凯 | B18: 18 | C18: 2026-08-28 | D18: 18.52 | E18: 44448 | F18: 配票 | G18: 俊兴 | H18: 131.8646 | I18: #21 | J18: 苏DBX137 | K18: 2026-08-28 | L18: 18.52 | M18: 44448 | N18: 林凯 | O18: 俊兴 | P18: 配票 | Q18: 224.1846 | R18: =IF(Q18="","",Q18-H18) -> 92.32 | S18: 92.6 | T18: 0 | U18: 0 | V18: 0 | W18: 0 | X18: 0 | Y18: -0.28 | Z18: =IF(Q18="","",SUM(S18:Y18)-R18) -> -1.1084467e-12 | AA18: 量补：财务按20元/吨，系统按25元/吨
A19: 林凯 | B19: 19 | C19: 2026-08-28 | D19: 38.2 | E19: 88624 | F19: 配票 | G19: 俊兴 | H19: 256.771 | I19: #20 | J19: 苏DBE075 | K19: 2026-08-28 | L19: 38.2 | M19: 88624 | N19: 林凯 | O19: 俊兴 | P19: 配票 | Q19: 447.131 | R19: =IF(Q19="","",Q19-H19) -> 190.36 | S19: 191 | T19: 0 | U19: 0 | V19: 0 | W19: 0 | X19: 0 | Y19: -0.64 | Z19: =IF(Q19="","",SUM(S19:Y19)-R19) -> -7.3896445e-13 | AA19: 量补：财务按20元/吨，系统按25元/吨
A20: 林凯 | B20: 20 | C20: 2026-08-28 | D20: 55.18 | E20: 130224.8 | F20: 配票 | G20: 俊兴 | H20: 381.3459 | I20: #23 | J20: 苏DFM060 | K20: 2026-08-28 | L20: 55.18 | M20: 130224.8 | N20: 林凯 | O20: 俊兴 | P20: 配票 | Q20: 656.9179 | R20: =IF(Q20="","",Q20-H20) -> 275.572 | S20: 275.9 | T20: 0 | U20: 0 | V20: 0 | W20: 0 | X20: 0 | Y20: -0.33 | Z20: =IF(Q20="","",SUM(S20:Y20)-R20) -> -0.002 | AA20: 量补：财务按20元/吨，系统按25元/吨
A21: 林凯 | B21: 21 | C21: 2026-08-28 | D21: 63.16 | E21: 153352.48 | F21: 配票 | G21: 俊兴 | H21: 457.727 | I21: #24 | J21: 苏DBB772 | K21: 2026-08-28 | L21: 63.16 | M21: 153352.48 | N21: 林凯 | O21: 俊兴 | P21: 配票 | Q21: 773.3942 | R21: =IF(Q21="","",Q21-H21) -> 315.6672 | S21: 315.8 | T21: 0 | U21: 0 | V21: 0 | W21: 0 | X21: 0 | Y21: -0.13 | Z21: =IF(Q21="","",SUM(S21:Y21)-R21) -> 0.0028 | AA21: 量补：财务按20元/吨，系统按25元/吨
A22: 林凯 | B22: 22 | C22: 2026-08-28 | D22: 27.22 | E22: 66416.8 | F22: 配票 | G22: 俊兴 | H22: 199.2901 | I22: #26 | J22: 苏BUK952 | K22: 2026-08-28 | L22: 27.22 | M22: 66416.8 | N22: 林凯 | O22: 俊兴 | P22: 配票 | Q22: 334.9421 | R22: =IF(Q22="","",Q22-H22) -> 135.652 | S22: 136.1 | T22: 0 | U22: 0 | V22: 0 | W22: 0 | X22: 0 | Y22: -0.45 | Z22: =IF(Q22="","",SUM(S22:Y22)-R22) -> -0.002 | AA22: 量补：财务按20元/吨，系统按25元/吨
... A49: 林凯 | B49: 49 | C49: 2026-09-18 | D49: 83.74 | E49: 202650.8 | F49: 配票 | G49: 煌烽 | H49: 2043.609 | I49: #89 | J49: 苏DBB772 | K49: 2026-09-18 | L49: 83.74 | M49: 202650.8 | N49: 林凯：君盛 | O49: 自带票 | P49: 直签带票 | Q49: 2260.98 | R49: =IF(Q49="","",Q49-H49) -> 217.37096 | S49: 0 | T49: 0 | U49: 0 | V49: 0 | W49: 0 | X49: 217.37 | Y49: 0 | Z49: =IF(Q49="","",SUM(S49:Y49)-R49) -> -0.00095999999 | AA49: 财务记在林凯配票(煌烽票源)；系统是君盛直签带票
A50: 林凯 | B50: 50 | C50: 2026-09-18 | D50: 34.02 | E50: 79266.6 | F50: 配票 | G50: 煌烽 | H50: 805.73352 | I50: #90 | J50: 苏NEN536 | K50: 2026-09-18 | L50: 34.02 | M50: 79266.6 | N50: 林凯 | O50: 煌烽 | P50: 配票 | Q50: 805.45752 | R50: =IF(Q50="","",Q50-H50) -> -0.276 | S50: 0 | T50: 0 | U50: 0 | V50: 0 | W50: 0 | X50: 0 | Y50: -0.28 | Z50: =IF(Q50="","",SUM(S50:Y50)-R50) -> -0.004
A51: 林凯 | B51: 51 | C51: 2026-09-19 | D51: 33.86 | E51: 78793.8 | F51: 配票 | G51: 煌烽 | H51: 801.53736 | I51: #95 | J51: 苏GE2356 | K51: 2026-09-19 | L51: 33.86 | M51: 78793.8 | N51: 林凯 | O51: 煌烽 | P51: 配票 | Q51: 700.86936 | R51: =IF(Q51="","",Q51-H51) -> -100.668 | S51: 0 | T51: 0 | U51: 0 | V51: 0 | W51: -100 | X51: 0 | Y51: -0.67 | Z51: =IF(Q51="","",SUM(S51:Y51)-R51) -> -0.002 | AA51: 切割费100元：两边结算额里都已扣掉；系统又从利润里再扣一次，财务没扣
A52: 林凯 | B52: 52 | C52: 2026-09-19 | D52: 33.96 | E52: 78619.28 | F52: 配票 | G52: 煌烽 | H52: 800.5576 | I52: #96 | J52: 苏NHY179 | K52: 2026-09-19 | L52: 33.96 | M52: 78619.28 | N52: 林凯 | O52: 煌烽 | P52: 配票 | Q52: 699.9768 | R52: =IF(Q52="","",Q52-H52) -> -100.5808 | S52: 0 | T52: 0 | U52: 0 | V52: 0 | W52: -100 | X52: 0 | Y52: -0.58 | Z52: =IF(Q52="","",SUM(S52:Y52)-R52) -> 0.0008 | AA52: 切割费100元：两边结算额里都已扣掉；系统又从利润里再扣一次，财务没扣
A53: 林凯-鑫景通 | B53: 2 | C53: 2026-09-12 | D53: 78.04 | E53: 200062.8 | F53: 带票 | G53: 带票 | H53: 2107.28 | I53: #66 | J53: 苏DBE075 | K53: 2026-09-12 | L53: 78.04 | M53: 200062.8 | N53: 林凯：𠓾景通 | O53: 俊兴 | P53: 户头通道 | Q53: 1607.08 | R53: =IF(Q53="","",Q53-H53) -> -500.2 | S53: 0 | T53: 0 | U53: 0 | V53: 0 | W53: -500 | X53: 0 | Y53: -0.2 | Z53: =IF(Q53="","",SUM(S53:Y53)-R53) -> 0 | AA53: 切割费500元：两边结算额里都已扣掉；系统又从利润里再扣一次，财务没扣
A54: 林凯-鑫景通 | B54: 3 | C54: 2026-09-15 | D54: 71.5 | E54: 200063.8 | F54: 带票 | G54: 带票 | H54: 1931.3 | I54: #78 | J54: 苏DBB772 | K54: 2026-09-15 | L54: 71.5 | M54: 169455 | N54: 林凯：𠓾景通 | O54: 自带票 | P54: 直签带票 | Q54: 1930.5 | R54: =IF(Q54="","",Q54-H54) -> -0.8 | S54: 0 | T54: 0 | U54: 0 | V54: 0 | W54: 0 | X54: 0 | Y54: -0.8 | Z54: =IF(Q54="","",SUM(S54:Y54)-R54) -> -1.0049961e-11 | AA54: 金额：财务应收写死200063.8，按71.5×2370应为169455（系统）；利润公式与金额无关所以利润一致，但财务应收金额多记30608.8
A55: 林凯-君盛 | B55: 2 | C55: 2026-08-27 | D55: 66.22 | E55: 148332.8 | F55: 带票 | G55: 带票 | H55: 1787.94 | I55: #14 | J55: 苏DBB772 | K55: 2026-08-27 | L55: 66.22 | M55: 148332.8 | N55: 林凯：君盛 | O55: 俊兴 | P55: 配票 | Q55: 748.6171 | R55: =IF(Q55="","",Q55-H55) -> -1039.3229 | S55: 0 | T55: 0 | U55: 0 | V55: 0 | W55: 0 | X55: -1039.32 | Y55: 0 | Z55: =IF(Q55="","",SUM(S55:Y55)-R55) -> 0.0029 | AA55: 财务记在“林凯-君盛”带票(服务费)；系统是配票+俊兴票源
A56: 林凯-君盛 | B56: 3 | C56: 2026-09-12 | D56: 65.44 | E56: 147240 | F56: 带票 | G56: 带票 | H56: 1767.28 | I56: #68 | J56: 苏DBE075 | K56: 2026-09-12 | L56: 65.44 | M56: 147240 | N56: 林凯：君盛 | O56: 俊兴 | P56: 户头通道 | Q56: 1766.88 | R56: =IF(Q56="","",Q56-H56) -> -0.4 | S56: 0 | T56: 0 | U56: 0 | V56: 0 | W56: 0 | X56: 0 | Y56: -0.4 | Z56: =IF(Q56="","",SUM(S56:Y56)-R56) -> -1.0459411e-12
A57: 林凯-君盛 | B57: 4 | C57: 2026-09-14 | D57: 60.9 | E57: 137025 | F57: 带票 | G57: 带票 | H57: 1644.3 | I57: #69 | J57: 苏DBB772 | K57: 2026-09-14 | L57: 60.9 | M57: 137025 | N57: 林凯 | O57: 俊兴 | P57: 配票 | Q57: 996.0195 | R57: =IF(Q57="","",Q57-H57) -> -648.2805 | S57: 0 | T57: 0 | U57: 0 | V57: 0 | W57: 0 | X57: -648.28 | Y57: 0 | Z57: =IF(Q57="","",SUM(S57:Y57)-R57) -> 0.0005 | AA57: 财务记在“林凯-君盛”带票；系统是配票、供货厂写的林凯
A58: 林凯-君盛 | B58: 5 | C58: 2026-09-15 | D58: 31.38 | E58: 70605 | F58: 带票 | G58: 带票 | H58: 848.06 | I58: #79 | J58: 苏DBE961 | K58: 2026-09-15 | L58: 31.38 | M58: 70605 | N58: 林凯：君盛 | O58: 自带票 | P58: 直签带票 | Q58: 847.26 | R58: =IF(Q58="","",Q58-H58) -> -0.8 | S58: 0 | T58: 0 | U58: 0 | V58: 0 | W58: 0 | X58: 0 | Y58: -0.8 | Z58: =IF(Q58="","",SUM(S58:Y58)-R58) -> -5.04774e-12
A59: 林凯-君盛 | B59: 6 | C59: 2026-09-15 | D59: 31.46 | E59: 70785 | F59: 带票 | G59: 带票 | H59: 850.02 | I59: #74 | J59: 苏DBE075 | K59: 2026-09-15 | L59: 31.46 | M59: 70785 | N59: 林凯：君盛 | O59: 自带票 | P59: 直签带票 | Q59: 849.42 | R59: =IF(Q59="","",Q59-H59) -> -0.6 | S59: 0 | T59: 0 | U59: 0 | V59: 0 | W59: 0 | X59: 0 | Y59: -0.6 | Z59: =IF(Q59="","",SUM(S59:Y59)-R59) -> -2.0236035e-12
A60: 林凯-君盛 | B60: 7 | C60: 2026-09-17 | D60: 28.84 | E60: 66389.68 | F60: 带票 | G60: 带票 | H60: 778.76 | I60: #87 | J60: 苏DBB772 | K60: 2026-09-17 | L60: 28.84 | M60: 66389.68 | N60: 林凯：君盛 | O60: 自带票 | P60: 直签带票 | Q60: 778.68 | R60: =IF(Q60="","",Q60-H60) -> -0.08 | S60: 0 | T60: 0 | U60: 0 | V60: 0 | W60: 0 | X60: 0 | Y60: -0.08 | Z60: =IF(Q60="","",SUM(S60:Y60)-R60) -> 9.504203e-13
A61: 林凯-君盛 | B61: 8 | C61: 2026-09-18 | D61: 30.72 | E61: 70717.44 | F61: 带票 | G61: 带票 | H61: 830.08 | I61: #91 | J61: 苏DBE075 | K61: 2026-09-18 | L61: 30.72 | M61: 70717.44 | N61: 林凯：君盛 | O61: 自带票 | P61: 直签带票 | Q61: 829.44 | R61: =IF(Q61="","",Q61-H61) -> -0.64 | S61: 0 | T61: 0 | U61: 0 | V61: 0 | W61: 0 | X61: 0 | Y61: -0.64 | Z61: =IF(Q61="","",SUM(S61:Y61)-R61) -> 4.9885651e-12
A62: 林凯-君盛 | B62: 9 | C62: 2026-09-18 | D62: 31.32 | E62: 72098.64 | F62: 带票 | G62: 带票 | H62: 846.48 | I62: #92 | J62: 苏DBB772 | K62: 2026-09-18 | L62: 31.32 | M62: 72098.64 | N62: 林凯：君盛 | O62: 自带票 | P62: 直签带票 | Q62: 845.64 | R62: =IF(Q62="","",Q62-H62) -> -0.84 | S62: 0 | T62: 0 | U62: 0 | V62: 0 | W62: 0 | X62: 0 | Y62: -0.84 | Z62: =IF(Q62="","",SUM(S62:Y62)-R62) -> -1.105005e-12
A63: 林凯-君盛 | B63: 10 | C63: 2026-09-20 | D63: 32.12 | E63: 73940.24 | F63: 带票 | G63: 带票 | H63: 867.68 | I63: #98 | J63: 苏DBB772 | K63: 2026-09-20 | L63: 32.12 | M63: 73940.24 | N63: 林凯：君盛 | O63: 自带票 | P63: 直签带票 | Q63: 867.24 | R63: =IF(Q63="","",Q63-H63) -> -0.44 | S63: 0 | T63: 0 | U63: 0 | V63: 0 | W63: 0 | X63: 0 | Y63: -0.44 | Z63: =IF(Q63="","",SUM(S63:Y63)-R63) -> -3.9244719e-12
A64: 林凯-君盛 | B64: 11 | C64: 2026-09-20 | D64: 32.72 | E64: 75321.44 | F64: 带票 | G64: 带票 | H64: 884.08 | I64: #99 | J64: 苏DBE075 | K64: 2026-09-20 | L64: 32.72 | M64: 75321.44 | N64: 林凯：君盛 | O64: 自带票 | P64: 直签带票 | Q64: 883.44 | R64: =IF(Q64="","",Q64-H64) -> -0.64 | S64: 0 | T64: 0 | U64: 0 | V64: 0 | W64: 0 | X64: 0 | Y64: -0.64 | Z64: =IF(Q64="","",SUM(S64:Y64)-R64) -> 4.7611914e-12
A65: 林凯-力拓 | B65: 2 | C65: 2026-09-10 | D65: 82.26 | E65: 208117.8 | F65: 带票 | G65: 带票 | H65: 2221.42 | I65: #63 | J65: 苏DBE075 | K65: 2026-09-10 | L65: 82.26 | M65: 208117.8 | N65: 林凯：君盛 | O65: 俊兴 | P65: 户头通道 | Q65: 2221.02 | R65: =IF(Q65="","",Q65-H65) -> -0.4 | S65: 0 | T65: 0 | U65: 0 | V65: 0 | W65: 0 | X65: 0 | Y65: -0.4 | Z65: =IF(Q65="","",SUM(S65:Y65)-R65) -> 1.0095369e-11 | AA65: 供货厂：财务力拓，系统君盛
A66: 林凯-力拓 | B66: 3 | C66: 2026-09-11 | D66: 82.2 | E66: 207966 | F66: 带票 | G66: 带票 | H66: 2219.4 | I66: #64 | J66: 苏DBB772 | K66: 2026-09-11 | L66: 82.2 | M66: 207966 | N66: 林凯：君盛 | O66: 俊兴 | P66: 户头通道 | Q66: 2219.4 | R66: =IF(Q66="","",Q66-H66) -> 1.0004442e-11 | S66: 0 | T66: 0 | U66: 0 | V66: 0 | W66: 0 | X66: 0 | Y66: 0 | Z66: =IF(Q66="","",SUM(S66:Y66)-R66) -> -1.0004442e-11 | AA66: 供货厂：财务力拓，系统君盛
...

Sheet 计算口径对照
A1: 路径 | B1: 财务表公式（以第2行为例） | C1: 系统公式 | D1: 是否一致
A2: 配票（俊兴/益周） | B2: 欧冶=结算额−23×吨；实际付款=INT(结算额×0.86)；利润=欧冶×0.865−实际付款+量补−提成 | C2: 给客户付=结算额×(1−14%)；前端实付=(结算额−垫资23×吨)×(1−13.5%)；利润=量补−(给客户付−前端实付)−提成−切割费 | D2: 一致（差 INT 取整、切割费）
A3: 配票（煌烽） | B3: 「林凯」表：利润=欧冶×0.868−实际付款+25×吨；「邓晶焱/高栾凤/尹鹏飞」表：仍用×0.865 | C3: 前端实付按煌烽 13.2%（×0.868） | D3: 「林凯」表一致；其它三张表财务公式疑似没改
A4: 反向 | B4: 实际付款=INT(结算额×0.86)；带票公司付=结算额×0.862；利润=结算额×0.862−实际付款+25×吨（不扣垫资23） | C4: 反向票点 13.8%，本期垫资费 0（已含在反向票点里） | D4: 一致
A5: 带票（君盛/力拓/兴德/鑫景通） | B5: 欧冶=结算额−23×吨；付供货厂=INT(结算额−40×吨)；利润=欧冶−付款+25×吨−15×吨 =27元/吨 | C5: 毛服务费40−垫资23−提成15+量补25 = 27元/吨，再减切割费 | D5: 一致（差切割费）
A6: 量补 | B6: 每行手写 20 或 25 | C6: 按钢厂结算周期累计吨位查阶梯：7/26~8/25 周期 20，8/26~9/25 周期 25 | D6: 8/26~9/05 林凯/邓晶焱的车不一致
A7: 林凯提成 | B7: 配票 9/05 前每行 −5×吨；带票 −15×吨 | C7: 配票 5 元/吨到 9/04，9/05 起 0；带票 15 元/吨 | D7: 规则一致；差在哪些车算林凯的
