Workbook

Sheet 总览
A1: 财务「发货记录表」× 系统 对账（按步骤）
A2: 顺序：①先对车次 → ②调货人/供货厂 → ③票源 → ④计算路径（人工确认修正）→ ⑤最后看参数差异。各表淡黄色列是给你填确认结果的，填完发回给我，我按确认结果批量改系统。
A4: 步骤 | B4: 对象 | C4: 一致 | D4: 需确认 | E4: 说明
A5: ①车次对账 | B5: 财务101行 | C5: =COUNTIF(①车次对账!K2:K102,"一致*") -> 97 | D5: =COUNTA(①车次对账!K2:K102)-C5 -> 4 | E5: 99 行一一对上；1 行是财务把两车合成一行(8/29 99.68吨 = 苏DBE075 + 冀A224E6)；1 行是 9/21 闫东鹏你还没录。吨位/金额录错 2 处（力拓 9/17 吨位、鑫景通 9/15 财务应收）
A6: ②调货人/供货厂 | B6: 系统车次 | C6: =COUNTIF(②调货人供货厂!J2:J102,"一致") -> 81 | D6: =COUNTA(②调货人供货厂!J2:J102)-C6 -> 20 | E6: 主要是：财务记林凯、系统没填调货人的车（会影响林凯提成）；高栾凤、王荣胜系统里没有这个人；力拓/君盛几车记混；名字写法“闫东鹏/闫东朋”“鑫景通/𠓾景通”
A7: ③票源 | B7: 系统车次 | C7: =COUNTIF(③票源!H2:H102,"一致") -> 76 | D7: =COUNTA(③票源!H2:H102)-C7 -> 25 | E7: 俊兴↔益周（影响票差留存和益周额度）、煌烽↔俊兴/益周（影响利润）、带票车系统挂了俊兴票源（户头通道那几车）
A8: ④计算路径 | B8: 系统车次 | C8: =COUNTIF(④计算路径!H2:H102,"一致") -> 96 | D8: =COUNTA(④计算路径!H2:H102)-C8 -> 5 | E8: 5 车不一致：苏DBB772 8/27、9/14、9/18，鲁DC6106 9/14，苏J19371 9/14(只是名字)；户头通道和直签带票算法相同，算一致
A9: ⑤参数差异 | B9: 路径一致的车 | C9: =COUNTA(⑤参数差异!A3:A97)-D9 -> 45 | D9: =⑤参数差异!Z98 -> 50 | E9: 量补 20/25、林凯提成、煌烽票点 0.865/0.868、王荣胜那条船给客户 13.8%、切割费是否再扣。金额见下
A11: ⑤ 参数差异金额（系统−财务，路径一致的车）
A12: 参数 | B12: 影响金额 | E12: 怎么定
A13: 量补单价 | B13: =⑤参数差异!M98 -> 12531.4 | E13: 8/26~9/05 林凯、邓晶焱的车财务按20，系统按25（财务自己给李涛/高栾凤/王荣胜同期又按25）。确认这段量补到底多少
A14: 调货提成 | B14: =⑤参数差异!P98 -> 4460.529 | E14: 财务记林凯、扣5元/吨的车，系统没填调货人没扣——②确认调货人后这项会消失或保留
A15: 票点系数 | B15: =⑤参数差异!S98 -> 9157.4511 | E15: 煌烽5车财务利润公式用了0.865，应是0.868（同表“带票公司付”列就是0.868），大概率财务公式没改
A16: 给客户点位 | B16: =⑤参数差异!V98 -> 2542.5179 | E16: 王荣胜 8/29 鲁济宁货4095：财务实际按13.8%付客户，系统按14%。若确实按13.8%付的，系统改这一车的“给客户付”
A17: 切割费 | B17: =⑤参数差异!X98 -> -800 | E17: 结算额里已扣切割费，系统又从利润扣一次（4车共800元）。要定规则：切割费客户承担还是我们承担
A18: 取整/其它 | B18: =⑤参数差异!Y98 -> -48.22676 | E18: 财务 INT 取整，每车零点几元，不处理
A19: 合计 | B19: =SUM(B13:B18) -> 27843.671
A20: 另：路径不一致5车的利润差、9/21未录一车，不在上面，见④、①
A22: 填写说明
A23: 淡黄色列 = 请你/财务填写的确认结果；可以下拉选（以系统为准 / 以财务为准 / 正确的票源或链条），也可以直接写正确的名字。其它列是比对结果，不用改。

Sheet ①车次对账
A1: 财务表 | B1: 行 | C1: 财务日期 | D1: 财务吨位 | E1: 财务应收金额 | F1: 系统车次 | G1: 车号 | H1: 系统结算日期 | I1: 系统吨位 | J1: 系统结算金额 | K1: 对账结果 | L1: 差异说明 | M1: 确认/处理（请填）
A2: 林凯 | B2: 2 | C2: 2026-08-19 | D2: 73.58 | E2: 168498.2 | F2: #1 | G2: 苏DBB772 | H2: 2026-08-19 | I2: 73.58 | J2: 168498.2 | K2: 一致
A3: 林凯 | B3: 3 | C3: 2026-08-20 | D3: 34.8 | E3: 84564 | F3: #2 | G3: 苏DFM060 | H3: 2026-08-20 | I3: 34.8 | J3: 84564 | K3: 一致
A4: 林凯 | B4: 4 | C4: 2026-08-21 | D4: 81.16 | E4: 201276.8 | F4: #3 | G4: 苏DBB772 | H4: 2026-08-21 | I4: 81.16 | J4: 201276.8 | K4: 一致
A5: 林凯 | B5: 5 | C5: 2026-08-21 | D5: 36.36 | E5: 83264.4 | F5: #4 | G5: 皖M2A505 | H5: 2026-08-21 | I5: 36.36 | J5: 83264.4 | K5: 一致
A6: 林凯 | B6: 6 | C6: 2026-08-21 | D6: 32.94 | E6: 75432.6 | F6: #5 | G6: 苏EQB977 | H6: 2026-08-21 | I6: 32.94 | J6: 75432.6 | K6: 一致
A7: 林凯 | B7: 7 | C7: 2026-08-21 | D7: 24.41 | E7: 59023.38 | F7: #6 | G7: 苏BUK952 | H7: 2026-08-21 | I7: 24.41 | J7: 59023.38 | K7: 一致
A8: 林凯 | B8: 8 | C8: 2026-08-22 | D8: 69.5 | E8: 159155 | F8: #7 | G8: 苏DBB772 | H8: 2026-08-22 | I8: 69.5 | J8: 159155 | K8: 一致
A9: 林凯 | B9: 9 | C9: 2026-08-22 | D9: 34.24 | E9: 78409.6 | F9: #9 | G9: 苏MAK862 | H9: 2026-08-22 | I9: 34.24 | J9: 78409.6 | K9: 一致
A10: 林凯 | B10: 10 | C10: 2026-08-25 | D10: 81 | E10: 184032 | F10: #10 | G10: 苏DBE075 | H10: 2026-08-25 | I10: 81 | J10: 184032 | K10: 一致
A11: 林凯 | B11: 11 | C11: 2026-08-26 | D11: 560.39 | E11: 1344115.9 | F11: #11 | G11: 苏淮货16776 | H11: 2026-08-27 | I11: 560.39 | J11: 1344115.9 | K11: 一致(日期差) | L11: 日期差1天（船，财务像是结算单日期）
A12: 林凯 | B12: 12 | C12: 2026-08-27 | D12: 40.27 | E12: 93426.4 | F12: #12 | G12: 苏NEX375 | H12: 2026-08-27 | I12: 40.27 | J12: 93426.4 | K12: 一致
A13: 林凯 | B13: 13 | C13: 2026-08-27 | D13: 34.3 | E13: 84206.5 | F13: #13 | G13: 苏DFM060 | H13: 2026-08-27 | I13: 34.3 | J13: 84206.5 | K13: 一致
A14: 林凯 | B14: 14 | C14: 2026-08-27 | D14: 32.05 | E14: 78682.75 | F14: #15 | G14: 苏BDK567 | H14: 2026-08-27 | I14: 32.05 | J14: 78682.75 | K14: 一致
A15: 林凯 | B15: 15 | C15: 2026-08-27 | D15: 28.47 | E15: 68569.64 | F15: #16 | G15: 苏BZP839 | H15: 2026-08-27 | I15: 28.47 | J15: 68569.64 | K15: 一致
A16: 林凯 | B16: 16 | C16: 2026-08-27 | D16: 48.38 | E16: 116112 | F16: #18 | G16: 苏ERS080 | H16: 2026-08-27 | I16: 48.38 | J16: 116112 | K16: 一致
A17: 林凯 | B17: 17 | C17: 2026-08-28 | D17: 81.9 | E17: 191646 | F17: #22 | G17: 苏DFB287 | H17: 2026-08-28 | I17: 81.9 | J17: 191646 | K17: 一致
A18: 林凯 | B18: 18 | C18: 2026-08-28 | D18: 18.52 | E18: 44448 | F18: #21 | G18: 苏DBX137 | H18: 2026-08-28 | I18: 18.52 | J18: 44448 | K18: 一致
A19: 林凯 | B19: 19 | C19: 2026-08-28 | D19: 38.2 | E19: 88624 | F19: #20 | G19: 苏DBE075 | H19: 2026-08-28 | I19: 38.2 | J19: 88624 | K19: 一致
A20: 林凯 | B20: 20 | C20: 2026-08-28 | D20: 55.18 | E20: 130224.8 | F20: #23 | G20: 苏DFM060 | H20: 2026-08-28 | I20: 55.18 | J20: 130224.8 | K20: 一致
A21: 林凯 | B21: 21 | C21: 2026-08-28 | D21: 63.16 | E21: 153352.48 | F21: #24 | G21: 苏DBB772 | H21: 2026-08-28 | I21: 63.16 | J21: 153352.48 | K21: 一致
A22: 林凯 | B22: 22 | C22: 2026-08-28 | D22: 27.22 | E22: 66416.8 | F22: #26 | G22: 苏BUK952 | H22: 2026-08-28 | I22: 27.22 | J22: 66416.8 | K22: 一致
A23: 林凯 | B23: 23 | C23: 2026-08-28 | D23: 34.22 | E23: 83496.8 | F23: #25 | G23: 苏BDK567 | H23: 2026-08-28 | I23: 34.22 | J23: 83496.8 | K23: 一致
... A28: 林凯 | B28: 28 | C28: 2026-08-29 | D28: 48.75 | E28: 117000 | F28: #32 | G28: 苏ERS080 | H28: 2026-08-29 | I28: 48.75 | J28: 117000 | K28: 一致
A29: 林凯 | B29: 29 | C29: 2026-08-29 | D29: 99.68 | E29: 248796.8 | F29: #33+#34 | G29: 苏DBE075 / 冀A224E6 | H29: 2026-08-29 | I29: 99.68 | J29: 248796.8 | K29: 合并 | L29: 财务一行 = 系统两车：苏DBE075 79.68吨 + 冀A224E6 20.0吨，吨位金额合计一致
A30: 林凯 | B30: 30 | C30: 2026-08-29 | D30: 66.06 | E30: 147974.4 | F30: #36 | G30: 苏DBB772 | H30: 2026-08-29 | I30: 66.06 | J30: 147974.4 | K30: 一致
A31: 林凯 | B31: 31 | C31: 2026-08-30 | D31: 67.96 | E31: 152230.4 | F31: #44 | G31: 苏DBB772 | H31: 2026-08-30 | I31: 67.96 | J31: 152230.4 | K31: 一致
A32: 林凯 | B32: 32 | C32: 2026-08-30 | D32: 46.28 | E32: 107924.96 | F32: #43 | G32: 冀A224E6 | H32: 2026-08-30 | I32: 46.28 | J32: 107924.96 | K32: 一致
A33: 林凯 | B33: 33 | C33: 2026-08-30 | D33: 83.78 | E33: 211125.6 | F33: #42 | G33: 苏DBB772 | H33: 2026-08-30 | I33: 83.78 | J33: 211125.6 | K33: 一致
A34: 林凯 | B34: 34 | C34: 2026-08-30 | D34: 43.34 | E34: 101068.88 | F34: #41 | G34: 皖SB2849 | H34: 2026-08-30 | I34: 43.34 | J34: 101068.88 | K34: 一致
A35: 林凯 | B35: 35 | C35: 2026-08-30 | D35: 78.64 | E35: 181501.12 | F35: #38 | G35: 苏DBE961 | H35: 2026-08-30 | I35: 78.64 | J35: 181501.12 | K35: 一致
A36: 林凯 | B36: 36 | C36: 2026-08-30 | D36: 83.26 | E36: 192164.08 | F36: #39 | G36: 苏DFB287 | H36: 2026-08-30 | I36: 83.26 | J36: 192164.08 | K36: 一致
A37: 林凯 | B37: 37 | C37: 2026-08-30 | D37: 81.92 | E37: 205619.2 | F37: #37 | G37: 苏DBE075 | H37: 2026-08-30 | I37: 81.92 | J37: 205619.2 | K37: 一致
A38: 林凯 | B38: 38 | C38: 2026-08-31 | D38: 25.12 | E38: 60288 | F38: #45 | G38: 苏DFM060 | H38: 2026-08-31 | I38: 25.12 | J38: 60288 | K38: 一致
A39: 林凯 | B39: 39 | C39: 2026-08-31 | D39: 29.08 | E39: 71216.92 | F39: #46 | G39: 冀A224E6 | H39: 2026-08-31 | I39: 29.08 | J39: 71216.92 | K39: 一致
A40: 林凯 | B40: 40 | C40: 2026-08-31 | D40: 56.78 | E40: 137407.6 | F40: #47 | G40: 苏DFM060 | H40: 2026-08-31 | I40: 56.78 | J40: 137407.6 | K40: 一致
A41: 林凯 | B41: 41 | C41: 2026-08-31 | D41: 80.96 | E41: 203209.6 | F41: #48 | G41: 苏DBB772 | H41: 2026-08-31 | I41: 80.96 | J41: 203209.6 | K41: 一致
... A46: 林凯 | B46: 46 | C46: 2026-09-01 | D46: 70.76 | E46: 158502.4 | F46: #53 | G46: 苏DBB772 | H46: 2026-09-01 | I46: 70.76 | J46: 158502.4 | K46: 一致
A47: 林凯 | B47: 47 | C47: 2026-09-06 | D47: 719.14 | E47: 1823625.4 | F47: #61 | G47: 皖城兴货688 | H47: 2026-09-05 | I47: 719.14 | J47: 1823625.4 | K47: 一致(日期差) | L47: 日期差1天（船，财务像是结算单日期）
A48: 林凯 | B48: 48 | C48: 2026-09-08 | D48: 613.8 | E48: 1467823.1 | F48: #62 | G48: 鲁济宁货1567 | H48: 2026-09-07 | I48: 613.8 | J48: 1467823.1 | K48: 一致(日期差) | L48: 日期差1天（船，财务像是结算单日期）
...

Sheet ②调货人供货厂
A1: 财务表 | B1: 行 | C1: 财务日期 | D1: 车号 | E1: 系统车次 | F1: 财务归属：调货人 | G1: 财务归属：供货厂 | H1: 系统调货人 | I1: 系统供货厂 | J1: 对比结果 | K1: 说明 | L1: 确认：正确调货人（请填） | M1: 确认：正确供货厂（请填）
A2: 林凯 | B2: 2 | C2: 2026-08-19 | D2: 苏DBB772 | E2: #1 | F2: 林凯 | G2: — | H2: 林凯 | I2: 林凯 | J2: 一致
A3: 林凯 | B3: 3 | C3: 2026-08-20 | D3: 苏DFM060 | E3: #2 | F3: 林凯 | G3: — | H3: 林凯 | I3: 林凯 | J3: 一致
A4: 林凯 | B4: 4 | C4: 2026-08-21 | D4: 苏DBB772 | E4: #3 | F4: 林凯 | G4: — | H4: 林凯 | I4: 林凯 | J4: 一致
A5: 林凯 | B5: 5 | C5: 2026-08-21 | D5: 皖M2A505 | E5: #4 | F5: 林凯 | G5: — | H5: （未填） | I5: 俊兴 | J5: 系统未填调货人 | K5: 财务记林凯（并扣了林凯提成）
A6: 林凯 | B6: 6 | C6: 2026-08-21 | D6: 苏EQB977 | E6: #5 | F6: 林凯 | G6: — | H6: （未填） | I6: 俊兴 | J6: 系统未填调货人 | K6: 财务记林凯（并扣了林凯提成）
A7: 林凯 | B7: 7 | C7: 2026-08-21 | D7: 苏BUK952 | E7: #6 | F7: 林凯 | G7: — | H7: 林凯 | I7: 林凯 | J7: 一致
A8: 林凯 | B8: 8 | C8: 2026-08-22 | D8: 苏DBB772 | E8: #7 | F8: 林凯 | G8: — | H8: 林凯 | I8: 林凯 | J8: 一致
A9: 林凯 | B9: 9 | C9: 2026-08-22 | D9: 苏MAK862 | E9: #9 | F9: 林凯 | G9: — | H9: （未填） | I9: 俊兴 | J9: 系统未填调货人 | K9: 财务记林凯（并扣了林凯提成）
A10: 林凯 | B10: 10 | C10: 2026-08-25 | D10: 苏DBE075 | E10: #10 | F10: 林凯 | G10: — | H10: 林凯 | I10: 林凯 | J10: 一致
A11: 林凯 | B11: 11 | C11: 2026-08-26 | D11: 苏淮货16776 | E11: #11 | F11: 林凯 | G11: — | H11: （未填） | I11: 俊兴 | J11: 系统未填调货人 | K11: 财务记林凯（并扣了林凯提成）
A12: 林凯 | B12: 12 | C12: 2026-08-27 | D12: 苏NEX375 | E12: #12 | F12: 林凯 | G12: — | H12: 林凯 | I12: 林凯 | J12: 一致
A13: 林凯 | B13: 13 | C13: 2026-08-27 | D13: 苏DFM060 | E13: #13 | F13: 林凯 | G13: — | H13: 林凯 | I13: 林凯 | J13: 一致
A14: 林凯 | B14: 14 | C14: 2026-08-27 | D14: 苏BDK567 | E14: #15 | F14: 林凯 | G14: — | H14: 林凯 | I14: 林凯 | J14: 一致
A15: 林凯 | B15: 15 | C15: 2026-08-27 | D15: 苏BZP839 | E15: #16 | F15: 林凯 | G15: — | H15: 林凯 | I15: 林凯 | J15: 一致
A16: 林凯 | B16: 16 | C16: 2026-08-27 | D16: 苏ERS080 | E16: #18 | F16: 林凯 | G16: — | H16: 林凯 | I16: 林凯 | J16: 一致
A17: 林凯 | B17: 17 | C17: 2026-08-28 | D17: 苏DFB287 | E17: #22 | F17: 林凯 | G17: — | H17: 林凯 | I17: 林凯 | J17: 一致
A18: 林凯 | B18: 18 | C18: 2026-08-28 | D18: 苏DBX137 | E18: #21 | F18: 林凯 | G18: — | H18: 林凯 | I18: 林凯 | J18: 一致
A19: 林凯 | B19: 19 | C19: 2026-08-28 | D19: 苏DBE075 | E19: #20 | F19: 林凯 | G19: — | H19: 林凯 | I19: 林凯 | J19: 一致
A20: 林凯 | B20: 20 | C20: 2026-08-28 | D20: 苏DFM060 | E20: #23 | F20: 林凯 | G20: — | H20: 林凯 | I20: 林凯 | J20: 一致
A21: 林凯 | B21: 21 | C21: 2026-08-28 | D21: 苏DBB772 | E21: #24 | F21: 林凯 | G21: — | H21: 林凯 | I21: 林凯 | J21: 一致
A22: 林凯 | B22: 22 | C22: 2026-08-28 | D22: 苏BUK952 | E22: #26 | F22: 林凯 | G22: — | H22: 林凯 | I22: 林凯 | J22: 一致
A23: 林凯 | B23: 23 | C23: 2026-08-28 | D23: 苏BDK567 | E23: #25 | F23: 林凯 | G23: — | H23: 林凯 | I23: 林凯 | J23: 一致
... A28: 林凯 | B28: 28 | C28: 2026-08-29 | D28: 苏ERS080 | E28: #32 | F28: 林凯 | G28: — | H28: 林凯 | I28: 林凯 | J28: 一致
A29: 林凯 | B29: 29 | C29: 2026-08-29 | D29: 苏DBE075 | E29: #33 | F29: 林凯 | G29: — | H29: 林凯 | I29: 林凯 | J29: 一致 | K29: ；（财务这一行是两车合并）
A30: 林凯 | B30: 29 | C30: 2026-08-29 | D30: 冀A224E6 | E30: #34 | F30: 林凯 | G30: — | H30: （未填） | I30: 俊兴 | J30: 系统未填调货人 | K30: 财务记林凯（并扣了林凯提成）；（财务这一行是两车合并）
A31: 林凯 | B31: 30 | C31: 2026-08-29 | D31: 苏DBB772 | E31: #36 | F31: 林凯 | G31: — | H31: 林凯 | I31: 林凯 | J31: 一致
A32: 林凯 | B32: 31 | C32: 2026-08-30 | D32: 苏DBB772 | E32: #44 | F32: 林凯 | G32: — | H32: 林凯 | I32: 林凯 | J32: 一致
A33: 林凯 | B33: 32 | C33: 2026-08-30 | D33: 冀A224E6 | E33: #43 | F33: 林凯 | G33: — | H33: （未填） | I33: 俊兴 | J33: 系统未填调货人 | K33: 财务记林凯（并扣了林凯提成）
A34: 林凯 | B34: 33 | C34: 2026-08-30 | D34: 苏DBB772 | E34: #42 | F34: 林凯 | G34: — | H34: 林凯 | I34: 林凯 | J34: 一致
A35: 林凯 | B35: 34 | C35: 2026-08-30 | D35: 皖SB2849 | E35: #41 | F35: 林凯 | G35: — | H35: 林凯 | I35: 林凯 | J35: 一致
A36: 林凯 | B36: 35 | C36: 2026-08-30 | D36: 苏DBE961 | E36: #38 | F36: 林凯 | G36: — | H36: （未填） | I36: 俊兴 | J36: 系统未填调货人 | K36: 财务记林凯（并扣了林凯提成）
A37: 林凯 | B37: 36 | C37: 2026-08-30 | D37: 苏DFB287 | E37: #39 | F37: 林凯 | G37: — | H37: （未填） | I37: 俊兴 | J37: 系统未填调货人 | K37: 财务记林凯（并扣了林凯提成）
A38: 林凯 | B38: 37 | C38: 2026-08-30 | D38: 苏DBE075 | E38: #37 | F38: 林凯 | G38: — | H38: 林凯 | I38: 林凯 | J38: 一致
A39: 林凯 | B39: 38 | C39: 2026-08-31 | D39: 苏DFM060 | E39: #45 | F39: 林凯 | G39: — | H39: 林凯 | I39: 林凯 | J39: 一致
A40: 林凯 | B40: 39 | C40: 2026-08-31 | D40: 冀A224E6 | E40: #46 | F40: 林凯 | G40: — | H40: 林凯 | I40: 林凯 | J40: 一致
A41: 林凯 | B41: 40 | C41: 2026-08-31 | D41: 苏DFM060 | E41: #47 | F41: 林凯 | G41: — | H41: 林凯 | I41: 林凯 | J41: 一致
A42: 林凯 | B42: 41 | C42: 2026-08-31 | D42: 苏DBB772 | E42: #48 | F42: 林凯 | G42: — | H42: 林凯 | I42: 林凯 | J42: 一致
A43: 林凯 | B43: 42 | C43: 2026-08-31 | D43: 苏DBB772 | E43: #49 | F43: 林凯 | G43: — | H43: 林凯 | I43: 林凯 | J43: 一致
A44: 林凯 | B44: 43 | C44: 2026-09-01 | D44: 苏ERS080 | E44: #50 | F44: 林凯 | G44: — | H44: 林凯 | I44: 林凯 | J44: 一致
...

Sheet ③票源
A1: 财务表 | B1: 行 | C1: 财务日期 | D1: 车号 | E1: 系统车次 | F1: 财务票源 | G1: 系统票源 | H1: 对比结果 | I1: 对利润的影响（参考） | J1: 说明 | K1: 确认：正确票源（请填）
A2: 林凯 | B2: 2 | C2: 2026-08-19 | D2: 苏DBB772 | E2: #1 | F2: 俊兴 | G2: 俊兴 | H2: 一致
A3: 林凯 | B3: 3 | C3: 2026-08-20 | D3: 苏DFM060 | E3: #2 | F3: 俊兴 | G3: 俊兴 | H3: 一致
A4: 林凯 | B4: 4 | C4: 2026-08-21 | D4: 苏DBB772 | E4: #3 | F4: 俊兴 | G4: 俊兴 | H4: 一致
A5: 林凯 | B5: 5 | C5: 2026-08-21 | D5: 皖M2A505 | E5: #4 | F5: 俊兴 | G5: 俊兴 | H5: 一致
A6: 林凯 | B6: 6 | C6: 2026-08-21 | D6: 苏EQB977 | E6: #5 | F6: 俊兴 | G6: 俊兴 | H6: 一致
A7: 林凯 | B7: 7 | C7: 2026-08-21 | D7: 苏BUK952 | E7: #6 | F7: 俊兴 | G7: 俊兴 | H7: 一致
A8: 林凯 | B8: 8 | C8: 2026-08-22 | D8: 苏DBB772 | E8: #7 | F8: 俊兴 | G8: 俊兴 | H8: 一致
A9: 林凯 | B9: 9 | C9: 2026-08-22 | D9: 苏MAK862 | E9: #9 | F9: 俊兴 | G9: 俊兴 | H9: 一致
A10: 林凯 | B10: 10 | C10: 2026-08-25 | D10: 苏DBE075 | E10: #10 | F10: 俊兴 | G10: 俊兴 | H10: 一致
A11: 林凯 | B11: 11 | C11: 2026-08-26 | D11: 苏淮货16776 | E11: #11 | F11: 俊兴 | G11: 俊兴 | H11: 一致
A12: 林凯 | B12: 12 | C12: 2026-08-27 | D12: 苏NEX375 | E12: #12 | F12: 俊兴 | G12: 俊兴 | H12: 一致
A13: 林凯 | B13: 13 | C13: 2026-08-27 | D13: 苏DFM060 | E13: #13 | F13: 俊兴 | G13: 俊兴 | H13: 一致
... A38: 林凯 | B38: 37 | C38: 2026-08-30 | D38: 苏DBE075 | E38: #37 | F38: 俊兴 | G38: 俊兴 | H38: 一致
A39: 林凯 | B39: 38 | C39: 2026-08-31 | D39: 苏DFM060 | E39: #45 | F39: 俊兴 | G39: 益周 | H39: 不一致 | J39: 俊兴/益周主营利润口径一样(都是13.5%)；但益周是“经过我们”的票，系统会另算票差留存，且占益周额度
A40: 林凯 | B40: 39 | C40: 2026-08-31 | D40: 冀A224E6 | E40: #46 | F40: 俊兴 | G40: 益周 | H40: 不一致 | J40: 俊兴/益周主营利润口径一样(都是13.5%)；但益周是“经过我们”的票，系统会另算票差留存，且占益周额度
A41: 林凯 | B41: 40 | C41: 2026-08-31 | D41: 苏DFM060 | E41: #47 | F41: 俊兴 | G41: 益周 | H41: 不一致 | J41: 俊兴/益周主营利润口径一样(都是13.5%)；但益周是“经过我们”的票，系统会另算票差留存，且占益周额度
A42: 林凯 | B42: 41 | C42: 2026-08-31 | D42: 苏DBB772 | E42: #48 | F42: 俊兴 | G42: 益周 | H42: 不一致 | J42: 俊兴/益周主营利润口径一样(都是13.5%)；但益周是“经过我们”的票，系统会另算票差留存，且占益周额度
A43: 林凯 | B43: 42 | C43: 2026-08-31 | D43: 苏DBB772 | E43: #49 | F43: 俊兴 | G43: 益周 | H43: 不一致 | J43: 俊兴/益周主营利润口径一样(都是13.5%)；但益周是“经过我们”的票，系统会另算票差留存，且占益周额度
A44: 林凯 | B44: 43 | C44: 2026-09-01 | D44: 苏ERS080 | E44: #50 | F44: 俊兴 | G44: 益周 | H44: 不一致 | J44: 俊兴/益周主营利润口径一样(都是13.5%)；但益周是“经过我们”的票，系统会另算票差留存，且占益周额度
A45: 林凯 | B45: 44 | C45: 2026-09-01 | D45: 苏DFM060 | E45: #51 | F45: 俊兴 | G45: 益周 | H45: 不一致 | J45: 俊兴/益周主营利润口径一样(都是13.5%)；但益周是“经过我们”的票，系统会另算票差留存，且占益周额度
A46: 林凯 | B46: 45 | C46: 2026-09-01 | D46: 苏DBX137 | E46: #52 | F46: 俊兴 | G46: 益周 | H46: 不一致 | J46: 俊兴/益周主营利润口径一样(都是13.5%)；但益周是“经过我们”的票，系统会另算票差留存，且占益周额度
A47: 林凯 | B47: 46 | C47: 2026-09-01 | D47: 苏DBB772 | E47: #53 | F47: 俊兴 | G47: 益周 | H47: 不一致 | J47: 俊兴/益周主营利润口径一样(都是13.5%)；但益周是“经过我们”的票，系统会另算票差留存，且占益周额度
A48: 林凯 | B48: 47 | C48: 2026-09-06 | D48: 皖城兴货688 | E48: #61 | F48: 俊兴 | G48: 益周 | H48: 不一致 | J48: 俊兴/益周主营利润口径一样(都是13.5%)；但益周是“经过我们”的票，系统会另算票差留存，且占益周额度
A49: 林凯 | B49: 48 | C49: 2026-09-08 | D49: 鲁济宁货1567 | E49: #62 | F49: 煌烽 | G49: 煌烽 | H49: 一致
A50: 林凯 | B50: 49 | C50: 2026-09-18 | D50: 苏DBB772 | E50: #89 | F50: 煌烽 | G50: 自带票 | H50: 不一致 | J50: 财务是煌烽票源，系统没挂票源（按带票算）
A51: 林凯 | B51: 50 | C51: 2026-09-18 | D51: 苏NEN536 | E51: #90 | F51: 煌烽 | G51: 煌烽 | H51: 一致
A52: 林凯 | B52: 51 | C52: 2026-09-19 | D52: 苏GE2356 | E52: #95 | F52: 煌烽 | G52: 煌烽 | H52: 一致
A53: 林凯 | B53: 52 | C53: 2026-09-19 | D53: 苏NHY179 | E53: #96 | F53: 煌烽 | G53: 煌烽 | H53: 一致
A54: 林凯-鑫景通 | B54: 2 | C54: 2026-09-12 | D54: 苏DBE075 | E54: #66 | F54: 自带票 | G54: 俊兴 | H54: 不一致 | J54: 财务是带票（供货厂自带票），系统挂了俊兴票源
A55: 林凯-鑫景通 | B55: 3 | C55: 2026-09-15 | D55: 苏DBB772 | E55: #78 | F55: 自带票 | G55: 自带票 | H55: 一致
A56: 林凯-君盛 | B56: 2 | C56: 2026-08-27 | D56: 苏DBB772 | E56: #14 | F56: 自带票 | G56: 俊兴 | H56: 不一致 | J56: 财务是带票（供货厂自带票），系统挂了俊兴票源
A57: 林凯-君盛 | B57: 3 | C57: 2026-09-12 | D57: 苏DBE075 | E57: #68 | F57: 自带票 | G57: 俊兴 | H57: 不一致 | J57: 财务是带票（供货厂自带票），系统挂了俊兴票源
A58: 林凯-君盛 | B58: 4 | C58: 2026-09-14 | D58: 苏DBB772 | E58: #69 | F58: 自带票 | G58: 俊兴 | H58: 不一致 | J58: 财务是带票（供货厂自带票），系统挂了俊兴票源
A59: 林凯-君盛 | B59: 5 | C59: 2026-09-15 | D59: 苏DBE961 | E59: #79 | F59: 自带票 | G59: 自带票 | H59: 一致
A60: 林凯-君盛 | B60: 6 | C60: 2026-09-15 | D60: 苏DBE075 | E60: #74 | F60: 自带票 | G60: 自带票 | H60: 一致
A61: 林凯-君盛 | B61: 7 | C61: 2026-09-17 | D61: 苏DBB772 | E61: #87 | F61: 自带票 | G61: 自带票 | H61: 一致
A62: 林凯-君盛 | B62: 8 | C62: 2026-09-18 | D62: 苏DBE075 | E62: #91 | F62: 自带票 | G62: 自带票 | H62: 一致
A63: 林凯-君盛 | B63: 9 | C63: 2026-09-18 | D63: 苏DBB772 | E63: #92 | F63: 自带票 | G63: 自带票 | H63: 一致
A64: 林凯-君盛 | B64: 10 | C64: 2026-09-20 | D64: 苏DBB772 | E64: #98 | F64: 自带票 | G64: 自带票 | H64: 一致
...

Sheet ④计算路径
A1: 财务表 | B1: 行 | C1: 财务日期 | D1: 车号 | E1: 系统车次 | F1: 财务路径 | G1: 系统链条规则 | H1: 对比结果 | I1: 财务利润 | J1: 系统利润 | K1: 说明 | L1: 确认：正确路径（请填）
A2: 林凯 | B2: 2 | C2: 2026-08-19 | D2: 苏DBB772 | E2: #1 | F2: 配票 | G2: 配票 | H2: 一致 | I2: 482.7689 | J2: 482.3169
A3: 林凯 | B3: 3 | C3: 2026-08-20 | D3: 苏DFM060 | E3: #2 | F3: 配票 | G3: 配票 | H3: 一致 | I3: 252.514 | J3: 252.474
A4: 林凯 | B4: 4 | C4: 2026-08-21 | D4: 苏DBB772 | E4: #3 | F4: 配票 | G4: 配票 | H4: 一致 | I4: 608.1538 | J4: 609.1058
A5: 林凯 | B5: 5 | C5: 2026-08-21 | D5: 皖M2A505 | E5: #4 | F5: 配票 | G5: 配票 | H5: 一致 | I5: 238.7238 | J5: 420.1398
A6: 林凯 | B6: 6 | C6: 2026-08-21 | D6: 苏EQB977 | E6: #5 | F6: 配票 | G6: 配票 | H6: 一致 | I6: 215.9577 | J6: 380.6217
A7: 林凯 | B7: 7 | C7: 2026-08-21 | D7: 苏BUK952 | E7: #6 | F7: 配票 | G7: 配票 | H7: 一致 | I7: 175.73675 | J7: 175.62995
A8: 林凯 | B8: 8 | C8: 2026-08-22 | D8: 苏DBB772 | E8: #7 | F8: 配票 | G8: 配票 | H8: 一致 | I8: 455.8725 | J8: 455.5725
A9: 林凯 | B9: 9 | C9: 2026-08-22 | D9: 苏MAK862 | E9: #9 | F9: 配票 | G9: 配票 | H9: 一致 | I9: 224.6992 | J9: 395.6432
A10: 林凯 | B10: 10 | C10: 2026-08-25 | D10: 苏DBE075 | E10: #10 | F10: 配票 | G10: 配票 | H10: 一致 | I10: 524.185 | J10: 523.665
A11: 林凯 | B11: 11 | C11: 2026-08-26 | D11: 苏淮货16776 | E11: #11 | F11: 配票 | G11: 配票 | H11: 一致 | I11: 3978.1358 | J11: 9581.3704
A12: 林凯 | B12: 12 | C12: 2026-08-27 | D12: 苏NEX375 | E12: #12 | F12: 配票 | G12: 配票 | H12: 一致 | I12: 270.71435 | J12: 471.36035
A13: 林凯 | B13: 13 | C13: 2026-08-27 | D13: 苏DFM060 | E13: #13 | F13: 配票 | G13: 配票 | H13: 一致 | I13: 253.724 | J13: 424.634
... A28: 林凯 | B28: 28 | C28: 2026-08-29 | D28: 苏ERS080 | E28: #32 | F28: 配票 | G28: 配票 | H28: 一致 | I28: 346.36875 | J28: 590.11875
A29: 林凯 | B29: 29 | C29: 2026-08-29 | D29: 苏DBE075 | E29: #33 | F29: 配票 | G29: 配票 | H29: 一致 | J29: 1008.3504
A30: 林凯 | B30: 29 | C30: 2026-08-29 | D30: 冀A224E6 | E30: #34 | F30: 配票 | G30: 配票 | H30: 一致 | J30: 346.1
A31: 林凯 | B31: 30 | C31: 2026-08-29 | D31: 苏DBB772 | E31: #36 | F31: 配票 | G31: 配票 | H31: 一致 | I31: 417.4923 | J31: 746.8083
A32: 林凯 | B32: 31 | C32: 2026-08-30 | D32: 苏DBB772 | E32: #44 | F32: 配票 | G32: 配票 | H32: 一致 | I32: 428.6318 | J32: 768.2878
A33: 林凯 | B33: 32 | C33: 2026-08-30 | D33: 冀A224E6 | E33: #43 | F33: 配票 | G33: 配票 | H33: 一致 | I33: 313.5498 | J33: 775.8842
A34: 林凯 | B34: 33 | C34: 2026-08-30 | D34: 苏DBB772 | E34: #42 | F34: 配票 | G34: 配票 | H34: 一致 | I34: 645.5409 | J34: 1064.4249
A35: 林凯 | B35: 34 | C35: 2026-08-30 | D35: 皖SB2849 | E35: #41 | F35: 配票 | G35: 配票 | H35: 一致 | I35: 293.4319 | J35: 509.8951
A36: 林凯 | B36: 35 | C36: 2026-08-30 | D36: 苏DBE961 | E36: #38 | F36: 配票 | G36: 配票 | H36: 一致 | I36: 523.526 | J36: 1308.9628
A37: 林凯 | B37: 36 | C37: 2026-08-30 | D37: 苏DFB287 | E37: #39 | F37: 配票 | G37: 配票 | H37: 一致 | I37: 553.3715 | J37: 1385.8627
A38: 林凯 | B38: 37 | C38: 2026-08-30 | D38: 苏DBE075 | E38: #37 | F38: 配票 | G38: 配票 | H38: 一致 | I38: 627.6096 | J38: 1036.6976
A39: 林凯 | B39: 38 | C39: 2026-08-31 | D39: 苏DFM060 | E39: #45 | F39: 配票 | G39: 配票 | H39: 一致 | I39: 179.1576 | J39: 304.0776
A40: 林凯 | B40: 39 | C40: 2026-08-31 | D40: 冀A224E6 | E40: #46 | F40: 配票 | G40: 配票 | H40: 一致 | I40: 214.2892 | J40: 359.138
A41: 林凯 | B41: 40 | C41: 2026-08-31 | D41: 苏DFM060 | E41: #47 | F41: 配票 | G41: 配票 | H41: 一致 | I41: 409.6359 | J41: 692.9999
A42: 林凯 | B42: 41 | C42: 2026-08-31 | D42: 苏DBB772 | E42: #48 | F42: 配票 | G42: 配票 | H42: 一致 | I42: 620.0048 | J42: 1024.5488
... A49: 林凯 | B49: 48 | C49: 2026-09-08 | D49: 鲁济宁货1567 | E49: #62 | F49: 配票 | G49: 配票 | H49: 一致 | I49: 14834.548 | J49: 14833.682
A50: 林凯 | B50: 49 | C50: 2026-09-18 | D50: 苏DBB772 | E50: #89 | F50: 配票 | G50: 直签带票 | H50: 不一致 | I50: 2043.609 | J50: 2260.98 | K50: 财务记在“林凯”配票(煌烽票源)，系统是君盛直签带票
A51: 林凯 | B51: 50 | C51: 2026-09-18 | D51: 苏NEN536 | E51: #90 | F51: 配票 | G51: 配票 | H51: 一致 | I51: 805.73352 | J51: 805.45752
A52: 林凯 | B52: 51 | C52: 2026-09-19 | D52: 苏GE2356 | E52: #95 | F52: 配票 | G52: 配票 | H52: 一致 | I52: 801.53736 | J52: 700.86936
A53: 林凯 | B53: 52 | C53: 2026-09-19 | D53: 苏NHY179 | E53: #96 | F53: 配票 | G53: 配票 | H53: 一致 | I53: 800.5576 | J53: 699.9768
A54: 林凯-鑫景通 | B54: 2 | C54: 2026-09-12 | D54: 苏DBE075 | E54: #66 | F54: 带票 | G54: 户头通道 | H54: 一致 | I54: 2107.28 | J54: 1607.08 | K54: 系统叫“户头通道”，和“直签带票”都是服务费算法，数值一样；名字按实际情况选
A55: 林凯-鑫景通 | B55: 3 | C55: 2026-09-15 | D55: 苏DBB772 | E55: #78 | F55: 带票 | G55: 直签带票 | H55: 一致 | I55: 1931.3 | J55: 1930.5
A56: 林凯-君盛 | B56: 2 | C56: 2026-08-27 | D56: 苏DBB772 | E56: #14 | F56: 带票 | G56: 配票 | H56: 不一致 | I56: 1787.94 | J56: 748.6171 | K56: 财务记在“林凯-君盛”带票(服务费)，系统是配票+俊兴票源
A57: 林凯-君盛 | B57: 3 | C57: 2026-09-12 | D57: 苏DBE075 | E57: #68 | F57: 带票 | G57: 户头通道 | H57: 一致 | I57: 1767.28 | J57: 1766.88 | K57: 系统叫“户头通道”，和“直签带票”都是服务费算法，数值一样；名字按实际情况选
A58: 林凯-君盛 | B58: 4 | C58: 2026-09-14 | D58: 苏DBB772 | E58: #69 | F58: 带票 | G58: 配票 | H58: 不一致 | I58: 1644.3 | J58: 996.0195 | K58: 财务记在“林凯-君盛”带票，系统是配票、供货厂写的林凯
A59: 林凯-君盛 | B59: 5 | C59: 2026-09-15 | D59: 苏DBE961 | E59: #79 | F59: 带票 | G59: 直签带票 | H59: 一致 | I59: 848.06 | J59: 847.26
A60: 林凯-君盛 | B60: 6 | C60: 2026-09-15 | D60: 苏DBE075 | E60: #74 | F60: 带票 | G60: 直签带票 | H60: 一致 | I60: 850.02 | J60: 849.42
...

Sheet ⑤参数差异
A1: 只比“计算路径一致”的车；路径不一致的 5 车等你在④改完后再比。调货人按系统当前记录算——②里改了调货人，提成那列会跟着变。财务 INT 取整造成的零点几元不单列（在最后一列“取整”里）。
A2: 财务表 | B2: 行 | C2: 车号 | D2: 系统车次 | E2: 路径 | F2: 吨位 | G2: 结算金额 | H2: 财务利润 | I2: 系统利润 | J2: 差额 (系统−财务) | K2: 量补 财务(元/吨) | L2: 量补 系统(元/吨) | M2: 量补影响 | N2: 提成 财务(元/吨) | O2: 提成 系统(元/吨) | P2: 提成影响 | Q2: 票点系数 财务 | R2: 票点系数 系统 | S2: 票点影响 | T2: 给客户付 财务 | U2: 给客户付 系统 | V2: 给客户影响 | W2: 切割费 系统另扣 | X2: 切割费影响 | Y2: 取整/其它 | Z2: 有参数差异
A3: 林凯 | B3: 2 | C3: 苏DBB772 | D3: #1 | E3: 配票 | F3: 73.58 | G3: 168498.2 | H3: 482.7689 | I3: 482.3169 | J3: =I3-H3 -> -0.452 | K3: 20 | L3: 20 | M3: =(L3-K3)*F3 -> 0 | N3: 5 | O3: 5 | P3: =(N3-O3)*F3 -> 0 | Q3: 0.865 | R3: 0.865 | S3: =(R3-Q3)*(G3-23*F3) -> 0 | T3: 0.86 | U3: 0.86 | V3: =(T3-U3)*G3 -> 0 | W3: 0 | X3: =-W3 -> 0 | Y3: =J3-M3-P3-S3-V3-X3 -> -0.452 | Z3: =IF(OR(ABS(M3)>0.5,ABS(P3)>0.5,ABS(S3)>0.5,ABS(V3)>0.5,ABS(X3)>0.5),"是","")
A4: 林凯 | B4: 3 | C4: 苏DFM060 | D4: #2 | E4: 配票 | F4: 34.8 | G4: 84564 | H4: 252.514 | I4: 252.474 | J4: =I4-H4 -> -0.04 | K4: 20 | L4: 20 | M4: =(L4-K4)*F4 -> 0 | N4: 5 | O4: 5 | P4: =(N4-O4)*F4 -> 0 | Q4: 0.865 | R4: 0.865 | S4: =(R4-Q4)*(G4-23*F4) -> 0 | T4: 0.86 | U4: 0.86 | V4: =(T4-U4)*G4 -> 0 | W4: 0 | X4: =-W4 -> 0 | Y4: =J4-M4-P4-S4-V4-X4 -> -0.04 | Z4: =IF(OR(ABS(M4)>0.5,ABS(P4)>0.5,ABS(S4)>0.5,ABS(V4)>0.5,ABS(X4)>0.5),"是","")
A5: 林凯 | B5: 4 | C5: 苏DBB772 | D5: #3 | E5: 配票 | F5: 81.16 | G5: 201276.8 | H5: 608.1538 | I5: 609.1058 | J5: =I5-H5 -> 0.952 | K5: 20 | L5: 20 | M5: =(L5-K5)*F5 -> 0 | N5: 5 | O5: 5 | P5: =(N5-O5)*F5 -> 0 | Q5: 0.865 | R5: 0.865 | S5: =(R5-Q5)*(G5-23*F5) -> 0 | T5: 0.86 | U5: 0.86 | V5: =(T5-U5)*G5 -> 0 | W5: 0 | X5: =-W5 -> 0 | Y5: =J5-M5-P5-S5-V5-X5 -> 0.952 | Z5: =IF(OR(ABS(M5)>0.5,ABS(P5)>0.5,ABS(S5)>0.5,ABS(V5)>0.5,ABS(X5)>0.5),"是","")
A6: 林凯 | B6: 5 | C6: 皖M2A505 | D6: #4 | E6: 配票 | F6: 36.36 | G6: 83264.4 | H6: 238.7238 | I6: 420.1398 | J6: =I6-H6 -> 181.416 | K6: 20 | L6: 20 | M6: =(L6-K6)*F6 -> 0 | N6: 5 | O6: 0 | P6: =(N6-O6)*F6 -> 181.8 | Q6: 0.865 | R6: 0.865 | S6: =(R6-Q6)*(G6-23*F6) -> 0 | T6: 0.86 | U6: 0.86 | V6: =(T6-U6)*G6 -> 0 | W6: 0 | X6: =-W6 -> 0 | Y6: =J6-M6-P6-S6-V6-X6 -> -0.384 | Z6: =IF(OR(ABS(M6)>0.5,ABS(P6)>0.5,ABS(S6)>0.5,ABS(V6)>0.5,ABS(X6)>0.5),"是","") -> 是
A7: 林凯 | B7: 6 | C7: 苏EQB977 | D7: #5 | E7: 配票 | F7: 32.94 | G7: 75432.6 | H7: 215.9577 | I7: 380.6217 | J7: =I7-H7 -> 164.664 | K7: 20 | L7: 20 | M7: =(L7-K7)*F7 -> 0 | N7: 5 | O7: 0 | P7: =(N7-O7)*F7 -> 164.7 | Q7: 0.865 | R7: 0.865 | S7: =(R7-Q7)*(G7-23*F7) -> 0 | T7: 0.86 | U7: 0.86 | V7: =(T7-U7)*G7 -> 0 | W7: 0 | X7: =-W7 -> 0 | Y7: =J7-M7-P7-S7-V7-X7 -> -0.036 | Z7: =IF(OR(ABS(M7)>0.5,ABS(P7)>0.5,ABS(S7)>0.5,ABS(V7)>0.5,ABS(X7)>0.5),"是","") -> 是
A8: 林凯 | B8: 7 | C8: 苏BUK952 | D8: #6 | E8: 配票 | F8: 24.41 | G8: 59023.38 | H8: 175.73675 | I8: 175.62995 | J8: =I8-H8 -> -0.1068 | K8: 20 | L8: 20 | M8: =(L8-K8)*F8 -> 0 | N8: 5 | O8: 5 | P8: =(N8-O8)*F8 -> 0 | Q8: 0.865 | R8: 0.865 | S8: =(R8-Q8)*(G8-23*F8) -> 0 | T8: 0.86 | U8: 0.86 | V8: =(T8-U8)*G8 -> 0 | W8: 0 | X8: =-W8 -> 0 | Y8: =J8-M8-P8-S8-V8-X8 -> -0.1068 | Z8: =IF(OR(ABS(M8)>0.5,ABS(P8)>0.5,ABS(S8)>0.5,ABS(V8)>0.5,ABS(X8)>0.5),"是","")
A9: 林凯 | B9: 8 | C9: 苏DBB772 | D9: #7 | E9: 配票 | F9: 69.5 | G9: 159155 | H9: 455.8725 | I9: 455.5725 | J9: =I9-H9 -> -0.3 | K9: 20 | L9: 20 | M9: =(L9-K9)*F9 -> 0 | N9: 5 | O9: 5 | P9: =(N9-O9)*F9 -> 0 | Q9: 0.865 | R9: 0.865 | S9: =(R9-Q9)*(G9-23*F9) -> 0 | T9: 0.86 | U9: 0.86 | V9: =(T9-U9)*G9 -> 0 | W9: 0 | X9: =-W9 -> 0 | Y9: =J9-M9-P9-S9-V9-X9 -> -0.3 | Z9: =IF(OR(ABS(M9)>0.5,ABS(P9)>0.5,ABS(S9)>0.5,ABS(V9)>0.5,ABS(X9)>0.5),"是","")
A10: 林凯 | B10: 9 | C10: 苏MAK862 | D10: #9 | E10: 配票 | F10: 34.24 | G10: 78409.6 | H10: 224.6992 | I10: 395.6432 | J10: =I10-H10 -> 170.944 | K10: 20 | L10: 20 | M10: =(L10-K10)*F10 -> 0 | N10: 5 | O10: 0 | P10: =(N10-O10)*F10 -> 171.2 | Q10: 0.865 | R10: 0.865 | S10: =(R10-Q10)*(G10-23*F10) -> 0 | T10: 0.86 | U10: 0.86 | V10: =(T10-U10)*G10 -> 0 | W10: 0 | X10: =-W10 -> 0 | Y10: =J10-M10-P10-S10-V10-X10 -> -0.256 | Z10: =IF(OR(ABS(M10)>0.5,ABS(P10)>0.5,ABS(S10)>0.5,ABS(V10)>0.5,ABS(X10)>0.5),"是","") -> 是
A11: 林凯 | B11: 10 | C11: 苏DBE075 | D11: #10 | E11: 配票 | F11: 81 | G11: 184032 | H11: 524.185 | I11: 523.665 | J11: =I11-H11 -> -0.52 | K11: 20 | L11: 20 | M11: =(L11-K11)*F11 -> 0 | N11: 5 | O11: 5 | P11: =(N11-O11)*F11 -> 0 | Q11: 0.865 | R11: 0.865 | S11: =(R11-Q11)*(G11-23*F11) -> 0 | T11: 0.86 | U11: 0.86 | V11: =(T11-U11)*G11 -> 0 | W11: 0 | X11: =-W11 -> 0 | Y11: =J11-M11-P11-S11-V11-X11 -> -0.52 | Z11: =IF(OR(ABS(M11)>0.5,ABS(P11)>0.5,ABS(S11)>0.5,ABS(V11)>0.5,ABS(X11)>0.5),"是","")
A12: 林凯 | B12: 11 | C12: 苏淮货16776 | D12: #11 | E12: 配票 | F12: 560.39 | G12: 1344115.9 | H12: 3978.1358 | I12: 9581.3704 | J12: =I12-H12 -> 5603.2346 | K12: 20 | L12: 25 | M12: =(L12-K12)*F12 -> 2801.95 | N12: 5 | O12: 0 | P12: =(N12-O12)*F12 -> 2801.95 | Q12: 0.865 | R12: 0.865 | S12: =(R12-Q12)*(G12-23*F12) -> 0 | T12: 0.86 | U12: 0.86 | V12: =(T12-U12)*G12 -> 0 | W12: 0 | X12: =-W12 -> 0 | Y12: =J12-M12-P12-S12-V12-X12 -> -0.6654 | Z12: =IF(OR(ABS(M12)>0.5,ABS(P12)>0.5,ABS(S12)>0.5,ABS(V12)>0.5,ABS(X12)>0.5),"是","") -> 是
A13: 林凯 | B13: 12 | C13: 苏NEX375 | D13: #12 | E13: 配票 | F13: 40.27 | G13: 93426.4 | H13: 270.71435 | I13: 471.36035 | J13: =I13-H13 -> 200.646 | K13: 20 | L13: 25 | M13: =(L13-K13)*F13 -> 201.35 | N13: 5 | O13: 5 | P13: =(N13-O13)*F13 -> 0 | Q13: 0.865 | R13: 0.865 | S13: =(R13-Q13)*(G13-23*F13) -> 0 | T13: 0.86 | U13: 0.86 | V13: =(T13-U13)*G13 -> 0 | W13: 0 | X13: =-W13 -> 0 | Y13: =J13-M13-P13-S13-V13-X13 -> -0.704 | Z13: =IF(OR(ABS(M13)>0.5,ABS(P13)>0.5,ABS(S13)>0.5,ABS(V13)>0.5,ABS(X13)>0.5),"是","") -> 是
A14: 林凯 | B14: 13 | C14: 苏DFM060 | D14: #13 | E14: 配票 | F14: 34.3 | G14: 84206.5 | H14: 253.724 | I14: 424.634 | J14: =I14-H14 -> 170.91 | K14: 20 | L14: 25 | M14: =(L14-K14)*F14 -> 171.5 | N14: 5 | O14: 5 | P14: =(N14-O14)*F14 -> 0 | Q14: 0.865 | R14: 0.865 | S14: =(R14-Q14)*(G14-23*F14) -> 0 | T14: 0.86 | U14: 0.86 | V14: =(T14-U14)*G14 -> 0 | W14: 0 | X14: =-W14 -> 0 | Y14: =J14-M14-P14-S14-V14-X14 -> -0.59 | Z14: =IF(OR(ABS(M14)>0.5,ABS(P14)>0.5,ABS(S14)>0.5,ABS(V14)>0.5,ABS(X14)>0.5),"是","") -> 是
... A52: 林凯 | B52: 52 | C52: 苏NHY179 | D52: #96 | E52: 配票 | F52: 33.96 | G52: 78619.28 | H52: 800.5576 | I52: 699.9768 | J52: =I52-H52 -> -100.5808 | K52: 25 | L52: 25 | M52: =(L52-K52)*F52 -> 0 | N52: 0 | O52: 0 | P52: =(N52-O52)*F52 -> 0 | Q52: 0.868 | R52: 0.868 | S52: =(R52-Q52)*(G52-23*F52) -> 0 | T52: 0.86 | U52: 0.86 | V52: =(T52-U52)*G52 -> 0 | W52: 100 | X52: =-W52 -> -100 | Y52: =J52-M52-P52-S52-V52-X52 -> -0.5808 | Z52: =IF(OR(ABS(M52)>0.5,ABS(P52)>0.5,ABS(S52)>0.5,ABS(V52)>0.5,ABS(X52)>0.5),"是","") -> 是
A53: 林凯-鑫景通 | B53: 2 | C53: 苏DBE075 | D53: #66 | E53: 带票 | F53: 78.04 | G53: 200062.8 | H53: 2107.28 | I53: 1607.08 | J53: =I53-H53 -> -500.2 | K53: 25 | L53: 25 | M53: =(L53-K53)*F53 -> 0 | N53: 15 | O53: 15 | P53: =(N53-O53)*F53 -> 0 | S53: 0 | V53: 0 | W53: 500 | X53: =-W53 -> -500 | Y53: =J53-M53-P53-S53-V53-X53 -> -0.2 | Z53: =IF(OR(ABS(M53)>0.5,ABS(P53)>0.5,ABS(S53)>0.5,ABS(V53)>0.5,ABS(X53)>0.5),"是","") -> 是
A54: 林凯-鑫景通 | B54: 3 | C54: 苏DBB772 | D54: #78 | E54: 带票 | F54: 71.5 | G54: 169455 | H54: 1931.3 | I54: 1930.5 | J54: =I54-H54 -> -0.8 | K54: 25 | L54: 25 | M54: =(L54-K54)*F54 -> 0 | N54: 15 | O54: 15 | P54: =(N54-O54)*F54 -> 0 | S54: 0 | V54: 0 | W54: 0 | X54: =-W54 -> 0 | Y54: =J54-M54-P54-S54-V54-X54 -> -0.8 | Z54: =IF(OR(ABS(M54)>0.5,ABS(P54)>0.5,ABS(S54)>0.5,ABS(V54)>0.5,ABS(X54)>0.5),"是","")
A55: 林凯-君盛 | B55: 3 | C55: 苏DBE075 | D55: #68 | E55: 带票 | F55: 65.44 | G55: 147240 | H55: 1767.28 | I55: 1766.88 | J55: =I55-H55 -> -0.4 | K55: 25 | L55: 25 | M55: =(L55-K55)*F55 -> 0 | N55: 15 | O55: 15 | P55: =(N55-O55)*F55 -> 0 | S55: 0 | V55: 0 | W55: 0 | X55: =-W55 -> 0 | Y55: =J55-M55-P55-S55-V55-X55 -> -0.4 | Z55: =IF(OR(ABS(M55)>0.5,ABS(P55)>0.5,ABS(S55)>0.5,ABS(V55)>0.5,ABS(X55)>0.5),"是","")
A56: 林凯-君盛 | B56: 5 | C56: 苏DBE961 | D56: #79 | E56: 带票 | F56: 31.38 | G56: 70605 | H56: 848.06 | I56: 847.26 | J56: =I56-H56 -> -0.8 | K56: 25 | L56: 25 | M56: =(L56-K56)*F56 -> 0 | N56: 15 | O56: 15 | P56: =(N56-O56)*F56 -> 0 | S56: 0 | V56: 0 | W56: 0 | X56: =-W56 -> 0 | Y56: =J56-M56-P56-S56-V56-X56 -> -0.8 | Z56: =IF(OR(ABS(M56)>0.5,ABS(P56)>0.5,ABS(S56)>0.5,ABS(V56)>0.5,ABS(X56)>0.5),"是","")
A57: 林凯-君盛 | B57: 6 | C57: 苏DBE075 | D57: #74 | E57: 带票 | F57: 31.46 | G57: 70785 | H57: 850.02 | I57: 849.42 | J57: =I57-H57 -> -0.6 | K57: 25 | L57: 25 | M57: =(L57-K57)*F57 -> 0 | N57: 15 | O57: 15 | P57: =(N57-O57)*F57 -> 0 | S57: 0 | V57: 0 | W57: 0 | X57: =-W57 -> 0 | Y57: =J57-M57-P57-S57-V57-X57 -> -0.6 | Z57: =IF(OR(ABS(M57)>0.5,ABS(P57)>0.5,ABS(S57)>0.5,ABS(V57)>0.5,ABS(X57)>0.5),"是","")
A58: 林凯-君盛 | B58: 7 | C58: 苏DBB772 | D58: #87 | E58: 带票 | F58: 28.84 | G58: 66389.68 | H58: 778.76 | I58: 778.68 | J58: =I58-H58 -> -0.08 | K58: 25 | L58: 25 | M58: =(L58-K58)*F58 -> 0 | N58: 15 | O58: 15 | P58: =(N58-O58)*F58 -> 0 | S58: 0 | V58: 0 | W58: 0 | X58: =-W58 -> 0 | Y58: =J58-M58-P58-S58-V58-X58 -> -0.08 | Z58: =IF(OR(ABS(M58)>0.5,ABS(P58)>0.5,ABS(S58)>0.5,ABS(V58)>0.5,ABS(X58)>0.5),"是","")
A59: 林凯-君盛 | B59: 8 | C59: 苏DBE075 | D59: #91 | E59: 带票 | F59: 30.72 | G59: 70717.44 | H59: 830.08 | I59: 829.44 | J59: =I59-H59 -> -0.64 | K59: 25 | L59: 25 | M59: =(L59-K59)*F59 -> 0 | N59: 15 | O59: 15 | P59: =(N59-O59)*F59 -> 0 | S59: 0 | V59: 0 | W59: 0 | X59: =-W59 -> 0 | Y59: =J59-M59-P59-S59-V59-X59 -> -0.64 | Z59: =IF(OR(ABS(M59)>0.5,ABS(P59)>0.5,ABS(S59)>0.5,ABS(V59)>0.5,ABS(X59)>0.5),"是","")
A60: 林凯-君盛 | B60: 9 | C60: 苏DBB772 | D60: #92 | E60: 带票 | F60: 31.32 | G60: 72098.64 | H60: 846.48 | I60: 845.64 | J60: =I60-H60 -> -0.84 | K60: 25 | L60: 25 | M60: =(L60-K60)*F60 -> 0 | N60: 15 | O60: 15 | P60: =(N60-O60)*F60 -> 0 | S60: 0 | V60: 0 | W60: 0 | X60: =-W60 -> 0 | Y60: =J60-M60-P60-S60-V60-X60 -> -0.84 | Z60: =IF(OR(ABS(M60)>0.5,ABS(P60)>0.5,ABS(S60)>0.5,ABS(V60)>0.5,ABS(X60)>0.5),"是","")
A61: 林凯-君盛 | B61: 10 | C61: 苏DBB772 | D61: #98 | E61: 带票 | F61: 32.12 | G61: 73940.24 | H61: 867.68 | I61: 867.24 | J61: =I61-H61 -> -0.44 | K61: 25 | L61: 25 | M61: =(L61-K61)*F61 -> 0 | N61: 15 | O61: 15 | P61: =(N61-O61)*F61 -> 0 | S61: 0 | V61: 0 | W61: 0 | X61: =-W61 -> 0 | Y61: =J61-M61-P61-S61-V61-X61 -> -0.44 | Z61: =IF(OR(ABS(M61)>0.5,ABS(P61)>0.5,ABS(S61)>0.5,ABS(V61)>0.5,ABS(X61)>0.5),"是","")
A62: 林凯-君盛 | B62: 11 | C62: 苏DBE075 | D62: #99 | E62: 带票 | F62: 32.72 | G62: 75321.44 | H62: 884.08 | I62: 883.44 | J62: =I62-H62 -> -0.64 | K62: 25 | L62: 25 | M62: =(L62-K62)*F62 -> 0 | N62: 15 | O62: 15 | P62: =(N62-O62)*F62 -> 0 | S62: 0 | V62: 0 | W62: 0 | X62: =-W62 -> 0 | Y62: =J62-M62-P62-S62-V62-X62 -> -0.64 | Z62: =IF(OR(ABS(M62)>0.5,ABS(P62)>0.5,ABS(S62)>0.5,ABS(V62)>0.5,ABS(X62)>0.5),"是","")
A63: 林凯-力拓 | B63: 2 | C63: 苏DBE075 | D63: #63 | E63: 带票 | F63: 82.26 | G63: 208117.8 | H63: 2221.42 | I63: 2221.02 | J63: =I63-H63 -> -0.4 | K63: 25 | L63: 25 | M63: =(L63-K63)*F63 -> 0 | N63: 15 | O63: 15 | P63: =(N63-O63)*F63 -> 0 | S63: 0 | V63: 0 | W63: 0 | X63: =-W63 -> 0 | Y63: =J63-M63-P63-S63-V63-X63 -> -0.4 | Z63: =IF(OR(ABS(M63)>0.5,ABS(P63)>0.5,ABS(S63)>0.5,ABS(V63)>0.5,ABS(X63)>0.5),"是","")
A64: 林凯-力拓 | B64: 3 | C64: 苏DBB772 | D64: #64 | E64: 带票 | F64: 82.2 | G64: 207966 | H64: 2219.4 | I64: 2219.4 | J64: =I64-H64 -> 1.0004442e-11 | K64: 25 | L64: 25 | M64: =(L64-K64)*F64 -> 0 | N64: 15 | O64: 15 | P64: =(N64-O64)*F64 -> 0 | S64: 0 | V64: 0 | W64: 0 | X64: =-W64 -> 0 | Y64: =J64-M64-P64-S64-V64-X64 -> 1.0004442e-11 | Z64: =IF(OR(ABS(M64)>0.5,ABS(P64)>0.5,ABS(S64)>0.5,ABS(V64)>0.5,ABS(X64)>0.5),"是","")
... A72: 林凯-兴德 | B72: 5 | C72: 苏DBB772 | D72: #102 | E72: 带票 | F72: 75.44 | G72: 196898.4 | H72: 2037.68 | I72: 2036.88 | J72: =I72-H72 -> -0.8 | K72: 25 | L72: 25 | M72: =(L72-K72)*F72 -> 0 | N72: 15 | O72: 15 | P72: =(N72-O72)*F72 -> 0 | S72: 0 | V72: 0 | W72: 0 | X72: =-W72 -> 0 | Y72: =J72-M72-P72-S72-V72-X72 -> -0.8 | Z72: =IF(OR(ABS(M72)>0.5,ABS(P72)>0.5,ABS(S72)>0.5,ABS(V72)>0.5,ABS(X72)>0.5),"是","")
A73: 李涛 | B73: 2 | C73: 苏BTQ938 | D73: #40 | E73: 配票 | F73: 32.42 | G73: 77808 | H73: 555.4241 | I73: 554.5441 | J73: =I73-H73 -> -0.88 | K73: 25 | L73: 25 | M73: =(L73-K73)*F73 -> 0 | N73: 0 | O73: 0 | P73: =(N73-O73)*F73 -> 0 | Q73: 0.865 | R73: 0.865 | S73: =(R73-Q73)*(G73-23*F73) -> 0 | T73: 0.86 | U73: 0.86 | V73: =(T73-U73)*G73 -> 0 | W73: 0 | X73: =-W73 -> 0 | Y73: =J73-M73-P73-S73-V73-X73 -> -0.88 | Z73: =IF(OR(ABS(M73)>0.5,ABS(P73)>0.5,ABS(S73)>0.5,ABS(V73)>0.5,ABS(X73)>0.5),"是","")
A74: 李涛 | B74: 3 | C74: 苏NER821 | D74: #56 | E74: 配票 | F74: 35.72 | G74: 86442.4 | H74: 615.0266 | I74: 614.5626 | J74: =I74-H74 -> -0.464 | K74: 25 | L74: 25 | M74: =(L74-K74)*F74 -> 0 | N74: 0 | O74: 0 | P74: =(N74-O74)*F74 -> 0 | Q74: 0.865 | R74: 0.865 | S74: =(R74-Q74)*(G74-23*F74) -> 0 | T74: 0.86 | U74: 0.86 | V74: =(T74-U74)*G74 -> 0 | W74: 0 | X74: =-W74 -> 0 | Y74: =J74-M74-P74-S74-V74-X74 -> -0.464 | Z74: =IF(OR(ABS(M74)>0.5,ABS(P74)>0.5,ABS(S74)>0.5,ABS(V74)>0.5,ABS(X74)>0.5),"是","")
A75: 李涛 | B75: 4 | C75: 皖SG1123 | D75: #58 | E75: 配票 | F75: 38.07 | G75: 91748.7 | H75: 652.97285 | I75: 653.09085 | J75: =I75-H75 -> 0.118 | K75: 25 | L75: 25 | M75: =(L75-K75)*F75 -> 0 | N75: 0 | O75: 0 | P75: =(N75-O75)*F75 -> 0 | Q75: 0.865 | R75: 0.865 | S75: =(R75-Q75)*(G75-23*F75) -> 0 | T75: 0.86 | U75: 0.86 | V75: =(T75-U75)*G75 -> 0 | W75: 0 | X75: =-W75 -> 0 | Y75: =J75-M75-P75-S75-V75-X75 -> 0.118 | Z75: =IF(OR(ABS(M75)>0.5,ABS(P75)>0.5,ABS(S75)>0.5,ABS(V75)>0.5,ABS(X75)>0.5),"是","")
A76: 李涛 | B76: 5 | C76: 皖LE9644 | D76: #59 | E76: 配票 | F76: 35.28 | G76: 68714.8 | H76: 524.4064 | I76: 523.6784 | J76: =I76-H76 -> -0.728 | K76: 25 | L76: 25 | M76: =(L76-K76)*F76 -> 0 | N76: 0 | O76: 0 | P76: =(N76-O76)*F76 -> 0 | Q76: 0.865 | R76: 0.865 | S76: =(R76-Q76)*(G76-23*F76) -> 0 | T76: 0.86 | U76: 0.86 | V76: =(T76-U76)*G76 -> 0 | W76: 0 | X76: =-W76 -> 0 | Y76: =J76-M76-P76-S76-V76-X76 -> -0.728 | Z76: =IF(OR(ABS(M76)>0.5,ABS(P76)>0.5,ABS(S76)>0.5,ABS(V76)>0.5,ABS(X76)>0.5),"是","")
A77: 邓晶焱 | B77: 2 | C77: 苏E9W908 | D77: #8 | E77: 配票 | F77: 39.16 | G77: 91242.8 | H77: 461.1338 | I77: 460.3258 | J77: =I77-H77 -> -0.808 | K77: 20 | L77: 20 | M77: =(L77-K77)*F77 -> 0 | N77: 0 | O77: 0 | P77: =(N77-O77)*F77 -> 0 | Q77: 0.865 | R77: 0.865 | S77: =(R77-Q77)*(G77-23*F77) -> 0 | T77: 0.86 | U77: 0.86 | V77: =(T77-U77)*G77 -> 0 | W77: 0 | X77: =-W77 -> 0 | Y77: =J77-M77-P77-S77-V77-X77 -> -0.808 | Z77: =IF(OR(ABS(M77)>0.5,ABS(P77)>0.5,ABS(S77)>0.5,ABS(V77)>0.5,ABS(X77)>0.5),"是","")
A78: 邓晶焱 | B78: 3 | C78: 苏NEV615 | D78: #17 | E78: 配票 | F78: 38.78 | G78: 89969.6 | H78: 454.7759 | I78: 647.8199 | J78: =I78-H78 -> 193.044 | K78: 20 | L78: 25 | M78: =(L78-K78)*F78 -> 193.9 | N78: 0 | O78: 0 | P78: =(N78-O78)*F78 -> 0 | Q78: 0.865 | R78: 0.865 | S78: =(R78-Q78)*(G78-23*F78) -> 0 | T78: 0.86 | U78: 0.86 | V78: =(T78-U78)*G78 -> 0 | W78: 0 | X78: =-W78 -> 0 | Y78: =J78-M78-P78-S78-V78-X78 -> -0.856 | Z78: =IF(OR(ABS(M78)>0.5,ABS(P78)>0.5,ABS(S78)>0.5,ABS(V78)>0.5,ABS(X78)>0.5),"是","") -> 是
A79: 邓晶焱 | B79: 4 | C79: 苏AE8896 | D79: #35 | E79: 配票 | F79: 39.96 | G79: 93186.72 | H79: 470.7086 | I79: 669.9294 | J79: =I79-H79 -> 199.2208 | K79: 20 | L79: 25 | M79: =(L79-K79)*F79 -> 199.8 | N79: 0 | O79: 0 | P79: =(N79-O79)*F79 -> 0 | Q79: 0.865 | R79: 0.865 | S79: =(R79-Q79)*(G79-23*F79) -> 0 | T79: 0.86 | U79: 0.86 | V79: =(T79-U79)*G79 -> 0 | W79: 0 | X79: =-W79 -> 0 | Y79: =J79-M79-P79-S79-V79-X79 -> -0.5792 | Z79: =IF(OR(ABS(M79)>0.5,ABS(P79)>0.5,ABS(S79)>0.5,ABS(V79)>0.5,ABS(X79)>0.5),"是","") -> 是
A80: 邓晶焱 | B80: 5 | C80: 皖F30399 | D80: #67 | E80: 配票 | F80: 39.17 | G80: 94008 | H80: 670.88285 | I80: 670.00285 | J80: =I80-H80 -> -0.88 | K80: 25 | L80: 25 | M80: =(L80-K80)*F80 -> 0 | N80: 0 | O80: 0 | P80: =(N80-O80)*F80 -> 0 | Q80: 0.865 | R80: 0.865 | S80: =(R80-Q80)*(G80-23*F80) -> 0 | T80: 0.86 | U80: 0.86 | V80: =(T80-U80)*G80 -> 0 | W80: 0 | X80: =-W80 -> 0 | Y80: =J80-M80-P80-S80-V80-X80 -> -0.88 | Z80: =IF(OR(ABS(M80)>0.5,ABS(P80)>0.5,ABS(S80)>0.5,ABS(V80)>0.5,ABS(X80)>0.5),"是","")
A81: 邓晶焱 | B81: 6 | C81: 苏ELU629 | D81: #73 | E81: 配票 | F81: 34.42 | G81: 82263.8 | H81: 587.9011 | I81: 831.44952 | J81: =I81-H81 -> 243.54842 | K81: 25 | L81: 25 | M81: =(L81-K81)*F81 -> 0 | N81: 0 | O81: 0 | P81: =(N81-O81)*F81 -> 0 | Q81: 0.865 | R81: 0.868 | S81: =(R81-Q81)*(G81-23*F81) -> 244.41642 | T81: 0.86 | U81: 0.86 | V81: =(T81-U81)*G81 -> 0 | W81: 0 | X81: =-W81 -> 0 | Y81: =J81-M81-P81-S81-V81-X81 -> -0.868 | Z81: =IF(OR(ABS(M81)>0.5,ABS(P81)>0.5,ABS(S81)>0.5,ABS(V81)>0.5,ABS(X81)>0.5),"是","") -> 是
A82: 邓晶焱 | B82: 7 | C82: 皖AK6033 | D82: #82 | E82: 配票 | F82: 41.42 | G82: 96094.4 | H82: 692.1051 | I82: 977.34632 | J82: =I82-H82 -> 285.24122 | K82: 25 | L82: 25 | M82: =(L82-K82)*F82 -> 0 | N82: 0 | O82: 0 | P82: =(N82-O82)*F82 -> 0 | Q82: 0.865 | R82: 0.868 | S82: =(R82-Q82)*(G82-23*F82) -> 285.42522 | T82: 0.86 | U82: 0.86 | V82: =(T82-U82)*G82 -> 0 | W82: 0 | X82: =-W82 -> 0 | Y82: =J82-M82-P82-S82-V82-X82 -> -0.184 | Z82: =IF(OR(ABS(M82)>0.5,ABS(P82)>0.5,ABS(S82)>0.5,ABS(V82)>0.5,ABS(X82)>0.5),"是","") -> 是
A83: 高栾凤 | B83: 2 | C83: 皖KQ1052 | D83: #27 | E83: 配票 | F83: 34.49 | G83: 80430.68 | H83: 578.60965 | I83: 578.22485 | J83: =I83-H83 -> -0.3848 | K83: 25 | L83: 25 | M83: =(L83-K83)*F83 -> 0 | N83: 0 | O83: 0 | P83: =(N83-O83)*F83 -> 0 | Q83: 0.865 | R83: 0.865 | S83: =(R83-Q83)*(G83-23*F83) -> 0 | T83: 0.86 | U83: 0.86 | V83: =(T83-U83)*G83 -> 0 | W83: 0 | X83: =-W83 -> 0 | Y83: =J83-M83-P83-S83-V83-X83 -> -0.3848 | Z83: =IF(OR(ABS(M83)>0.5,ABS(P83)>0.5,ABS(S83)>0.5,ABS(V83)>0.5,ABS(X83)>0.5),"是","")
A84: 高栾凤 | B84: 4 | C84: 苏CLK667 | D84: #77 | E84: 配票 | F84: 33.02 | G84: 76606.4 | H84: 552.1031 | I84: 779.13992 | J84: =I84-H84 -> 227.03682 | K84: 25 | L84: 25 | M84: =(L84-K84)*F84 -> 0 | N84: 0 | O84: 0 | P84: =(N84-O84)*F84 -> 0 | Q84: 0.865 | R84: 0.868 | S84: =(R84-Q84)*(G84-23*F84) -> 227.54082 | T84: 0.86 | U84: 0.86 | V84: =(T84-U84)*G84 -> 0 | W84: 0 | X84: =-W84 -> 0 | Y84: =J84-M84-P84-S84-V84-X84 -> -0.504 | Z84: =IF(OR(ABS(M84)>0.5,ABS(P84)>0.5,ABS(S84)>0.5,ABS(V84)>0.5,ABS(X84)>0.5),"是","") -> 是
...

Sheet 计算口径对照
A1: 路径 | B1: 财务表公式 | C1: 系统公式 | D1: 是否一致
A2: 配票（俊兴/益周） | B2: 欧冶=结算额−23×吨；实际付款=INT(结算额×0.86)；利润=欧冶×0.865−实际付款+量补−提成 | C2: 给客户付=结算额×(1−14%)；前端实付=(结算额−23×吨)×(1−13.5%)；利润=量补−(给客户付−前端实付)−提成−切割费 | D2: 一致（差 INT 取整、切割费）
A3: 配票（煌烽） | B3: 「林凯」表：利润=欧冶×0.868−实际付款+25×吨；「邓晶焱/高栾凤/尹鹏飞」表仍用×0.865 | C3: 前端实付按煌烽 13.2%（×0.868） | D3: 「林凯」表一致；另三张表财务公式疑似没改
A4: 反向 | B4: 实际付款=INT(结算额×0.86)；带票公司付=结算额×0.862；利润=结算额×0.862−实际付款+25×吨（不扣垫资） | C4: 反向票点 13.8%，本期垫资费 0 | D4: 一致
A5: 带票 | B5: 欧冶=结算额−23×吨；付供货厂=INT(结算额−40×吨)；利润=欧冶−付款+25×吨−15×吨（=27元/吨） | C5: 毛服务费40−垫资23−提成15+量补25=27元/吨，再减切割费 | D5: 一致（差切割费）
A6: 量补 | B6: 每行手写 20 或 25 | C6: 按钢厂结算周期累计吨位查阶梯：7/26~8/25 周期 20，8/26~9/25 周期 25 | D6: 8/26~9/05 林凯/邓晶焱的车不一致
A7: 林凯提成 | B7: 配票 9/05 前 −5×吨；带票 −15×吨 | C7: 配票 5 元/吨到 9/04，9/05 起 0；带票 15 元/吨 | D7: 规则一致；差在哪些车算林凯的
