Workbook

Sheet 总览
A1: 财务「发货记录表6」× 系统（同步后）对账
A2: 先按财务标记同步了系统（调货人/供货厂/票源/计算路径），并按你确认的规则改了系统（切割费客户承担只扣一次、王荣胜特批13.8%、林凯配票提成9/05停），再逐项对比。
A4: 步骤 | B4: 对象 | C4: 一致 | D4: 需关注 | E4: 结论
A5: ①车次对账 | B5: 财务101行 | C5: =COUNTIF(①车次对账!K2:K102,"一致*") -> 99 | D5: =COUNTA(①车次对账!K2:K102)-C5 -> 2 | E5: 99 行一一对上（9 行只是日期差 1~2 天，蓝色）。1 行是财务把两车合成一行（8/29 苏DBE075+冀A224E6）；1 行是 9/21 闫东鹏你还没录
A6: ②调货人/供货厂 | B6: 系统车次 | C6: =COUNTIF(②调货人供货厂!J2:J102,"一致") -> 93 | D6: =COUNTA(②调货人供货厂!J2:J102)-C6 -> 8 | E6: 已全部按财务同步。剩下只有名字写法“闫东鹏(财务)/闫东朋(系统)”——你告诉我哪个对，我统一改
A7: ③票源 | B7: 系统车次 | C7: =COUNTIF(③票源!H2:H102,"一致") -> 100 | D7: =COUNTA(③票源!H2:H102)-C7 -> 1 | E7: 已全部按财务同步。剩下闫东鹏 9/02 苏BXT103 财务没写票源（系统俊兴，利润两边一致）
A8: ④计算路径 | B8: 系统车次 | C8: =COUNTIF(④计算路径!H2:H102,"一致") -> 101 | D8: =COUNTA(④计算路径!H2:H102)-C8 -> 0 | E8: 全部一致
A9: ⑤计算过程 | B9: 逐车逐步 | C9: =COUNTIF(⑤计算过程对比!AI3:AI102,"<=1")-COUNTIF(⑤计算过程对比!AI3:AI102,"<-1") -> 100 | D9: =COUNTIF(⑤计算过程对比!AI3:AI102,">1")+COUNTIF(⑤计算过程对比!AI3:AI102,"<-1") -> 0 | E9: 每一步（结算额→垫资→开票额→给客户付→前端实付→个人垫资→量补→提成→利润）都对上，只剩财务 INT 取整的几毛钱（灰色）
A11: 利润总账
A12: 项目 | B12: 金额 | E12: 说明
A13: 财务利润合计（101行） | B13: =SUM(⑥路径统计!F13) -> 183767.05 | E13: 含 9/21 未录那车 840.59；财务表自己的合计公式漏了这一行
A14: 系统利润合计（101车） | B14: =SUM(⑥路径统计!G13) -> 182881.49 | E14: 同步后。同步前是 186,934.98
A15: 差额（系统−财务） | B15: =B14-B13 -> -885.55532
A16: 其中：9/21 未录一车 | B16: -840.5876 | E16: 你录入后这项消失
A17: 其中：财务 INT 取整 | B17: =B15-B16 -> -44.96772 | E17: 99 车每车差不到 1 元，可忽略
A20: 颜色说明
B21: 红：不一致（差额>1元、字段不同、系统没录）
B22: 橙：本次按财务同步改过的地方 / 合并车次
B23: 蓝：只是日期差、名字写法不同
B24: 绿：一致
B25: 灰“INT”：财务 INT 取整的几毛钱，忽略
B26: 淡橙：财务表的数
B27: 淡蓝：系统的数
A29: 其它表
A30: ⑥路径统计：按 配票/反向/带票 × 票源 统计车数、吨位、结算额、两边利润、每吨利润；下面按调货人再统计一遍
A31: ⑦各路径计算过程：三条路径各拿一车真实数据，逐步写出财务怎么算、系统怎么算、两边结果
A32: ⑧系统同步明细：这次系统里每一车改了什么、利润前后变化

Sheet ①车次对账
A1: 财务表 | B1: 行 | C1: 财务日期 | D1: 财务吨位 | E1: 财务应收金额 | F1: 系统车次 | G1: 车号 | H1: 系统结算日期 | I1: 系统吨位 | J1: 系统结算金额 | K1: 对账结果 | L1: 说明
A2: 林凯 | B2: 2 | C2: 2026-08-19 | D2: 73.58 | E2: 168498.2 | F2: #1 | G2: 苏DBB772 | H2: 2026-08-19 | I2: 73.58 | J2: 168498.2 | K2: 一致
A3: 林凯 | B3: 3 | C3: 2026-08-20 | D3: 34.8 | E3: 84564 | F3: #2 | G3: 苏DFM060 | H3: 2026-08-20 | I3: 34.8 | J3: 84564 | K3: 一致
A4: 林凯 | B4: 4 | C4: 2026-08-21 | D4: 81.16 | E4: 201276.8 | F4: #3 | G4: 苏DBB772 | H4: 2026-08-21 | I4: 81.16 | J4: 201276.8 | K4: 一致
A5: 林凯 | B5: 5 | C5: 2026-08-21 | D5: 36.36 | E5: 83264.4 | F5: #4 | G5: 皖M2A505 | H5: 2026-08-21 | I5: 36.36 | J5: 83264.4 | K5: 一致
A6: 林凯 | B6: 6 | C6: 2026-08-21 | D6: 32.94 | E6: 75432.6 | F6: #5 | G6: 苏EQB977 | H6: 2026-08-21 | I6: 32.94 | J6: 75432.6 | K6: 一致
A7: 林凯 | B7: 7 | C7: 2026-08-21 | D7: 24.41 | E7: 59023.38 | F7: #6 | G7: 苏BUK952 | H7: 2026-08-21 | I7: 24.41 | J7: 59023.38 | K7: 一致
A8: 林凯 | B8: 8 | C8: 2026-08-22 | D8: 69.5 | E8: 159155 | F8: #7 | G8: 苏DBB772 | H8: 2026-08-22 | I8: 69.5 | J8: 159155 | K8: 一致
A9: 林凯 | B9: 9 | C9: 2026-08-22 | D9: 34.24 | E9: 78409.6 | F9: #9 | G9: 苏MAK862 | H9: 2026-08-22 | I9: 34.24 | J9: 78409.6 | K9: 一致
A10: 林凯 | B10: 10 | C10: 2026-08-25 | D10: 81 | E10: 184032 | F10: #10 | G10: 苏DBE075 | H10: 2026-08-25 | I10: 81 | J10: 184032 | K10: 一致
A11: 林凯 | B11: 11 | C11: 2026-08-26 | D11: 560.39 | E11: 1344115.9 | F11: #11 | G11: 苏淮货16776 | H11: 2026-08-27 | I11: 560.39 | J11: 1344115.9 | K11: 一致(日期差) | L11: 日期差1天（船，财务是结算单日期）
A12: 林凯 | B12: 12 | C12: 2026-08-27 | D12: 40.27 | E12: 93426.4 | F12: #12 | G12: 苏NEX375 | H12: 2026-08-27 | I12: 40.27 | J12: 93426.4 | K12: 一致
A13: 林凯 | B13: 13 | C13: 2026-08-27 | D13: 34.3 | E13: 84206.5 | F13: #13 | G13: 苏DFM060 | H13: 2026-08-27 | I13: 34.3 | J13: 84206.5 | K13: 一致
A14: 林凯 | B14: 14 | C14: 2026-08-27 | D14: 32.05 | E14: 78682.75 | F14: #15 | G14: 苏BDK567 | H14: 2026-08-27 | I14: 32.05 | J14: 78682.75 | K14: 一致
A15: 林凯 | B15: 15 | C15: 2026-08-27 | D15: 28.47 | E15: 68569.64 | F15: #16 | G15: 苏BZP839 | H15: 2026-08-27 | I15: 28.47 | J15: 68569.64 | K15: 一致
A16: 林凯 | B16: 16 | C16: 2026-08-27 | D16: 48.38 | E16: 116112 | F16: #18 | G16: 苏ERS080 | H16: 2026-08-27 | I16: 48.38 | J16: 116112 | K16: 一致
A17: 林凯 | B17: 17 | C17: 2026-08-28 | D17: 81.9 | E17: 191646 | F17: #22 | G17: 苏DFB287 | H17: 2026-08-28 | I17: 81.9 | J17: 191646 | K17: 一致
A18: 林凯 | B18: 18 | C18: 2026-08-28 | D18: 18.52 | E18: 44448 | F18: #21 | G18: 苏DBX137 | H18: 2026-08-28 | I18: 18.52 | J18: 44448 | K18: 一致
A19: 林凯 | B19: 19 | C19: 2026-08-28 | D19: 38.2 | E19: 88624 | F19: #20 | G19: 苏DBE075 | H19: 2026-08-28 | I19: 38.2 | J19: 88624 | K19: 一致
A20: 林凯 | B20: 20 | C20: 2026-08-28 | D20: 55.18 | E20: 130224.8 | F20: #23 | G20: 苏DFM060 | H20: 2026-08-28 | I20: 55.18 | J20: 130224.8 | K20: 一致
A21: 林凯 | B21: 21 | C21: 2026-08-28 | D21: 63.16 | E21: 153352.48 | F21: #24 | G21: 苏DBB772 | H21: 2026-08-28 | I21: 63.16 | J21: 153352.48 | K21: 一致
A22: 林凯 | B22: 22 | C22: 2026-08-28 | D22: 27.22 | E22: 66416.8 | F22: #26 | G22: 苏BUK952 | H22: 2026-08-28 | I22: 27.22 | J22: 66416.8 | K22: 一致
A23: 林凯 | B23: 23 | C23: 2026-08-28 | D23: 34.22 | E23: 83496.8 | F23: #25 | G23: 苏BDK567 | H23: 2026-08-28 | I23: 34.22 | J23: 83496.8 | K23: 一致
... A28: 林凯 | B28: 28 | C28: 2026-08-29 | D28: 48.75 | E28: 117000 | F28: #32 | G28: 苏ERS080 | H28: 2026-08-29 | I28: 48.75 | J28: 117000 | K28: 一致
A29: 林凯 | B29: 29 | C29: 2026-08-29 | D29: 99.68 | E29: 248796.8 | F29: #33+#34 | G29: 苏DBE075 / 冀A224E6 | H29: 2026-08-29 | I29: 99.68 | J29: 248796.8 | K29: 合并 | L29: 财务一行 = 系统两车：苏DBE075 79.68吨 + 冀A224E6 20.0吨，吨位金额合计一致
A30: 林凯 | B30: 30 | C30: 2026-08-29 | D30: 66.06 | E30: 147974.4 | F30: #36 | G30: 苏DBB772 | H30: 2026-08-29 | I30: 66.06 | J30: 147974.4 | K30: 一致
A31: 林凯 | B31: 31 | C31: 2026-08-30 | D31: 67.96 | E31: 152230.4 | F31: #44 | G31: 苏DBB772 | H31: 2026-08-30 | I31: 67.96 | J31: 152230.4 | K31: 一致
A32: 林凯 | B32: 32 | C32: 2026-08-30 | D32: 46.28 | E32: 107924.96 | F32: #43 | G32: 冀A224E6 | H32: 2026-08-30 | I32: 46.28 | J32: 107924.96 | K32: 一致
A33: 林凯 | B33: 33 | C33: 2026-08-30 | D33: 83.78 | E33: 211125.6 | F33: #42 | G33: 苏DBB772 | H33: 2026-08-30 | I33: 83.78 | J33: 211125.6 | K33: 一致
A34: 林凯 | B34: 34 | C34: 2026-08-30 | D34: 43.34 | E34: 101068.88 | F34: #41 | G34: 皖SB2849 | H34: 2026-08-30 | I34: 43.34 | J34: 101068.88 | K34: 一致
A35: 林凯 | B35: 35 | C35: 2026-08-30 | D35: 78.64 | E35: 181501.12 | F35: #38 | G35: 苏DBE961 | H35: 2026-08-30 | I35: 78.64 | J35: 181501.12 | K35: 一致
A36: 林凯 | B36: 36 | C36: 2026-08-30 | D36: 83.26 | E36: 192164.08 | F36: #39 | G36: 苏DFB287 | H36: 2026-08-30 | I36: 83.26 | J36: 192164.08 | K36: 一致
A37: 林凯 | B37: 37 | C37: 2026-08-30 | D37: 81.92 | E37: 205619.2 | F37: #37 | G37: 苏DBE075 | H37: 2026-08-30 | I37: 81.92 | J37: 205619.2 | K37: 一致
A38: 林凯 | B38: 38 | C38: 2026-08-31 | D38: 25.12 | E38: 60288 | F38: #45 | G38: 苏DFM060 | H38: 2026-08-31 | I38: 25.12 | J38: 60288 | K38: 一致
A39: 林凯 | B39: 39 | C39: 2026-08-31 | D39: 29.08 | E39: 71216.92 | F39: #46 | G39: 冀A224E6 | H39: 2026-08-31 | I39: 29.08 | J39: 71216.92 | K39: 一致
A40: 林凯 | B40: 40 | C40: 2026-08-31 | D40: 56.78 | E40: 137407.6 | F40: #47 | G40: 苏DFM060 | H40: 2026-08-31 | I40: 56.78 | J40: 137407.6 | K40: 一致
A41: 林凯 | B41: 41 | C41: 2026-08-31 | D41: 80.96 | E41: 203209.6 | F41: #48 | G41: 苏DBB772 | H41: 2026-08-31 | I41: 80.96 | J41: 203209.6 | K41: 一致
... A46: 林凯 | B46: 46 | C46: 2026-09-01 | D46: 70.76 | E46: 158502.4 | F46: #53 | G46: 苏DBB772 | H46: 2026-09-01 | I46: 70.76 | J46: 158502.4 | K46: 一致
A47: 林凯 | B47: 47 | C47: 2026-09-06 | D47: 719.14 | E47: 1823625.4 | F47: #61 | G47: 皖城兴货688 | H47: 2026-09-05 | I47: 719.14 | J47: 1823625.4 | K47: 一致(日期差) | L47: 日期差1天（船，财务是结算单日期）
A48: 林凯 | B48: 48 | C48: 2026-09-08 | D48: 613.8 | E48: 1467823.1 | F48: #62 | G48: 鲁济宁货1567 | H48: 2026-09-07 | I48: 613.8 | J48: 1467823.1 | K48: 一致(日期差) | L48: 日期差1天（船，财务是结算单日期）
...

Sheet ②调货人供货厂
A1: 财务表 | B1: 行 | C1: 财务日期 | D1: 车号 | E1: 系统车次 | F1: 财务：调货人 | G1: 财务：供货厂 | H1: 系统调货人 | I1: 系统供货厂 | J1: 对比结果 | K1: 说明 | L1: 本次同步改了什么
A2: 林凯 | B2: 2 | C2: 2026-08-19 | D2: 苏DBB772 | E2: #1 | F2: 林凯 | G2: — | H2: 林凯 | I2: 林凯 | J2: 一致
A3: 林凯 | B3: 3 | C3: 2026-08-20 | D3: 苏DFM060 | E3: #2 | F3: 林凯 | G3: — | H3: 林凯 | I3: 林凯 | J3: 一致
A4: 林凯 | B4: 4 | C4: 2026-08-21 | D4: 苏DBB772 | E4: #3 | F4: 林凯 | G4: — | H4: 林凯 | I4: 林凯 | J4: 一致
A5: 林凯 | B5: 5 | C5: 2026-08-21 | D5: 皖M2A505 | E5: #4 | F5: 林凯 | G5: — | H5: 林凯 | I5: 俊兴 | J5: 一致 | L5: 调货人：（空） → 林凯
A6: 林凯 | B6: 6 | C6: 2026-08-21 | D6: 苏EQB977 | E6: #5 | F6: 林凯 | G6: — | H6: 林凯 | I6: 俊兴 | J6: 一致 | L6: 调货人：（空） → 林凯
A7: 林凯 | B7: 7 | C7: 2026-08-21 | D7: 苏BUK952 | E7: #6 | F7: 林凯 | G7: — | H7: 林凯 | I7: 林凯 | J7: 一致
A8: 林凯 | B8: 8 | C8: 2026-08-22 | D8: 苏DBB772 | E8: #7 | F8: 林凯 | G8: — | H8: 林凯 | I8: 林凯 | J8: 一致
A9: 林凯 | B9: 9 | C9: 2026-08-22 | D9: 苏MAK862 | E9: #9 | F9: 林凯 | G9: — | H9: 林凯 | I9: 俊兴 | J9: 一致 | L9: 调货人：（空） → 林凯
A10: 林凯 | B10: 10 | C10: 2026-08-25 | D10: 苏DBE075 | E10: #10 | F10: 林凯 | G10: — | H10: 林凯 | I10: 林凯 | J10: 一致
A11: 林凯 | B11: 11 | C11: 2026-08-26 | D11: 苏淮货16776 | E11: #11 | F11: 林凯 | G11: — | H11: 林凯 | I11: 俊兴 | J11: 一致 | L11: 调货人：（空） → 林凯
A12: 林凯 | B12: 12 | C12: 2026-08-27 | D12: 苏NEX375 | E12: #12 | F12: 林凯 | G12: — | H12: 林凯 | I12: 林凯 | J12: 一致
A13: 林凯 | B13: 13 | C13: 2026-08-27 | D13: 苏DFM060 | E13: #13 | F13: 林凯 | G13: — | H13: 林凯 | I13: 林凯 | J13: 一致
A14: 林凯 | B14: 14 | C14: 2026-08-27 | D14: 苏BDK567 | E14: #15 | F14: 林凯 | G14: — | H14: 林凯 | I14: 林凯 | J14: 一致
A15: 林凯 | B15: 15 | C15: 2026-08-27 | D15: 苏BZP839 | E15: #16 | F15: 林凯 | G15: — | H15: 林凯 | I15: 林凯 | J15: 一致
A16: 林凯 | B16: 16 | C16: 2026-08-27 | D16: 苏ERS080 | E16: #18 | F16: 林凯 | G16: — | H16: 林凯 | I16: 林凯 | J16: 一致
A17: 林凯 | B17: 17 | C17: 2026-08-28 | D17: 苏DFB287 | E17: #22 | F17: 林凯 | G17: — | H17: 林凯 | I17: 林凯 | J17: 一致
A18: 林凯 | B18: 18 | C18: 2026-08-28 | D18: 苏DBX137 | E18: #21 | F18: 林凯 | G18: — | H18: 林凯 | I18: 林凯 | J18: 一致
A19: 林凯 | B19: 19 | C19: 2026-08-28 | D19: 苏DBE075 | E19: #20 | F19: 林凯 | G19: — | H19: 林凯 | I19: 林凯 | J19: 一致
A20: 林凯 | B20: 20 | C20: 2026-08-28 | D20: 苏DFM060 | E20: #23 | F20: 林凯 | G20: — | H20: 林凯 | I20: 林凯 | J20: 一致
A21: 林凯 | B21: 21 | C21: 2026-08-28 | D21: 苏DBB772 | E21: #24 | F21: 林凯 | G21: — | H21: 林凯 | I21: 林凯 | J21: 一致
A22: 林凯 | B22: 22 | C22: 2026-08-28 | D22: 苏BUK952 | E22: #26 | F22: 林凯 | G22: — | H22: 林凯 | I22: 林凯 | J22: 一致
A23: 林凯 | B23: 23 | C23: 2026-08-28 | D23: 苏BDK567 | E23: #25 | F23: 林凯 | G23: — | H23: 林凯 | I23: 林凯 | J23: 一致
... A28: 林凯 | B28: 28 | C28: 2026-08-29 | D28: 苏ERS080 | E28: #32 | F28: 林凯 | G28: — | H28: 林凯 | I28: 林凯 | J28: 一致
A29: 林凯 | B29: 29 | C29: 2026-08-29 | D29: 苏DBE075 | E29: #33 | F29: 林凯 | G29: — | H29: 林凯 | I29: 林凯 | J29: 一致 | K29: ；财务这一行是两车合并
A30: 林凯 | B30: 29 | C30: 2026-08-29 | D30: 冀A224E6 | E30: #34 | F30: 林凯 | G30: — | H30: 林凯 | I30: 俊兴 | J30: 一致 | K30: ；财务这一行是两车合并 | L30: 调货人：（空） → 林凯
A31: 林凯 | B31: 30 | C31: 2026-08-29 | D31: 苏DBB772 | E31: #36 | F31: 林凯 | G31: — | H31: 林凯 | I31: 林凯 | J31: 一致
A32: 林凯 | B32: 31 | C32: 2026-08-30 | D32: 苏DBB772 | E32: #44 | F32: 林凯 | G32: — | H32: 林凯 | I32: 林凯 | J32: 一致
A33: 林凯 | B33: 32 | C33: 2026-08-30 | D33: 冀A224E6 | E33: #43 | F33: 林凯 | G33: — | H33: 林凯 | I33: 俊兴 | J33: 一致 | L33: 调货人：（空） → 林凯
A34: 林凯 | B34: 33 | C34: 2026-08-30 | D34: 苏DBB772 | E34: #42 | F34: 林凯 | G34: — | H34: 林凯 | I34: 林凯 | J34: 一致
A35: 林凯 | B35: 34 | C35: 2026-08-30 | D35: 皖SB2849 | E35: #41 | F35: 林凯 | G35: — | H35: 林凯 | I35: 林凯 | J35: 一致
A36: 林凯 | B36: 35 | C36: 2026-08-30 | D36: 苏DBE961 | E36: #38 | F36: 林凯 | G36: — | H36: 林凯 | I36: 俊兴 | J36: 一致 | L36: 调货人：（空） → 林凯
A37: 林凯 | B37: 36 | C37: 2026-08-30 | D37: 苏DFB287 | E37: #39 | F37: 林凯 | G37: — | H37: 林凯 | I37: 俊兴 | J37: 一致 | L37: 调货人：（空） → 林凯
A38: 林凯 | B38: 37 | C38: 2026-08-30 | D38: 苏DBE075 | E38: #37 | F38: 林凯 | G38: — | H38: 林凯 | I38: 林凯 | J38: 一致
A39: 林凯 | B39: 38 | C39: 2026-08-31 | D39: 苏DFM060 | E39: #45 | F39: 林凯 | G39: — | H39: 林凯 | I39: 林凯 | J39: 一致
A40: 林凯 | B40: 39 | C40: 2026-08-31 | D40: 冀A224E6 | E40: #46 | F40: 林凯 | G40: — | H40: 林凯 | I40: 林凯 | J40: 一致
A41: 林凯 | B41: 40 | C41: 2026-08-31 | D41: 苏DFM060 | E41: #47 | F41: 林凯 | G41: — | H41: 林凯 | I41: 林凯 | J41: 一致
A42: 林凯 | B42: 41 | C42: 2026-08-31 | D42: 苏DBB772 | E42: #48 | F42: 林凯 | G42: — | H42: 林凯 | I42: 林凯 | J42: 一致
A43: 林凯 | B43: 42 | C43: 2026-08-31 | D43: 苏DBB772 | E43: #49 | F43: 林凯 | G43: — | H43: 林凯 | I43: 林凯 | J43: 一致
A44: 林凯 | B44: 43 | C44: 2026-09-01 | D44: 苏ERS080 | E44: #50 | F44: 林凯 | G44: — | H44: 林凯 | I44: 林凯 | J44: 一致
...

Sheet ③票源
A1: 财务表 | B1: 行 | C1: 财务日期 | D1: 车号 | E1: 系统车次 | F1: 财务票源 | G1: 系统票源 | H1: 对比结果 | I1: 说明 | J1: 本次同步改了什么
A2: 林凯 | B2: 2 | C2: 2026-08-19 | D2: 苏DBB772 | E2: #1 | F2: 俊兴 | G2: 俊兴 | H2: 一致
A3: 林凯 | B3: 3 | C3: 2026-08-20 | D3: 苏DFM060 | E3: #2 | F3: 俊兴 | G3: 俊兴 | H3: 一致
A4: 林凯 | B4: 4 | C4: 2026-08-21 | D4: 苏DBB772 | E4: #3 | F4: 俊兴 | G4: 俊兴 | H4: 一致
A5: 林凯 | B5: 5 | C5: 2026-08-21 | D5: 皖M2A505 | E5: #4 | F5: 俊兴 | G5: 俊兴 | H5: 一致
A6: 林凯 | B6: 6 | C6: 2026-08-21 | D6: 苏EQB977 | E6: #5 | F6: 俊兴 | G6: 俊兴 | H6: 一致
A7: 林凯 | B7: 7 | C7: 2026-08-21 | D7: 苏BUK952 | E7: #6 | F7: 俊兴 | G7: 俊兴 | H7: 一致
A8: 林凯 | B8: 8 | C8: 2026-08-22 | D8: 苏DBB772 | E8: #7 | F8: 俊兴 | G8: 俊兴 | H8: 一致
A9: 林凯 | B9: 9 | C9: 2026-08-22 | D9: 苏MAK862 | E9: #9 | F9: 俊兴 | G9: 俊兴 | H9: 一致
A10: 林凯 | B10: 10 | C10: 2026-08-25 | D10: 苏DBE075 | E10: #10 | F10: 俊兴 | G10: 俊兴 | H10: 一致
A11: 林凯 | B11: 11 | C11: 2026-08-26 | D11: 苏淮货16776 | E11: #11 | F11: 俊兴 | G11: 俊兴 | H11: 一致
A12: 林凯 | B12: 12 | C12: 2026-08-27 | D12: 苏NEX375 | E12: #12 | F12: 俊兴 | G12: 俊兴 | H12: 一致
A13: 林凯 | B13: 13 | C13: 2026-08-27 | D13: 苏DFM060 | E13: #13 | F13: 俊兴 | G13: 俊兴 | H13: 一致
... A38: 林凯 | B38: 37 | C38: 2026-08-30 | D38: 苏DBE075 | E38: #37 | F38: 俊兴 | G38: 俊兴 | H38: 一致
A39: 林凯 | B39: 38 | C39: 2026-08-31 | D39: 苏DFM060 | E39: #45 | F39: 俊兴 | G39: 俊兴 | H39: 一致 | J39: 益周 → 俊兴
A40: 林凯 | B40: 39 | C40: 2026-08-31 | D40: 冀A224E6 | E40: #46 | F40: 俊兴 | G40: 俊兴 | H40: 一致 | J40: 益周 → 俊兴
A41: 林凯 | B41: 40 | C41: 2026-08-31 | D41: 苏DFM060 | E41: #47 | F41: 俊兴 | G41: 俊兴 | H41: 一致 | J41: 益周 → 俊兴
A42: 林凯 | B42: 41 | C42: 2026-08-31 | D42: 苏DBB772 | E42: #48 | F42: 俊兴 | G42: 俊兴 | H42: 一致 | J42: 益周 → 俊兴
A43: 林凯 | B43: 42 | C43: 2026-08-31 | D43: 苏DBB772 | E43: #49 | F43: 俊兴 | G43: 俊兴 | H43: 一致 | J43: 益周 → 俊兴
A44: 林凯 | B44: 43 | C44: 2026-09-01 | D44: 苏ERS080 | E44: #50 | F44: 俊兴 | G44: 俊兴 | H44: 一致 | J44: 益周 → 俊兴
A45: 林凯 | B45: 44 | C45: 2026-09-01 | D45: 苏DFM060 | E45: #51 | F45: 俊兴 | G45: 俊兴 | H45: 一致 | J45: 益周 → 俊兴
A46: 林凯 | B46: 45 | C46: 2026-09-01 | D46: 苏DBX137 | E46: #52 | F46: 俊兴 | G46: 俊兴 | H46: 一致 | J46: 益周 → 俊兴
A47: 林凯 | B47: 46 | C47: 2026-09-01 | D47: 苏DBB772 | E47: #53 | F47: 俊兴 | G47: 俊兴 | H47: 一致 | J47: 益周 → 俊兴
A48: 林凯 | B48: 47 | C48: 2026-09-06 | D48: 皖城兴货688 | E48: #61 | F48: 俊兴 | G48: 俊兴 | H48: 一致 | J48: 益周 → 俊兴
A49: 林凯 | B49: 48 | C49: 2026-09-08 | D49: 鲁济宁货1567 | E49: #62 | F49: 煌烽 | G49: 煌烽 | H49: 一致
A50: 林凯 | B50: 49 | C50: 2026-09-18 | D50: 苏DBB772 | E50: #89 | F50: 煌烽 | G50: 煌烽 | H50: 一致 | J50: （空） → 煌烽
A51: 林凯 | B51: 50 | C51: 2026-09-18 | D51: 苏NEN536 | E51: #90 | F51: 煌烽 | G51: 煌烽 | H51: 一致
A52: 林凯 | B52: 51 | C52: 2026-09-19 | D52: 苏GE2356 | E52: #95 | F52: 煌烽 | G52: 煌烽 | H52: 一致
A53: 林凯 | B53: 52 | C53: 2026-09-19 | D53: 苏NHY179 | E53: #96 | F53: 煌烽 | G53: 煌烽 | H53: 一致
A54: 林凯-鑫景通 | B54: 2 | C54: 2026-09-12 | D54: 苏DBE075 | E54: #66 | F54: 自带票 | G54: 自带票 | H54: 一致 | J54: 俊兴 → （空）
A55: 林凯-鑫景通 | B55: 3 | C55: 2026-09-15 | D55: 苏DBB772 | E55: #78 | F55: 自带票 | G55: 自带票 | H55: 一致
A56: 林凯-君盛 | B56: 2 | C56: 2026-08-27 | D56: 苏DBB772 | E56: #14 | F56: 自带票 | G56: 自带票 | H56: 一致 | J56: 俊兴 → （空）
A57: 林凯-君盛 | B57: 3 | C57: 2026-09-12 | D57: 苏DBE075 | E57: #68 | F57: 自带票 | G57: 自带票 | H57: 一致 | J57: 俊兴 → （空）
A58: 林凯-君盛 | B58: 4 | C58: 2026-09-14 | D58: 苏DBB772 | E58: #69 | F58: 自带票 | G58: 自带票 | H58: 一致 | J58: 俊兴 → （空）
A59: 林凯-君盛 | B59: 5 | C59: 2026-09-15 | D59: 苏DBE961 | E59: #79 | F59: 自带票 | G59: 自带票 | H59: 一致
A60: 林凯-君盛 | B60: 6 | C60: 2026-09-15 | D60: 苏DBE075 | E60: #74 | F60: 自带票 | G60: 自带票 | H60: 一致
A61: 林凯-君盛 | B61: 7 | C61: 2026-09-17 | D61: 苏DBB772 | E61: #87 | F61: 自带票 | G61: 自带票 | H61: 一致
A62: 林凯-君盛 | B62: 8 | C62: 2026-09-18 | D62: 苏DBE075 | E62: #91 | F62: 自带票 | G62: 自带票 | H62: 一致
A63: 林凯-君盛 | B63: 9 | C63: 2026-09-18 | D63: 苏DBB772 | E63: #92 | F63: 自带票 | G63: 自带票 | H63: 一致
A64: 林凯-君盛 | B64: 10 | C64: 2026-09-20 | D64: 苏DBB772 | E64: #98 | F64: 自带票 | G64: 自带票 | H64: 一致
...

Sheet ④计算路径
A1: 财务表 | B1: 行 | C1: 财务日期 | D1: 车号 | E1: 系统车次 | F1: 财务路径 | G1: 系统链条规则 | H1: 对比结果 | I1: 本次同步改了什么
A2: 林凯 | B2: 2 | C2: 2026-08-19 | D2: 苏DBB772 | E2: #1 | F2: 配票 | G2: 配票 | H2: 一致
A3: 林凯 | B3: 3 | C3: 2026-08-20 | D3: 苏DFM060 | E3: #2 | F3: 配票 | G3: 配票 | H3: 一致
A4: 林凯 | B4: 4 | C4: 2026-08-21 | D4: 苏DBB772 | E4: #3 | F4: 配票 | G4: 配票 | H4: 一致
A5: 林凯 | B5: 5 | C5: 2026-08-21 | D5: 皖M2A505 | E5: #4 | F5: 配票 | G5: 配票 | H5: 一致
A6: 林凯 | B6: 6 | C6: 2026-08-21 | D6: 苏EQB977 | E6: #5 | F6: 配票 | G6: 配票 | H6: 一致
A7: 林凯 | B7: 7 | C7: 2026-08-21 | D7: 苏BUK952 | E7: #6 | F7: 配票 | G7: 配票 | H7: 一致
A8: 林凯 | B8: 8 | C8: 2026-08-22 | D8: 苏DBB772 | E8: #7 | F8: 配票 | G8: 配票 | H8: 一致
A9: 林凯 | B9: 9 | C9: 2026-08-22 | D9: 苏MAK862 | E9: #9 | F9: 配票 | G9: 配票 | H9: 一致
A10: 林凯 | B10: 10 | C10: 2026-08-25 | D10: 苏DBE075 | E10: #10 | F10: 配票 | G10: 配票 | H10: 一致
A11: 林凯 | B11: 11 | C11: 2026-08-26 | D11: 苏淮货16776 | E11: #11 | F11: 配票 | G11: 配票 | H11: 一致
A12: 林凯 | B12: 12 | C12: 2026-08-27 | D12: 苏NEX375 | E12: #12 | F12: 配票 | G12: 配票 | H12: 一致
A13: 林凯 | B13: 13 | C13: 2026-08-27 | D13: 苏DFM060 | E13: #13 | F13: 配票 | G13: 配票 | H13: 一致
... A49: 林凯 | B49: 48 | C49: 2026-09-08 | D49: 鲁济宁货1567 | E49: #62 | F49: 配票 | G49: 配票 | H49: 一致
A50: 林凯 | B50: 49 | C50: 2026-09-18 | D50: 苏DBB772 | E50: #89 | F50: 配票 | G50: 配票 | H50: 一致 | I50: 直签带票 → 配票
A51: 林凯 | B51: 50 | C51: 2026-09-18 | D51: 苏NEN536 | E51: #90 | F51: 配票 | G51: 配票 | H51: 一致
A52: 林凯 | B52: 51 | C52: 2026-09-19 | D52: 苏GE2356 | E52: #95 | F52: 配票 | G52: 配票 | H52: 一致
A53: 林凯 | B53: 52 | C53: 2026-09-19 | D53: 苏NHY179 | E53: #96 | F53: 配票 | G53: 配票 | H53: 一致
A54: 林凯-鑫景通 | B54: 2 | C54: 2026-09-12 | D54: 苏DBE075 | E54: #66 | F54: 带票 | G54: 直签带票 | H54: 一致 | I54: 户头通道 → 直签带票
A55: 林凯-鑫景通 | B55: 3 | C55: 2026-09-15 | D55: 苏DBB772 | E55: #78 | F55: 带票 | G55: 直签带票 | H55: 一致
A56: 林凯-君盛 | B56: 2 | C56: 2026-08-27 | D56: 苏DBB772 | E56: #14 | F56: 带票 | G56: 直签带票 | H56: 一致 | I56: 配票 → 直签带票
A57: 林凯-君盛 | B57: 3 | C57: 2026-09-12 | D57: 苏DBE075 | E57: #68 | F57: 带票 | G57: 直签带票 | H57: 一致 | I57: 户头通道 → 直签带票
A58: 林凯-君盛 | B58: 4 | C58: 2026-09-14 | D58: 苏DBB772 | E58: #69 | F58: 带票 | G58: 直签带票 | H58: 一致 | I58: 配票 → 直签带票
A59: 林凯-君盛 | B59: 5 | C59: 2026-09-15 | D59: 苏DBE961 | E59: #79 | F59: 带票 | G59: 直签带票 | H59: 一致
A60: 林凯-君盛 | B60: 6 | C60: 2026-09-15 | D60: 苏DBE075 | E60: #74 | F60: 带票 | G60: 直签带票 | H60: 一致
A61: 林凯-君盛 | B61: 7 | C61: 2026-09-17 | D61: 苏DBB772 | E61: #87 | F61: 带票 | G61: 直签带票 | H61: 一致
A62: 林凯-君盛 | B62: 8 | C62: 2026-09-18 | D62: 苏DBE075 | E62: #91 | F62: 带票 | G62: 直签带票 | H62: 一致
A63: 林凯-君盛 | B63: 9 | C63: 2026-09-18 | D63: 苏DBB772 | E63: #92 | F63: 带票 | G63: 直签带票 | H63: 一致
A64: 林凯-君盛 | B64: 10 | C64: 2026-09-20 | D64: 苏DBB772 | E64: #98 | F64: 带票 | G64: 直签带票 | H64: 一致
A65: 林凯-君盛 | B65: 11 | C65: 2026-09-20 | D65: 苏DBE075 | E65: #99 | F65: 带票 | G65: 直签带票 | H65: 一致
A66: 林凯-力拓 | B66: 2 | C66: 2026-09-10 | D66: 苏DBE075 | E66: #63 | F66: 带票 | G66: 直签带票 | H66: 一致 | I66: 户头通道 → 直签带票
A67: 林凯-力拓 | B67: 3 | C67: 2026-09-11 | D67: 苏DBB772 | E67: #64 | F67: 带票 | G67: 直签带票 | H67: 一致 | I67: 户头通道 → 直签带票
A68: 林凯-力拓 | B68: 4 | C68: 2026-09-11 | D68: 苏DBE961 | E68: #65 | F68: 带票 | G68: 直签带票 | H68: 一致 | I68: 户头通道 → 直签带票
A69: 林凯-力拓 | B69: 5 | C69: 2026-09-14 | D69: 苏DBE961 | E69: #70 | F69: 带票 | G69: 直签带票 | H69: 一致 | I69: 户头通道 → 直签带票
A70: 林凯-力拓 | B70: 6 | C70: 2026-09-17 | D70: 苏DBE075 | E70: #86 | F70: 带票 | G70: 直签带票 | H70: 一致
A71: 林凯-力拓 | B71: 7 | C71: 2026-09-17 | D71: 苏DBE075 | E71: #83 | F71: 带票 | G71: 直签带票 | H71: 一致
A72: 林凯-兴德 | B72: 2 | C72: 2026-09-19 | D72: 皖SG1498 | E72: #97 | F72: 带票 | G72: 直签带票 | H72: 一致
A73: 林凯-兴德 | B73: 3 | C73: 2026-09-20 | D73: 苏BYR535 | E73: #100 | F73: 带票 | G73: 直签带票 | H73: 一致
A74: 林凯-兴德 | B74: 4 | C74: 2026-09-20 | D74: 冀A224E6 | E74: #101 | F74: 带票 | G74: 直签带票 | H74: 一致
A75: 林凯-兴德 | B75: 5 | C75: 2026-09-20 | D75: 苏DBB772 | E75: #102 | F75: 带票 | G75: 直签带票 | H75: 一致
...

Sheet ⑤计算过程对比
A1: 逐车把计算过程拆开对比：左边橙底=财务表，右边蓝底=系统。配票/反向：结算额 → 垫资费 → 前端开票额(欧冶) → 给客户付(实际付款) → 前端实付(带票公司付) → 个人垫资 → 量补、提成 → 利润。带票：结算额 → 垫资 → 欧冶 → 付供货厂 → 毛服务费(40/吨) → 量补、提成 → 利润。差额>1元标红；0.01~1元标灰“INT”(财务实际付款用了 INT 向下取整，可忽略)。
A2: 财务表 | B2: 行 | C2: 车号 | D2: 系统车次 | E2: 路径 | F2: 票源 | G2: 吨位 | H2: 点位(财务→系统) | I2: 结算额 财务 | J2: 结算额 系统 | K2: 差 | L2: 垫资费 财务 | M2: 垫资费 系统 | N2: 差 | O2: 前端开票额 (欧冶) 财务 | P2: 前端开票额 (欧冶) 系统 | Q2: 差 | R2: 给客户付/ 付供货厂 财务 | S2: 给客户付/ 付供货厂 系统 | T2: 差 | U2: 前端实付/ 毛服务费 财务 | V2: 前端实付/ 毛服务费 系统 | W2: 差 | X2: 个人垫资 财务 | Y2: 个人垫资 系统 | Z2: 差 | AA2: 量补 财务 | AB2: 量补 系统 | AC2: 差 | AD2: 提成 财务 | AE2: 提成 系统 | AF2: 差 | AG2: 利润 财务 | AH2: 利润 系统 | AI2: 差 | AJ2: 说明
A3: 林凯 | B3: 2 | C3: 苏DBB772 | D3: #1 | E3: 配票 | F3: 俊兴 | G3: 73.58 | H3: 给客户 ×0.860→×0.860；实付 ×0.865→×0.865 | I3: 168498.2 | J3: 168498.2 | K3: =J3-I3 -> 0 | L3: 1692.34 | M3: 1692.34 | N3: =M3-L3 -> 0 | O3: 166805.86 | P3: 166805.86 | Q3: =P3-O3 -> 0 | R3: 144908 | S3: 144908.45 | T3: =S3-R3 -> 0.452 | U3: 144287.07 | V3: 144287.07 | W3: =V3-U3 -> 0 | X3: 620.9311 | Y3: 621.3831 | Z3: =Y3-X3 -> 0.452 | AA3: 1471.6 | AB3: 1471.6 | AC3: =AB3-AA3 -> 0 | AD3: 367.9 | AE3: 367.9 | AF3: =AE3-AD3 -> 0 | AG3: 482.7689 | AH3: 482.3169 | AI3: =AH3-AG3 -> -0.452
A4: 林凯 | B4: 3 | C4: 苏DFM060 | D4: #2 | E4: 配票 | F4: 俊兴 | G4: 34.8 | H4: 给客户 ×0.860→×0.860；实付 ×0.865→×0.865 | I4: 84564 | J4: 84564 | K4: =J4-I4 -> 0 | L4: 800.4 | M4: 800.4 | N4: =M4-L4 -> 0 | O4: 83763.6 | P4: 83763.6 | Q4: =P4-O4 -> 0 | R4: 72725 | S4: 72725.04 | T4: =S4-R4 -> 0.04 | U4: 72455.514 | V4: 72455.514 | W4: =V4-U4 -> 0 | X4: 269.486 | Y4: 269.526 | Z4: =Y4-X4 -> 0.04 | AA4: 696 | AB4: 696 | AC4: =AB4-AA4 -> 0 | AD4: 174 | AE4: 174 | AF4: =AE4-AD4 -> 0 | AG4: 252.514 | AH4: 252.474 | AI4: =AH4-AG4 -> -0.04
A5: 林凯 | B5: 4 | C5: 苏DBB772 | D5: #3 | E5: 配票 | F5: 俊兴 | G5: 81.16 | H5: 给客户 ×0.860→×0.860；实付 ×0.865→×0.865 | I5: 201276.8 | J5: 201276.8 | K5: =J5-I5 -> 0 | L5: 1866.68 | M5: 1866.68 | N5: =M5-L5 -> 0 | O5: 199410.12 | P5: 199410.12 | Q5: =P5-O5 -> 0 | R5: 173099 | S5: 173098.05 | T5: =S5-R5 -> -0.952 | U5: 172489.75 | V5: 172489.75 | W5: =V5-U5 -> 0 | X5: 609.2462 | Y5: 608.2942 | Z5: =Y5-X5 -> -0.952 | AA5: 1623.2 | AB5: 1623.2 | AC5: =AB5-AA5 -> 0 | AD5: 405.8 | AE5: 405.8 | AF5: =AE5-AD5 -> 0 | AG5: 608.1538 | AH5: 609.1058 | AI5: =AH5-AG5 -> 0.952
A6: 林凯 | B6: 5 | C6: 皖M2A505 | D6: #4 | E6: 配票 | F6: 俊兴 | G6: 36.36 | H6: 给客户 ×0.860→×0.860；实付 ×0.865→×0.865 | I6: 83264.4 | J6: 83264.4 | K6: =J6-I6 -> 0 | L6: 836.28 | M6: 836.28 | N6: =M6-L6 -> 0 | O6: 82428.12 | P6: 82428.12 | Q6: =P6-O6 -> 0 | R6: 71607 | S6: 71607.384 | T6: =S6-R6 -> 0.384 | U6: 71300.324 | V6: 71300.324 | W6: =V6-U6 -> 0 | X6: 306.6762 | Y6: 307.0602 | Z6: =Y6-X6 -> 0.384 | AA6: 727.2 | AB6: 727.2 | AC6: =AB6-AA6 -> 0 | AD6: 181.8 | AE6: 181.8 | AF6: =AE6-AD6 -> 0 | AG6: 238.7238 | AH6: 238.3398 | AI6: =AH6-AG6 -> -0.384
A7: 林凯 | B7: 6 | C7: 苏EQB977 | D7: #5 | E7: 配票 | F7: 俊兴 | G7: 32.94 | H7: 给客户 ×0.860→×0.860；实付 ×0.865→×0.865 | I7: 75432.6 | J7: 75432.6 | K7: =J7-I7 -> 0 | L7: 757.62 | M7: 757.62 | N7: =M7-L7 -> 0 | O7: 74674.98 | P7: 74674.98 | Q7: =P7-O7 -> 0 | R7: 64872 | S7: 64872.036 | T7: =S7-R7 -> 0.036 | U7: 64593.858 | V7: 64593.858 | W7: =V7-U7 -> 0 | X7: 278.1423 | Y7: 278.1783 | Z7: =Y7-X7 -> 0.036 | AA7: 658.8 | AB7: 658.8 | AC7: =AB7-AA7 -> 0 | AD7: 164.7 | AE7: 164.7 | AF7: =AE7-AD7 -> 0 | AG7: 215.9577 | AH7: 215.9217 | AI7: =AH7-AG7 -> -0.036
A8: 林凯 | B8: 7 | C8: 苏BUK952 | D8: #6 | E8: 配票 | F8: 俊兴 | G8: 24.41 | H8: 给客户 ×0.860→×0.860；实付 ×0.865→×0.865 | I8: 59023.38 | J8: 59023.38 | K8: =J8-I8 -> 0 | L8: 561.43 | M8: 561.43 | N8: =M8-L8 -> 0 | O8: 58461.95 | P8: 58461.95 | Q8: =P8-O8 -> 0 | R8: 50760 | S8: 50760.107 | T8: =S8-R8 -> 0.1068 | U8: 50569.587 | V8: 50569.587 | W8: =V8-U8 -> 0 | X8: 190.41325 | Y8: 190.52005 | Z8: =Y8-X8 -> 0.1068 | AA8: 488.2 | AB8: 488.2 | AC8: =AB8-AA8 -> 0 | AD8: 122.05 | AE8: 122.05 | AF8: =AE8-AD8 -> 0 | AG8: 175.73675 | AH8: 175.62995 | AI8: =AH8-AG8 -> -0.1068
A9: 林凯 | B9: 8 | C9: 苏DBB772 | D9: #7 | E9: 配票 | F9: 俊兴 | G9: 69.5 | H9: 给客户 ×0.860→×0.860；实付 ×0.865→×0.865 | I9: 159155 | J9: 159155 | K9: =J9-I9 -> 0 | L9: 1598.5 | M9: 1598.5 | N9: =M9-L9 -> 0 | O9: 157556.5 | P9: 157556.5 | Q9: =P9-O9 -> 0 | R9: 136873 | S9: 136873.3 | T9: =S9-R9 -> 0.3 | U9: 136286.37 | V9: 136286.37 | W9: =V9-U9 -> 0 | X9: 586.6275 | Y9: 586.9275 | Z9: =Y9-X9 -> 0.3 | AA9: 1390 | AB9: 1390 | AC9: =AB9-AA9 -> 0 | AD9: 347.5 | AE9: 347.5 | AF9: =AE9-AD9 -> 0 | AG9: 455.8725 | AH9: 455.5725 | AI9: =AH9-AG9 -> -0.3
A10: 林凯 | B10: 9 | C10: 苏MAK862 | D10: #9 | E10: 配票 | F10: 俊兴 | G10: 34.24 | H10: 给客户 ×0.860→×0.860；实付 ×0.865→×0.865 | I10: 78409.6 | J10: 78409.6 | K10: =J10-I10 -> 0 | L10: 787.52 | M10: 787.52 | N10: =M10-L10 -> 0 | O10: 77622.08 | P10: 77622.08 | Q10: =P10-O10 -> 0 | R10: 67432 | S10: 67432.256 | T10: =S10-R10 -> 0.256 | U10: 67143.099 | V10: 67143.099 | W10: =V10-U10 -> 0 | X10: 288.9008 | Y10: 289.1568 | Z10: =Y10-X10 -> 0.256 | AA10: 684.8 | AB10: 684.8 | AC10: =AB10-AA10 -> 0 | AD10: 171.2 | AE10: 171.2 | AF10: =AE10-AD10 -> 0 | AG10: 224.6992 | AH10: 224.4432 | AI10: =AH10-AG10 -> -0.256
A11: 林凯 | B11: 10 | C11: 苏DBE075 | D11: #10 | E11: 配票 | F11: 俊兴 | G11: 81 | H11: 给客户 ×0.860→×0.860；实付 ×0.865→×0.865 | I11: 184032 | J11: 184032 | K11: =J11-I11 -> 0 | L11: 1863 | M11: 1863 | N11: =M11-L11 -> 0 | O11: 182169 | P11: 182169 | Q11: =P11-O11 -> 0 | R11: 158267 | S11: 158267.52 | T11: =S11-R11 -> 0.52 | U11: 157576.18 | V11: 157576.18 | W11: =V11-U11 -> 0 | X11: 690.815 | Y11: 691.335 | Z11: =Y11-X11 -> 0.52 | AA11: 1620 | AB11: 1620 | AC11: =AB11-AA11 -> 0 | AD11: 405 | AE11: 405 | AF11: =AE11-AD11 -> 0 | AG11: 524.185 | AH11: 523.665 | AI11: =AH11-AG11 -> -0.52
A12: 林凯 | B12: 11 | C12: 苏淮货16776 | D12: #11 | E12: 配票 | F12: 俊兴 | G12: 560.39 | H12: 给客户 ×0.860→×0.860；实付 ×0.865→×0.865 | I12: 1344115.9 | J12: 1344115.9 | K12: =J12-I12 -> 0 | L12: 12888.97 | M12: 12888.97 | N12: =M12-L12 -> 0 | O12: 1331226.9 | P12: 1331226.9 | Q12: =P12-O12 -> 0 | R12: 1155939 | S12: 1155939.7 | T12: =S12-R12 -> 0.6654 | U12: 1151511.3 | V12: 1151511.3 | W12: =V12-U12 -> 0 | X12: 4427.7142 | Y12: 4428.3796 | Z12: =Y12-X12 -> 0.6654 | AA12: 14009.75 | AB12: 14009.75 | AC12: =AB12-AA12 -> 0 | AD12: 2801.95 | AE12: 2801.95 | AF12: =AE12-AD12 -> 0 | AG12: 6780.0858 | AH12: 6779.4204 | AI12: =AH12-AG12 -> -0.6654
A13: 林凯 | B13: 12 | C13: 苏NEX375 | D13: #12 | E13: 配票 | F13: 俊兴 | G13: 40.27 | H13: 给客户 ×0.860→×0.860；实付 ×0.865→×0.865 | I13: 93426.4 | J13: 93426.4 | K13: =J13-I13 -> 0 | L13: 926.21 | M13: 926.21 | N13: =M13-L13 -> 0 | O13: 92500.19 | P13: 92500.19 | Q13: =P13-O13 -> 0 | R13: 80346 | S13: 80346.704 | T13: =S13-R13 -> 0.704 | U13: 80012.664 | V13: 80012.664 | W13: =V13-U13 -> 0 | X13: 333.33565 | Y13: 334.03965 | Z13: =Y13-X13 -> 0.704 | AA13: 1006.75 | AB13: 1006.75 | AC13: =AB13-AA13 -> 0 | AD13: 201.35 | AE13: 201.35 | AF13: =AE13-AD13 -> 0 | AG13: 472.06435 | AH13: 471.36035 | AI13: =AH13-AG13 -> -0.704
A14: 林凯 | B14: 13 | C14: 苏DFM060 | D14: #13 | E14: 配票 | F14: 俊兴 | G14: 34.3 | H14: 给客户 ×0.860→×0.860；实付 ×0.865→×0.865 | I14: 84206.5 | J14: 84206.5 | K14: =J14-I14 -> 0 | L14: 788.9 | M14: 788.9 | N14: =M14-L14 -> 0 | O14: 83417.6 | P14: 83417.6 | Q14: =P14-O14 -> 0 | R14: 72417 | S14: 72417.59 | T14: =S14-R14 -> 0.59 | U14: 72156.224 | V14: 72156.224 | W14: =V14-U14 -> 0 | X14: 260.776 | Y14: 261.366 | Z14: =Y14-X14 -> 0.59 | AA14: 857.5 | AB14: 857.5 | AC14: =AB14-AA14 -> 0 | AD14: 171.5 | AE14: 171.5 | AF14: =AE14-AD14 -> 0 | AG14: 425.224 | AH14: 424.634 | AI14: =AH14-AG14 -> -0.59
A15: 林凯 | B15: 14 | C15: 苏BDK567 | D15: #15 | E15: 配票 | F15: 俊兴 | G15: 32.05 | H15: 给客户 ×0.860→×0.860；实付 ×0.865→×0.865 | I15: 78682.75 | J15: 78682.75 | K15: =J15-I15 -> 0 | L15: 737.15 | M15: 737.15 | N15: =M15-L15 -> 0 | O15: 77945.6 | P15: 77945.6 | Q15: =P15-O15 -> 0 | R15: 67667 | S15: 67667.165 | T15: =S15-R15 -> 0.165 | U15: 67422.944 | V15: 67422.944 | W15: =V15-U15 -> 0 | X15: 244.056 | Y15: 244.221 | Z15: =Y15-X15 -> 0.165 | AA15: 801.25 | AB15: 801.25 | AC15: =AB15-AA15 -> 0 | AD15: 160.25 | AE15: 160.25 | AF15: =AE15-AD15 -> 0 | AG15: 396.944 | AH15: 396.779 | AI15: =AH15-AG15 -> -0.165
A16: 林凯 | B16: 15 | C16: 苏BZP839 | D16: #16 | E16: 配票 | F16: 俊兴 | G16: 28.47 | H16: 给客户 ×0.860→×0.860；实付 ×0.865→×0.865 | I16: 68569.64 | J16: 68569.64 | K16: =J16-I16 -> 0 | L16: 654.81 | M16: 654.81 | N16: =M16-L16 -> 0 | O16: 67914.83 | P16: 67914.83 | Q16: =P16-O16 -> 0 | R16: 58969 | S16: 58969.89 | T16: =S16-R16 -> 0.8904 | U16: 58746.328 | V16: 58746.328 | W16: =V16-U16 -> 0 | X16: 222.67205 | Y16: 223.56245 | Z16: =Y16-X16 -> 0.8904 | AA16: 711.75 | AB16: 711.75 | AC16: =AB16-AA16 -> 0 | AD16: 142.35 | AE16: 142.35 | AF16: =AE16-AD16 -> 0 | AG16: 346.72795 | AH16: 345.83755 | AI16: =AH16-AG16 -> -0.8904 | AJ16: 切割费100：两边结算额里都已扣，客户承担，利润不再扣（已统一）
A17: 林凯 | B17: 16 | C17: 苏ERS080 | D17: #18 | E17: 配票 | F17: 俊兴 | G17: 48.38 | H17: 给客户 ×0.860→×0.860；实付 ×0.865→×0.865 | I17: 116112 | J17: 116112 | K17: =J17-I17 -> 0 | L17: 1112.74 | M17: 1112.74 | N17: =M17-L17 -> 0 | O17: 114999.26 | P17: 114999.26 | Q17: =P17-O17 -> 0 | R17: 99856 | S17: 99856.32 | T17: =S17-R17 -> 0.32 | U17: 99474.36 | V17: 99474.36 | W17: =V17-U17 -> 0 | X17: 381.6401 | Y17: 381.9601 | Z17: =Y17-X17 -> 0.32 | AA17: 1209.5 | AB17: 1209.5 | AC17: =AB17-AA17 -> 0 | AD17: 241.9 | AE17: 241.9 | AF17: =AE17-AD17 -> 0 | AG17: 585.9599 | AH17: 585.6399 | AI17: =AH17-AG17 -> -0.32
A18: 林凯 | B18: 17 | C18: 苏DFB287 | D18: #22 | E18: 配票 | F18: 俊兴 | G18: 81.9 | H18: 给客户 ×0.860→×0.860；实付 ×0.865→×0.865 | I18: 191646 | J18: 191646 | K18: =J18-I18 -> 0 | L18: 1883.7 | M18: 1883.7 | N18: =M18-L18 -> 0 | O18: 189762.3 | P18: 189762.3 | Q18: =P18-O18 -> 0 | R18: 164815 | S18: 164815.56 | T18: =S18-R18 -> 0.56 | U18: 164144.39 | V18: 164144.39 | W18: =V18-U18 -> 0 | X18: 670.6105 | Y18: 671.1705 | Z18: =Y18-X18 -> 0.56 | AA18: 2047.5 | AB18: 2047.5 | AC18: =AB18-AA18 -> 0 | AD18: 409.5 | AE18: 409.5 | AF18: =AE18-AD18 -> 0 | AG18: 967.3895 | AH18: 966.8295 | AI18: =AH18-AG18 -> -0.56
A19: 林凯 | B19: 18 | C19: 苏DBX137 | D19: #21 | E19: 配票 | F19: 俊兴 | G19: 18.52 | H19: 给客户 ×0.860→×0.860；实付 ×0.865→×0.865 | I19: 44448 | J19: 44448 | K19: =J19-I19 -> 0 | L19: 425.96 | M19: 425.96 | N19: =M19-L19 -> 0 | O19: 44022.04 | P19: 44022.04 | Q19: =P19-O19 -> 0 | R19: 38225 | S19: 38225.28 | T19: =S19-R19 -> 0.28 | U19: 38079.065 | V19: 38079.065 | W19: =V19-U19 -> 0 | X19: 145.9354 | Y19: 146.2154 | Z19: =Y19-X19 -> 0.28 | AA19: 463 | AB19: 463 | AC19: =AB19-AA19 -> 0 | AD19: 92.6 | AE19: 92.6 | AF19: =AE19-AD19 -> 0 | AG19: 224.4646 | AH19: 224.1846 | AI19: =AH19-AG19 -> -0.28
A20: 林凯 | B20: 19 | C20: 苏DBE075 | D20: #20 | E20: 配票 | F20: 俊兴 | G20: 38.2 | H20: 给客户 ×0.860→×0.860；实付 ×0.865→×0.865 | I20: 88624 | J20: 88624 | K20: =J20-I20 -> 0 | L20: 878.6 | M20: 878.6 | N20: =M20-L20 -> 0 | O20: 87745.4 | P20: 87745.4 | Q20: =P20-O20 -> 0 | R20: 76216 | S20: 76216.64 | T20: =S20-R20 -> 0.64 | U20: 75899.771 | V20: 75899.771 | W20: =V20-U20 -> 0 | X20: 316.229 | Y20: 316.869 | Z20: =Y20-X20 -> 0.64 | AA20: 955 | AB20: 955 | AC20: =AB20-AA20 -> 0 | AD20: 191 | AE20: 191 | AF20: =AE20-AD20 -> 0 | AG20: 447.771 | AH20: 447.131 | AI20: =AH20-AG20 -> -0.64
A21: 林凯 | B21: 20 | C21: 苏DFM060 | D21: #23 | E21: 配票 | F21: 俊兴 | G21: 55.18 | H21: 给客户 ×0.860→×0.860；实付 ×0.865→×0.865 | I21: 130224.8 | J21: 130224.8 | K21: =J21-I21 -> 0 | L21: 1269.14 | M21: 1269.14 | N21: =M21-L21 -> 0 | O21: 128955.66 | P21: 128955.66 | Q21: =P21-O21 -> 0 | R21: 111993 | S21: 111993.33 | T21: =S21-R21 -> 0.328 | U21: 111546.65 | V21: 111546.65 | W21: =V21-U21 -> 0 | X21: 446.3541 | Y21: 446.6821 | Z21: =Y21-X21 -> 0.328 | AA21: 1379.5 | AB21: 1379.5 | AC21: =AB21-AA21 -> 0 | AD21: 275.9 | AE21: 275.9 | AF21: =AE21-AD21 -> 0 | AG21: 657.2459 | AH21: 656.9179 | AI21: =AH21-AG21 -> -0.328
A22: 林凯 | B22: 21 | C22: 苏DBB772 | D22: #24 | E22: 配票 | F22: 俊兴 | G22: 63.16 | H22: 给客户 ×0.860→×0.860；实付 ×0.865→×0.865 | I22: 153352.48 | J22: 153352.48 | K22: =J22-I22 -> 0 | L22: 1452.68 | M22: 1452.68 | N22: =M22-L22 -> 0 | O22: 151899.8 | P22: 151899.8 | Q22: =P22-O22 -> 0 | R22: 131883 | S22: 131883.13 | T22: =S22-R22 -> 0.1328 | U22: 131393.33 | V22: 131393.33 | W22: =V22-U22 -> 0 | X22: 489.673 | Y22: 489.8058 | Z22: =Y22-X22 -> 0.1328 | AA22: 1579 | AB22: 1579 | AC22: =AB22-AA22 -> 0 | AD22: 315.8 | AE22: 315.8 | AF22: =AE22-AD22 -> 0 | AG22: 773.527 | AH22: 773.3942 | AI22: =AH22-AG22 -> -0.1328
A23: 林凯 | B23: 22 | C23: 苏BUK952 | D23: #26 | E23: 配票 | F23: 俊兴 | G23: 27.22 | H23: 给客户 ×0.860→×0.860；实付 ×0.865→×0.865 | I23: 66416.8 | J23: 66416.8 | K23: =J23-I23 -> 0 | L23: 626.06 | M23: 626.06 | N23: =M23-L23 -> 0 | O23: 65790.74 | P23: 65790.74 | Q23: =P23-O23 -> 0 | R23: 57118 | S23: 57118.448 | T23: =S23-R23 -> 0.448 | U23: 56908.99 | V23: 56908.99 | W23: =V23-U23 -> 0 | X23: 209.0099 | Y23: 209.4579 | Z23: =Y23-X23 -> 0.448 | AA23: 680.5 | AB23: 680.5 | AC23: =AB23-AA23 -> 0 | AD23: 136.1 | AE23: 136.1 | AF23: =AE23-AD23 -> 0 | AG23: 335.3901 | AH23: 334.9421 | AI23: =AH23-AG23 -> -0.448
A24: 林凯 | B24: 23 | C24: 苏BDK567 | D24: #25 | E24: 配票 | F24: 俊兴 | G24: 34.22 | H24: 给客户 ×0.860→×0.860；实付 ×0.865→×0.865 | I24: 83496.8 | J24: 83496.8 | K24: =J24-I24 -> 0 | L24: 787.06 | M24: 787.06 | N24: =M24-L24 -> 0 | O24: 82709.74 | P24: 82709.74 | Q24: =P24-O24 -> 0 | R24: 71807 | S24: 71807.248 | T24: =S24-R24 -> 0.248 | U24: 71543.925 | V24: 71543.925 | W24: =V24-U24 -> 0 | X24: 263.0749 | Y24: 263.3229 | Z24: =Y24-X24 -> 0.248 | AA24: 855.5 | AB24: 855.5 | AC24: =AB24-AA24 -> 0 | AD24: 171.1 | AE24: 171.1 | AF24: =AE24-AD24 -> 0 | AG24: 421.3251 | AH24: 421.0771 | AI24: =AH24-AG24 -> -0.248
A25: 林凯 | B25: 24 | C25: 苏DBE075 | D25: #28 | E25: 配票 | F25: 俊兴 | G25: 67.8 | H25: 给客户 ×0.860→×0.860；实付 ×0.865→×0.865 | I25: 151872 | J25: 151872 | K25: =J25-I25 -> 0 | L25: 1559.4 | M25: 1559.4 | N25: =M25-L25 -> 0 | O25: 150312.6 | P25: 150312.6 | Q25: =P25-O25 -> 0 | R25: 130609 | S25: 130609.92 | T25: =S25-R25 -> 0.92 | U25: 130020.4 | V25: 130020.4 | W25: =V25-U25 -> 0 | X25: 588.601 | Y25: 589.521 | Z25: =Y25-X25 -> 0.92 | AA25: 1695 | AB25: 1695 | AC25: =AB25-AA25 -> 0 | AD25: 339 | AE25: 339 | AF25: =AE25-AD25 -> 0 | AG25: 767.399 | AH25: 766.479 | AI25: =AH25-AG25 -> -0.92
A26: 林凯 | B26: 25 | C26: 苏BWX568 | D26: #30 | E26: 配票 | F26: 俊兴 | G26: 32.52 | H26: 给客户 ×0.860→×0.860；实付 ×0.865→×0.865 | I26: 78048 | J26: 78048 | K26: =J26-I26 -> 0 | L26: 747.96 | M26: 747.96 | N26: =M26-L26 -> 0 | O26: 77300.04 | P26: 77300.04 | Q26: =P26-O26 -> 0 | R26: 67121 | S26: 67121.28 | T26: =S26-R26 -> 0.28 | U26: 66864.535 | V26: 66864.535 | W26: =V26-U26 -> 0 | X26: 256.4654 | Y26: 256.7454 | Z26: =Y26-X26 -> 0.28 | AA26: 813 | AB26: 813 | AC26: =AB26-AA26 -> 0 | AD26: 162.6 | AE26: 162.6 | AF26: =AE26-AD26 -> 0 | AG26: 393.9346 | AH26: 393.6546 | AI26: =AH26-AG26 -> -0.28
A27: 林凯 | B27: 26 | C27: 冀A224E6 | D27: #29 | E27: 配票 | F27: 俊兴 | G27: 29 | H27: 给客户 ×0.860→×0.860；实付 ×0.865→×0.865 | I27: 71369 | J27: 71369 | K27: =J27-I27 -> 0 | L27: 667 | M27: 667 | N27: =M27-L27 -> 0 | O27: 70702 | P27: 70702 | Q27: =P27-O27 -> 0 | R27: 61377 | S27: 61377.34 | T27: =S27-R27 -> 0.34 | U27: 61157.23 | V27: 61157.23 | W27: =V27-U27 -> 0 | X27: 219.77 | Y27: 220.11 | Z27: =Y27-X27 -> 0.34 | AA27: 725 | AB27: 725 | AC27: =AB27-AA27 -> 0 | AD27: 145 | AE27: 145 | AF27: =AE27-AD27 -> 0 | AG27: 360.23 | AH27: 359.89 | AI27: =AH27-AG27 -> -0.34
A28: 林凯 | B28: 27 | C28: 苏DBB772 | D28: #31 | E28: 配票 | F28: 俊兴 | G28: 81.36 | H28: 给客户 ×0.860→×0.860；实付 ×0.865→×0.865 | I28: 204213.6 | J28: 204213.6 | K28: =J28-I28 -> 0 | L28: 1871.28 | M28: 1871.28 | N28: =M28-L28 -> 0 | O28: 202342.32 | P28: 202342.32 | Q28: =P28-O28 -> 0 | R28: 175623 | S28: 175623.7 | T28: =S28-R28 -> 0.696 | U28: 175026.11 | V28: 175026.11 | W28: =V28-U28 -> 0 | X28: 596.8932 | Y28: 597.5892 | Z28: =Y28-X28 -> 0.696 | AA28: 2034 | AB28: 2034 | AC28: =AB28-AA28 -> 0 | AD28: 406.8 | AE28: 406.8 | AF28: =AE28-AD28 -> 0 | AG28: 1030.3068 | AH28: 1029.6108 | AI28: =AH28-AG28 -> -0.696
A29: 林凯 | B29: 28 | C29: 苏ERS080 | D29: #32 | E29: 配票 | F29: 俊兴 | G29: 48.75 | H29: 给客户 ×0.860→×0.860；实付 ×0.865→×0.865 | I29: 117000 | J29: 117000 | K29: =J29-I29 -> 0 | L29: 1121.25 | M29: 1121.25 | N29: =M29-L29 -> 0 | O29: 115878.75 | P29: 115878.75 | Q29: =P29-O29 -> 0 | R29: 100620 | S29: 100620 | T29: =S29-R29 -> 0 | U29: 100235.12 | V29: 100235.12 | W29: =V29-U29 -> 0 | X29: 384.88125 | Y29: 384.88125 | Z29: =Y29-X29 -> 0 | AA29: 1218.75 | AB29: 1218.75 | AC29: =AB29-AA29 -> 0 | AD29: 243.75 | AE29: 243.75 | AF29: =AE29-AD29 -> 0 | AG29: 590.11875 | AH29: 590.11875 | AI29: =AH29-AG29 -> 0
A30: 林凯 | B30: 29 | C30: 苏DBE075 / 冀A224E6 | D30: #33+#34 | E30: 配票 | F30: 俊兴 | G30: 99.68 | H30: 给客户 ×0.860→×0.860；实付 ×0.865→×0.865 | I30: 248796.8 | J30: 248796.8 | K30: =J30-I30 -> 0 | L30: 2292.64 | M30: 2292.64 | N30: =M30-L30 -> 0 | O30: 246504.16 | P30: 246504.16 | Q30: =P30-O30 -> 0 | R30: 213965 | S30: 213965.25 | T30: =S30-R30 -> 0.248 | U30: 213226.1 | V30: 213226.1 | W30: =V30-U30 -> 0 | X30: 738.9016 | Y30: 739.1496 | Z30: =Y30-X30 -> 0.248 | AA30: 2492 | AB30: 2492 | AC30: =AB30-AA30 -> 0 | AD30: 498.4 | AE30: 498.4 | AF30: =AE30-AD30 -> 0 | AG30: 1254.6984 | AH30: 1254.4504 | AI30: =AH30-AG30 -> -0.248 | AJ30: 财务一行=系统两车，系统数为两车相加
A31: 林凯 | B31: 30 | C31: 苏DBB772 | D31: #36 | E31: 配票 | F31: 俊兴 | G31: 66.06 | H31: 给客户 ×0.860→×0.860；实付 ×0.865→×0.865 | I31: 147974.4 | J31: 147974.4 | K31: =J31-I31 -> 0 | L31: 1519.38 | M31: 1519.38 | N31: =M31-L31 -> 0 | O31: 146455.02 | P31: 146455.02 | Q31: =P31-O31 -> 0 | R31: 127257 | S31: 127257.98 | T31: =S31-R31 -> 0.984 | U31: 126683.59 | V31: 126683.59 | W31: =V31-U31 -> 0 | X31: 573.4077 | Y31: 574.3917 | Z31: =Y31-X31 -> 0.984 | AA31: 1651.5 | AB31: 1651.5 | AC31: =AB31-AA31 -> 0 | AD31: 330.3 | AE31: 330.3 | AF31: =AE31-AD31 -> 0 | AG31: 747.7923 | AH31: 746.8083 | AI31: =AH31-AG31 -> -0.984
A32: 林凯 | B32: 31 | C32: 苏DBB772 | D32: #44 | E32: 配票 | F32: 俊兴 | G32: 67.96 | H32: 给客户 ×0.860→×0.860；实付 ×0.865→×0.865 | I32: 152230.4 | J32: 152230.4 | K32: =J32-I32 -> 0 | L32: 1563.08 | M32: 1563.08 | N32: =M32-L32 -> 0 | O32: 150667.32 | P32: 150667.32 | Q32: =P32-O32 -> 0 | R32: 130918 | S32: 130918.14 | T32: =S32-R32 -> 0.144 | U32: 130327.23 | V32: 130327.23 | W32: =V32-U32 -> 0 | X32: 590.7682 | Y32: 590.9122 | Z32: =Y32-X32 -> 0.144 | AA32: 1699 | AB32: 1699 | AC32: =AB32-AA32 -> 0 | AD32: 339.8 | AE32: 339.8 | AF32: =AE32-AD32 -> 0 | AG32: 768.4318 | AH32: 768.2878 | AI32: =AH32-AG32 -> -0.144
A33: 林凯 | B33: 32 | C33: 冀A224E6 | D33: #43 | E33: 配票 | F33: 俊兴 | G33: 46.28 | H33: 给客户 ×0.860→×0.860；实付 ×0.865→×0.865 | I33: 107924.96 | J33: 107924.96 | K33: =J33-I33 -> 0 | L33: 1064.44 | M33: 1064.44 | N33: =M33-L33 -> 0 | O33: 106860.52 | P33: 106860.52 | Q33: =P33-O33 -> 0 | R33: 92815 | S33: 92815.466 | T33: =S33-R33 -> 0.4656 | U33: 92434.35 | V33: 92434.35 | W33: =V33-U33 -> 0 | X33: 380.6502 | Y33: 381.1158 | Z33: =Y33-X33 -> 0.4656 | AA33: 1157 | AB33: 1157 | AC33: =AB33-AA33 -> 0 | AD33: 231.4 | AE33: 231.4 | AF33: =AE33-AD33 -> 0 | AG33: 544.9498 | AH33: 544.4842 | AI33: =AH33-AG33 -> -0.4656
A34: 林凯 | B34: 33 | C34: 苏DBB772 | D34: #42 | E34: 配票 | F34: 俊兴 | G34: 83.78 | H34: 给客户 ×0.860→×0.860；实付 ×0.865→×0.865 | I34: 211125.6 | J34: 211125.6 | K34: =J34-I34 -> 0 | L34: 1926.94 | M34: 1926.94 | N34: =M34-L34 -> 0 | O34: 209198.66 | P34: 209198.66 | Q34: =P34-O34 -> 0 | R34: 181568 | S34: 181568.02 | T34: =S34-R34 -> 0.016 | U34: 180956.84 | V34: 180956.84 | W34: =V34-U34 -> 0 | X34: 611.1591 | Y34: 611.1751 | Z34: =Y34-X34 -> 0.016 | AA34: 2094.5 | AB34: 2094.5 | AC34: =AB34-AA34 -> 0 | AD34: 418.9 | AE34: 418.9 | AF34: =AE34-AD34 -> 0 | AG34: 1064.4409 | AH34: 1064.4249 | AI34: =AH34-AG34 -> -0.016
A35: 林凯 | B35: 34 | C35: 皖SB2849 | D35: #41 | E35: 配票 | F35: 俊兴 | G35: 43.34 | H35: 给客户 ×0.860→×0.860；实付 ×0.865→×0.865 | I35: 101068.88 | J35: 101068.88 | K35: =J35-I35 -> 0 | L35: 996.82 | M35: 996.82 | N35: =M35-L35 -> 0 | O35: 100072.06 | P35: 100072.06 | Q35: =P35-O35 -> 0 | R35: 86919 | S35: 86919.237 | T35: =S35-R35 -> 0.2368 | U35: 86562.332 | V35: 86562.332 | W35: =V35-U35 -> 0 | X35: 356.6681 | Y35: 356.9049 | Z35: =Y35-X35 -> 0.2368 | AA35: 1083.5 | AB35: 1083.5 | AC35: =AB35-AA35 -> 0 | AD35: 216.7 | AE35: 216.7 | AF35: =AE35-AD35 -> 0 | AG35: 510.1319 | AH35: 509.8951 | AI35: =AH35-AG35 -> -0.2368
A36: 林凯 | B36: 35 | C36: 苏DBE961 | D36: #38 | E36: 配票 | F36: 俊兴 | G36: 78.64 | H36: 给客户 ×0.860→×0.860；实付 ×0.865→×0.865 | I36: 181501.12 | J36: 181501.12 | K36: =J36-I36 -> 0 | L36: 1808.72 | M36: 1808.72 | N36: =M36-L36 -> 0 | O36: 179692.4 | P36: 179692.4 | Q36: =P36-O36 -> 0 | R36: 156090 | S36: 156090.96 | T36: =S36-R36 -> 0.9632 | U36: 155433.93 | V36: 155433.93 | W36: =V36-U36 -> 0 | X36: 656.074 | Y36: 657.0372 | Z36: =Y36-X36 -> 0.9632 | AA36: 1966 | AB36: 1966 | AC36: =AB36-AA36 -> 0 | AD36: 393.2 | AE36: 393.2 | AF36: =AE36-AD36 -> 0 | AG36: 916.726 | AH36: 915.7628 | AI36: =AH36-AG36 -> -0.9632
A37: 林凯 | B37: 36 | C37: 苏DFB287 | D37: #39 | E37: 配票 | F37: 俊兴 | G37: 83.26 | H37: 给客户 ×0.860→×0.860；实付 ×0.865→×0.865 | I37: 192164.08 | J37: 192164.08 | K37: =J37-I37 -> 0 | L37: 1914.98 | M37: 1914.98 | N37: =M37-L37 -> 0 | O37: 190249.1 | P37: 190249.1 | Q37: =P37-O37 -> 0 | R37: 165261 | S37: 165261.11 | T37: =S37-R37 -> 0.1088 | U37: 164565.47 | V37: 164565.47 | W37: =V37-U37 -> 0 | X37: 695.5285 | Y37: 695.6373 | Z37: =Y37-X37 -> 0.1088 | AA37: 2081.5 | AB37: 2081.5 | AC37: =AB37-AA37 -> 0 | AD37: 416.3 | AE37: 416.3 | AF37: =AE37-AD37 -> 0 | AG37: 969.6715 | AH37: 969.5627 | AI37: =AH37-AG37 -> -0.1088
A38: 林凯 | B38: 37 | C38: 苏DBE075 | D38: #37 | E38: 配票 | F38: 俊兴 | G38: 81.92 | H38: 给客户 ×0.860→×0.860；实付 ×0.865→×0.865 | I38: 205619.2 | J38: 205619.2 | K38: =J38-I38 -> 0 | L38: 1884.16 | M38: 1884.16 | N38: =M38-L38 -> 0 | O38: 203735.04 | P38: 203735.04 | Q38: =P38-O38 -> 0 | R38: 176832 | S38: 176832.51 | T38: =S38-R38 -> 0.512 | U38: 176230.81 | V38: 176230.81 | W38: =V38-U38 -> 0 | X38: 601.1904 | Y38: 601.7024 | Z38: =Y38-X38 -> 0.512 | AA38: 2048 | AB38: 2048 | AC38: =AB38-AA38 -> 0 | AD38: 409.6 | AE38: 409.6 | AF38: =AE38-AD38 -> 0 | AG38: 1037.2096 | AH38: 1036.6976 | AI38: =AH38-AG38 -> -0.512
A39: 林凯 | B39: 38 | C39: 苏DFM060 | D39: #45 | E39: 配票 | F39: 俊兴 | G39: 25.12 | H39: 给客户 ×0.860→×0.860；实付 ×0.865→×0.865 | I39: 60288 | J39: 60288 | K39: =J39-I39 -> 0 | L39: 577.76 | M39: 577.76 | N39: =M39-L39 -> 0 | O39: 59710.24 | P39: 59710.24 | Q39: =P39-O39 -> 0 | R39: 51847 | S39: 51847.68 | T39: =S39-R39 -> 0.68 | U39: 51649.358 | V39: 51649.358 | W39: =V39-U39 -> 0 | X39: 197.6424 | Y39: 198.3224 | Z39: =Y39-X39 -> 0.68 | AA39: 628 | AB39: 628 | AC39: =AB39-AA39 -> 0 | AD39: 125.6 | AE39: 125.6 | AF39: =AE39-AD39 -> 0 | AG39: 304.7576 | AH39: 304.0776 | AI39: =AH39-AG39 -> -0.68
A40: 林凯 | B40: 39 | C40: 冀A224E6 | D40: #46 | E40: 配票 | F40: 俊兴 | G40: 29.08 | H40: 给客户 ×0.860→×0.860；实付 ×0.865→×0.865 | I40: 71216.92 | J40: 71216.92 | K40: =J40-I40 -> 0 | L40: 668.84 | M40: 668.84 | N40: =M40-L40 -> 0 | O40: 70548.08 | P40: 70548.08 | Q40: =P40-O40 -> 0 | R40: 61246 | S40: 61246.551 | T40: =S40-R40 -> 0.5512 | U40: 61024.089 | V40: 61024.089 | W40: =V40-U40 -> 0 | X40: 221.9108 | Y40: 222.462 | Z40: =Y40-X40 -> 0.5512 | AA40: 727 | AB40: 727 | AC40: =AB40-AA40 -> 0 | AD40: 145.4 | AE40: 145.4 | AF40: =AE40-AD40 -> 0 | AG40: 359.6892 | AH40: 359.138 | AI40: =AH40-AG40 -> -0.5512
...

Sheet ⑥路径统计
A1: 按计算路径统计（同步后；财务利润按财务表，系统利润按系统；9/21 未录那车只在财务列）
A3: 路径 | B3: 票源 | C3: 车数 | D3: 吨位 | E3: 结算额 | F3: 财务利润 | G3: 系统利润 | H3: 差额(系统−财务) | I3: 每吨利润(系统) | J3: 说明
A4: 配票 | B4: 俊兴 | C4: 57 | D4: 4483.17 | E4: 10791816 | F4: 57312.59 | G4: 57289.742 | H4: =G4-F4 -> -22.84792 | I4: =IF(D4=0,"",G4/D4) -> 12.778847
A5: 配票 | B5: 煌烽 | C5: 13 | D5: 2180.5 | E5: 5275457.6 | F5: 53192.203 | G5: 53184.659 | H5: =G5-F5 -> -7.5446 | I5: =IF(D5=0,"",G5/D5) -> 24.391038
A6: 配票 | B6: 益周 | C6: 1 | D6: 481.77 | E6: 1181813.6 | F6: 8369.1999 | G6: 8368.5038 | H6: =G6-F6 -> -0.696 | I6: =IF(D6=0,"",G6/D6) -> 17.37033
A7: 配票 小计 | C7: =SUM(C4:C6) -> 71 | D7: =SUM(D4:D6) -> 7145.44 | E7: =SUM(E4:E6) -> 17249087 | F7: =SUM(F4:F6) -> 118873.99 | G7: =SUM(G4:G6) -> 118842.91 | H7: =G7-F7 -> -31.08852 | I7: =IF(D7=0,"",G7/D7) -> 16.631993 | J7: 企业票源差价模型：利润 = 量补 − (给客户付 − 前端实付) − 提成
A8: 反向 | B8: 反向-尹鹏飞 | C8: 1 | D8: 646.85 | E8: 1563945.8 | F8: 19299.564 | G8: 19299.142 | H8: =G8-F8 -> -0.4224 | I8: =IF(D8=0,"",G8/D8) -> 29.835575
A9: 反向 | B9: 反向-闫东朋 | C9: 7 | D9: 412.4 | E9: 1037538.9 | F9: 13230.102 | G9: 12385.078 | H9: =G9-F9 -> -845.0244 | I9: =IF(D9=0,"",G9/D9) -> 30.031711 | J9: 含 9/21 未录一车（财务利润 840.59）
A10: 反向 小计 | C10: =SUM(C8:C9) -> 8 | D10: =SUM(D8:D9) -> 1059.25 | E10: =SUM(E8:E9) -> 2601484.7 | F10: =SUM(F8:F9) -> 32529.666 | G10: =SUM(G8:G9) -> 31684.219 | H10: =G10-F10 -> -845.4468 | I10: =IF(D10=0,"",G10/D10) -> 29.911937 | J10: 反向个人开票：不扣垫资，前端实付=结算额×(1−13.8%)
A11: 带票 | B11: 自带票 | C11: 22 | D11: 1198.31 | E11: 2895945.4 | F11: 32363.39 | G11: 32354.37 | H11: =G11-F11 -> -9.02 | I11: =IF(D11=0,"",G11/D11) -> 27
A12: 带票 小计 | C12: =SUM(C11:C11) -> 22 | D12: =SUM(D11:D11) -> 1198.31 | E12: =SUM(E11:E11) -> 2895945.4 | F12: =SUM(F11:F11) -> 32363.39 | G12: =SUM(G11:G11) -> 32354.37 | H12: =G12-F12 -> -9.02 | I12: =IF(D12=0,"",G12/D12) -> 27 | J12: 供货厂自带票服务费：40 − 垫资23 − 提成15 + 量补25 = 27元/吨
A13: 总计 | C13: =C7+C10+C12 -> 101 | D13: =D7+D10+D12 -> 9403 | E13: =E7+E10+E12 -> 22746517 | F13: =F7+F10+F12 -> 183767.05 | G13: =G7+G10+G12 -> 182881.49 | H13: =G13-F13 -> -885.55532 | I13: =IF(D13=0,"",G13/D13) -> 19.449271 | J13: 差额 = 9/21 未录一车(−840.59) + 财务 INT 取整(约 −45)
A15: 按调货人统计（同步后，系统）
A16: 调货人 | B16: 路径 | C16: 车数 | D16: 吨位 | E16: 结算额 | F16: 财务利润 | G16: 系统利润 | H16: 差额 | I16: 每吨利润(系统) | J16: 提成(系统)
A17: 林凯 | B17: 带票 | C17: 22 | D17: 1198.31 | E17: 2895945.4 | F17: 32363.39 | G17: 32354.37 | H17: =G17-F17 -> -9.02 | I17: =IF(D17=0,"",G17/D17) -> 27 | J17: 17974.65
A18: 林凯 | B18: 配票 | C18: 52 | D18: 4414.05 | E18: 10615227 | F18: 64478.697 | G18: 64458.563 | H18: =G18-F18 -> -20.134 | I18: =IF(D18=0,"",G18/D18) -> 14.603043 | J18: 14477.65
A19: （无） | B19: 反向 | C19: 1 | D19: 646.85 | E19: 1563945.8 | F19: 19299.564 | G19: 19299.142 | H19: =G19-F19 -> -0.4224 | I19: =IF(D19=0,"",G19/D19) -> 29.835575 | J19: 0
A20: （无） | B20: 配票 | C20: 3 | D20: 1631.22 | E20: 4008273.8 | F20: 36770.31 | G20: 36768.816 | H20: =G20-F20 -> -1.4938 | I20: =IF(D20=0,"",G20/D20) -> 22.540685 | J20: 0
A21: 王荣胜 | B21: 配票 | C21: 1 | D21: 518.48 | E21: 1271259 | F21: 6460.8408 | G21: 6460.6173 | H21: =G21-F21 -> -0.22352 | I21: =IF(D21=0,"",G21/D21) -> 12.460688 | J21: 0
A22: 闫东朋 | B22: 反向 | C22: 7 | D22: 412.4 | E22: 1037538.9 | F22: 12389.515 | G22: 12385.078 | H22: =G22-F22 -> -4.4368 | I22: =IF(D22=0,"",G22/D22) -> 30.031711 | J22: 0
A23: 闫东朋 | B23: 配票 | C23: 1 | D23: 56.14 | E23: 132939.52 | F23: 952.2795 | G23: 951.2923 | H23: =G23-F23 -> -0.9872 | I23: =IF(D23=0,"",G23/D23) -> 16.945 | J23: 0
A24: 邓晶焱 | B24: 配票 | C24: 6 | D24: 232.91 | E24: 546765.32 | F24: 4540.3703 | G24: 4536.1951 | H24: =G24-F24 -> -4.1752 | I24: =IF(D24=0,"",G24/D24) -> 19.476171 | J24: 0
A25: 李涛 | B25: 配票 | C25: 4 | D25: 141.49 | E25: 324713.9 | F25: 2347.8299 | G25: 2345.8759 | H25: =G25-F25 -> -1.954 | I25: =IF(D25=0,"",G25/D25) -> 16.5798 | J25: 0
A26: 高栾凤 | B26: 配票 | C26: 3 | D26: 112.03 | E26: 260323.48 | F26: 2409.0515 | G26: 2407.8587 | H26: =G26-F26 -> -1.1928 | I26: =IF(D26=0,"",G26/D26) -> 21.492981 | J26: 0
A27: 陈杰 | B27: 配票 | C27: 1 | D27: 39.12 | E27: 89584.8 | F27: 914.61472 | G27: 913.68672 | H27: =G27-F27 -> -0.928 | I27: =IF(D27=0,"",G27/D27) -> 23.356 | J27: 0
A28: 合计 | C28: =SUM(C17:C27) -> 101 | D28: =SUM(D17:D27) -> 9403 | E28: =SUM(E17:E27) -> 22746517 | F28: =SUM(F17:F27) -> 182926.46 | G28: =SUM(G17:G27) -> 182881.49 | H28: =SUM(H17:H27) -> -44.96772 | J28: =SUM(J17:J27) -> 32452.3
A29: 注：财务 8/29 那行是两车合并，按系统两车利润比例分摊到各自调货人。

Sheet ⑦各路径计算过程
A1: 配票路径 实例：林凯 第50行 苏NEN536 2026-09-18 34.02吨（系统 #90）
A2: 步骤 | B2: 财务表怎么算 | C2: 系统怎么算 | D2: 财务结果 | E2: 系统结果
A3: 结算额 A | B3: 应收金额 D = 吨位×单价 | C3: 结算金额（磅重明细合计） | D3: 79266.6 | E3: 79266.6
A4: 垫资费 | B4: 23 × 吨位 | C4: 吨位 × 户头垫资费率(费率与关系，23) | D4: 782.46 | E4: 782.46
A5: 前端开票额 | B5: 欧冶 E = D − 23×吨位 | C5: 结算额 − 垫资费 | D5: 78484.14 | E5: 78484.14
A6: 给客户付 | B6: 实际付款 F = INT(D × 0.86) | C6: 结算额 × (1 − 对外点位14%) | D6: 68169 | E6: 68169.276
A7: 前端实付 | B7: E × 0.865(俊兴/益周) 或 × 0.868(煌烽) | C7: 前端开票额 × (1 − 票源点位) | D7: 68124.234 | E7: 68124.234
A8: 个人垫资 | B8: F − 前端实付 | C8: 给客户付 − 前端实付 | D8: 44.76648 | E8: 45.04248
A9: 量补 | B9: 25 × 吨位（7/26~8/25 那期 20） | C9: 钢厂量补阶梯（那期固化 20） | D9: 850.5 | E9: 850.5
A10: 调货提成 | B10: 林凯 5 × 吨位（9/04 前） | C10: 费率与关系：林凯配票 5 元/吨到 9/04，9/05 起 0 | D10: 0 | E10: 0
A11: 利润 | B11: 前端实付 − F + 量补 − 提成 | C11: 量补 − 个人垫资 − 提成 − 其他成本 | D11: 805.73352 | E11: 805.45752
A14: 反向路径 实例：闫东鹏 第3行 苏J19371 2026-09-14 78.36吨（系统 #72）
A15: 步骤 | B15: 财务表怎么算 | C15: 系统怎么算 | D15: 财务结果 | E15: 系统结果
A16: 结算额 A | B16: 应收金额 D | C16: 结算金额 | D16: 198250.8 | E16: 198250.8
A17: 垫资费 | B17: 不扣（本期已含在反向票点里） | C17: 户头+反向 生效档 = 0 | D17: 0 | E17: 0
A18: 前端开票额 | B18: 就是 D（不扣垫资） | C18: 结算额 − 0 | D18: 198250.8 | E18: 198250.8
A19: 给客户付 | B19: F = INT(D × 0.86) | C19: 结算额 × (1 − 14%) | D19: 170495 | E19: 170495.69
A20: 前端实付 | B20: 带票公司付 G = D × 0.862 | C20: 前端开票额 × (1 − 13.8%) | D20: 170892.19 | E20: 170892.19
A21: 个人垫资 | B21: F − G | C21: 给客户付 − 前端实付 | D21: -397.1896 | E21: -396.5016
A22: 量补 | B22: 25 × 吨位 | C22: 钢厂量补阶梯 | D22: 1959 | E22: 1959
A23: 调货提成 | B23: 0 | C23: 0 | D23: 0 | E23: 0
A24: 利润 | B24: G − F + 25×吨位 | C24: 量补 − 个人垫资 − 提成 | D24: 2356.1896 | E24: 2355.5016
A27: 带票路径 实例：林凯-君盛 第3行 苏DBE075 2026-09-12 65.44吨（系统 #68）
A28: 步骤 | B28: 财务表怎么算 | C28: 系统怎么算 | D28: 财务结果 | E28: 系统结果
A29: 结算额 A | B29: 应收金额 D | C29: 结算金额 | D29: 147240 | E29: 147240
A30: 垫资 | B30: 23 × 吨位 | C30: 吨位 × 垫资费率 23 | D30: 1505.12 | E30: 1505.12
A31: 欧冶 | B31: E = D − 23×吨位 | C31: 结算额 − 垫资 | D31: 145734.88 | E31: 145734.88
A32: 付供货厂 | B32: F = INT(D − 40×吨位) | C32: 结算额 − 毛服务费 | D32: 144622 | E32: 144622.4
A33: 毛服务费 | B33: D − F ≈ 40 × 吨位 | C33: 吨位 × 40 | D33: 2618 | E33: 2617.6
A34: 量补 | B34: 25 × 吨位 | C34: 钢厂量补阶梯 | D34: 1636 | E34: 1636
A35: 调货提成 | B35: 15 × 吨位 | C35: 费率与关系：林凯带票 15 元/吨 | D35: 981.6 | E35: 981.6
A36: 利润 | B36: E − F + 25×吨位 − 15×吨位（=27元/吨） | C36: 毛服务费 − 垫资 + 量补 − 提成 | D36: 1767.28 | E36: 1766.88
A39: 规则说明（本次统一）
A40: 1. 切割费：由客户承担。钢厂结算单里已经从结算额扣掉，给客户付款也按扣后的结算额算，所以利润里不再扣（以前系统重复扣了，已改）。
A41: 2. 王荣胜 8/29 鲁济宁货4095：特批按 13.8% 给客户付款（×0.862），系统在这一车的“本车费率”里设了。
A42: 3. 林凯配票提成：9/04 以前 5 元/吨，9/05 起停。带票 15 元/吨不变。
A43: 4. 量补：7/26~8/25 那期按约定 20 元/吨（已写进这 10 车的本车费率固定下来），8/26 起按阶梯 25 元/吨。
A44: 5. 财务“实际付款”用 INT() 向下取整，每车差几毛钱，系统不取整；对比表里标灰“INT”，可忽略。

Sheet ⑧系统同步明细
A1: 车次 | B1: 车号 | C1: 结算日期 | D1: 改了什么（改前 → 改后） | E1: 同步前系统利润 | F1: 同步后系统利润 | G1: 利润变化 | H1: 同步前票差留存 | I1: 同步后票差留存 | J1: 原因
A2: #1 | B2: 苏DBB772 | C2: 2026-08-19 | D2: 本车费率：None → {"rate:reward_profit": 20.0} | E2: 482.3169 | F2: 482.3169 | G2: =F2-E2 -> 0 | H2: 0 | I2: 0 | J2: 7/26~8/25 那期量补 20 固定进本车费率（利润不变）
A3: #2 | B3: 苏DFM060 | C3: 2026-08-20 | D3: 本车费率：None → {"rate:reward_profit": 20.0} | E3: 252.474 | F3: 252.474 | G3: =F3-E3 -> 0 | H3: 0 | I3: 0 | J3: 7/26~8/25 那期量补 20 固定进本车费率（利润不变）
A4: #3 | B4: 苏DBB772 | C4: 2026-08-21 | D4: 本车费率：None → {"rate:reward_profit": 20.0} | E4: 609.1058 | F4: 609.1058 | G4: =F4-E4 -> 0 | H4: 0 | I4: 0 | J4: 7/26~8/25 那期量补 20 固定进本车费率（利润不变）
A5: #4 | B5: 皖M2A505 | C5: 2026-08-21 | D5: 调货人：（空） → 林凯；本车费率：None → {"rate:reward_profit": 20.0} | E5: 420.1398 | F5: 238.3398 | G5: =F5-E5 -> -181.8 | H5: 0 | I5: 0 | J5: 按财务标记同步；7/26~8/25 那期量补 20 固定进本车费率（利润不变）
A6: #5 | B6: 苏EQB977 | C6: 2026-08-21 | D6: 调货人：（空） → 林凯；本车费率：None → {"rate:reward_profit": 20.0} | E6: 380.6217 | F6: 215.9217 | G6: =F6-E6 -> -164.7 | H6: 0 | I6: 0 | J6: 按财务标记同步；7/26~8/25 那期量补 20 固定进本车费率（利润不变）
A7: #6 | B7: 苏BUK952 | C7: 2026-08-21 | D7: 本车费率：None → {"rate:reward_profit": 20.0} | E7: 175.62995 | F7: 175.62995 | G7: =F7-E7 -> 0 | H7: 0 | I7: 0 | J7: 7/26~8/25 那期量补 20 固定进本车费率（利润不变）
A8: #7 | B8: 苏DBB772 | C8: 2026-08-22 | D8: 本车费率：None → {"rate:reward_profit": 20.0} | E8: 455.5725 | F8: 455.5725 | G8: =F8-E8 -> 0 | H8: 0 | I8: 0 | J8: 7/26~8/25 那期量补 20 固定进本车费率（利润不变）
A9: #8 | B9: 苏E9W908 | C9: 2026-08-22 | D9: 本车费率：None → {"rate:reward_profit": 20.0} | E9: 460.3258 | F9: 460.3258 | G9: =F9-E9 -> 0 | H9: 0 | I9: 0 | J9: 7/26~8/25 那期量补 20 固定进本车费率（利润不变）
A10: #9 | B10: 苏MAK862 | C10: 2026-08-22 | D10: 调货人：（空） → 林凯；本车费率：None → {"rate:reward_profit": 20.0} | E10: 395.6432 | F10: 224.4432 | G10: =F10-E10 -> -171.2 | H10: 0 | I10: 0 | J10: 按财务标记同步；7/26~8/25 那期量补 20 固定进本车费率（利润不变）
A11: #10 | B11: 苏DBE075 | C11: 2026-08-25 | D11: 本车费率：None → {"rate:reward_profit": 20.0} | E11: 523.665 | F11: 523.665 | G11: =F11-E11 -> 0 | H11: 0 | I11: 0 | J11: 7/26~8/25 那期量补 20 固定进本车费率（利润不变）
A12: #11 | B12: 苏淮货16776 | C12: 2026-08-27 | D12: 调货人：（空） → 林凯 | E12: 9581.3704 | F12: 6779.4204 | G12: =F12-E12 -> -2801.95 | H12: 0 | I12: 0 | J12: 按财务标记同步
A13: #14 | B13: 苏DBB772 | C13: 2026-08-27 | D13: 票源：俊兴 → （空）；链条规则：配票 → 直签带票 | E13: 748.6171 | F13: 1787.94 | G13: =F13-E13 -> 1039.3229 | H13: 0 | I13: 0 | J13: 按财务标记同步
A14: #16 | B14: 苏BZP839 | C14: 2026-08-27 | E14: 246.33755 | F14: 345.83755 | G14: =F14-E14 -> 99.5 | H14: 0 | I14: 0 | J14: 切割费客户承担，利润不再扣
A15: #17 | B15: 苏NEV615 | C15: 2026-08-27 | D15: 调货人：（空） → 邓晶焱 | E15: 647.8199 | F15: 647.8199 | G15: =F15-E15 -> 0 | H15: 0 | I15: 0 | J15: 按财务标记同步
A16: #19 | B16: 鲁济宁货4095 | C16: 2026-08-27 | D16: 调货人：（空） → 王荣胜；本车费率：None → {"rate:give_customer": 13.8} | E16: 9003.1352 | F16: 6460.6173 | G16: =F16-E16 -> -2542.5179 | H16: 0 | I16: 0 | J16: 按财务标记同步；王荣胜特批 13.8%
A17: #27 | B17: 皖KQ1052 | C17: 2026-08-28 | D17: 调货人：（空） → 高栾凤 | E17: 578.22485 | F17: 578.22485 | G17: =F17-E17 -> 0 | H17: 0 | I17: 0 | J17: 按财务标记同步
A18: #34 | B18: 冀A224E6 | C18: 2026-08-29 | D18: 调货人：（空） → 林凯 | E18: 346.1 | F18: 246.1 | G18: =F18-E18 -> -100 | H18: 0 | I18: 0 | J18: 按财务标记同步
A19: #35 | B19: 苏AE8896 | C19: 2026-08-29 | D19: 调货人：（空） → 邓晶焱 | E19: 669.9294 | F19: 669.9294 | G19: =F19-E19 -> 0 | H19: 0 | I19: 0 | J19: 按财务标记同步
A20: #38 | B20: 苏DBE961 | C20: 2026-08-30 | D20: 调货人：（空） → 林凯 | E20: 1308.9628 | F20: 915.7628 | G20: =F20-E20 -> -393.2 | H20: 0 | I20: 0 | J20: 按财务标记同步
A21: #39 | B21: 苏DFB287 | C21: 2026-08-30 | D21: 调货人：（空） → 林凯 | E21: 1385.8627 | F21: 969.5627 | G21: =F21-E21 -> -416.3 | H21: 0 | I21: 0 | J21: 按财务标记同步
A22: #43 | B22: 冀A224E6 | C22: 2026-08-30 | D22: 调货人：（空） → 林凯 | E22: 775.8842 | F22: 544.4842 | G22: =F22-E22 -> -231.4 | H22: 0 | I22: 0 | J22: 按财务标记同步
A23: #45 | B23: 苏DFM060 | C23: 2026-08-31 | D23: 票源：益周 → 俊兴 | E23: 304.0776 | F23: 304.0776 | G23: =F23-E23 -> 0 | H23: 417.97168 | I23: 0 | J23: 按财务标记同步
A24: #46 | B24: 冀A224E6 | C24: 2026-08-31 | D24: 票源：益周 → 俊兴 | E24: 359.138 | F24: 359.138 | G24: =F24-E24 -> 0 | H24: 493.83656 | I24: 0 | J24: 按财务标记同步
A25: #47 | B25: 苏DFM060 | C25: 2026-08-31 | D25: 票源：益周 → 俊兴 | E25: 692.9999 | F25: 692.9999 | G25: =F25-E25 -> 0 | H25: 952.71162 | I25: 0 | J25: 按财务标记同步
A26: #48 | B26: 苏DBB772 | C26: 2026-08-31 | D26: 票源：益周 → 俊兴 | E26: 1024.5488 | F26: 1024.5488 | G26: =F26-E26 -> 0 | H26: 1409.4326 | I26: 0 | J26: 按财务标记同步
... A52: #89 | B52: 苏DBB772 | C52: 2026-09-18 | D52: 供货厂：君盛 → 林凯；票源：（空） → 煌烽；链条规则：直签带票 → 配票 | E52: 2260.98 | F52: 2042.921 | G52: =F52-E52 -> -218.05896 | H52: 0 | I52: 0 | J52: 按财务标记同步
A53: #95 | B53: 苏GE2356 | C53: 2026-09-19 | E53: 700.86936 | F53: 800.86936 | G53: =F53-E53 -> 100 | H53: 0 | I53: 0 | J53: 切割费客户承担，利润不再扣
A54: #96 | B54: 苏NHY179 | C54: 2026-09-19 | E54: 699.9768 | F54: 799.9768 | G54: =F54-E54 -> 100 | H54: 0 | I54: 0 | J54: 切割费客户承担，利润不再扣
A55: 合计 | E55: =SUM(E2:E54) -> 95744.295 | F55: =SUM(F2:F54) -> 91690.81 | G55: =SUM(G2:G54) -> -4053.4844 | H55: =SUM(H2:H54) -> 21844.516 | I55: =SUM(I2:I54) -> 8195.1302
A57: 档案：供货厂“𠓾景通”改名“鑫景通”；新增调货人“高栾凤”“王荣胜”（提成 0）。链条规则 5 个模板的“其他成本”节点去掉切割费。同步前已自动备份（data/backups/manual_20260922_063133.db），每项修改在「系统 → 操作记录」里可查。
